Workbook

Sheet Assumptions
A1: Test School Automation — Financial Model Assumptions
A2: Yellow cells are editable inputs. All other cells in this workbook are formulas.
A4: SCHOOL PROFILE
A5: School Name | B5: Test School Automation
A6: State | B6: CA
A7: School Type | B7: Private School
A8: Legal Entity | B8: LLC (Partnership)
A9: EIN | B9: N/A
A10: Fiscal Year Start | B10: July
A11: Maximum Capacity | B11: 150
A12: School Stage | B12: Operating School
A14: ENROLLMENT | B14: Year 1 | C14: Year 2 | D14: Year 3 | E14: Year 4 | F14: Year 5
A15: Students Enrolled | B15: 0 | C15: 0 | D15: 0 | E15: 0 | F15: 0
A17: REVENUE SOURCES | B17: Category | C17: Driver | D17: Yr 1 Amount | E17: Escalation % | F17: Billing Mo. | G17: Collection % | H17: Note
A20: STAFFING ROSTER | B20: Function | C20: Type | D20: FTE | E20: Annual Rate | F20: Benefits % | G20: Payroll Tax % | H20: Benefits Elig. | I20: Notes
A22: FACILITIES & OCCUPANCY | B22: Amount | C22: Frequency
A23: Ownership Type | B23: Rent
A24: Monthly Rent | B24: 0 | C24: Monthly
A25: Annual Rent Escalation | B25: 0.03
A27: OPERATING EXPENSES | B27: Category | C27: Driver | D27: Yr 1 Amount | E27: Escalation % | F27: Note
A29: CAPITAL & DEBT | B29: Is Loan? | C29: Yr 1 Amount | D29: Principal | E29: Interest Rate | F29: Term (Yrs) | G29: Annual Payment | H29: Note
A31: GROWTH & TIMING ASSUMPTIONS
A32: Annual Salary Escalation | B32: 0.03
A33: General Cost Inflation | B33: 0.03
A34: Year 1 Proration Factor | B34: 1 | C34: (12 of 12 months)
A35: Tuition Escalation Rate | B35: 0.03
A36: Management Fee % | B36: 0
A37: Starting Cash | B37: 10000
A39: HISTORICAL / CURRENT YEAR DATA | B39: Prior Year | C39: Current Year
A40: Enrollment | B40: 8
A41: Total Revenue | B41: 50000
A42: Total Expenses | B42: 40000
A43: Net Income | B43: =B42-B43 -> 0
A44: Ending Cash | B44: 10000
A46: Built by SchoolStack Budget • budget.schoolstack.ai

Sheet 5-Year Model
A1: Test School Automation — 5-Year Financial Model
B2: Year 1 | C2: Year 2 | D2: Year 3 | E2: Year 4 | F2: Year 5
A3: Students Enrolled | B3: =Assumptions!B15 -> 0 | C3: =Assumptions!C15 -> 0 | D3: =Assumptions!D15 -> 0 | E3: =Assumptions!E15 -> 0 | F3: =Assumptions!F15 -> 0
A5: REVENUE
A6: TOTAL REVENUE | B6: =SUM(B6:B5) -> 0 | C6: =SUM(C6:C5) -> 0 | D6: =SUM(D6:D5) -> 0 | E6: =SUM(E6:E5) -> 0 | F6: =SUM(F6:F5) -> 0
A8: PERSONNEL
A9: TOTAL PERSONNEL | B9: =SUM(B9:B8) -> 0 | C9: =SUM(C9:C8) -> 0 | D9: =SUM(D9:D8) -> 0 | E9: =SUM(E9:E8) -> 0 | F9: =SUM(F9:F8) -> 0
A11: OPERATING EXPENSES
A12: TOTAL OPERATING EXPENSES | B12: =SUM(B12:B11) -> 0 | C12: =SUM(C12:C11) -> 0 | D12: =SUM(D12:D11) -> 0 | E12: =SUM(E12:E11) -> 0 | F12: =SUM(F12:F11) -> 0
A14: CAPITAL & DEBT SERVICE
A15: TOTAL CAPITAL & DEBT SERVICE | B15: 0 | C15: 0 | D15: 0 | E15: 0 | F15: 0
A17: INCOME STATEMENT SUMMARY
A18: Total Revenue | B18: =B6 -> 0 | C18: =C6 -> 0 | D18: =D6 -> 0 | E18: =E6 -> 0 | F18: =F6 -> 0
A19: Total Personnel | B19: =B9 -> 0 | C19: =C9 -> 0 | D19: =D9 -> 0 | E19: =E9 -> 0 | F19: =F9 -> 0
A20: Total Operating Expenses | B20: =B12 -> 0 | C20: =C12 -> 0 | D20: =D12 -> 0 | E20: =E12 -> 0 | F20: =F12 -> 0
A21: Total Capital & Debt Service | B21: =B15 -> 0 | C21: =C15 -> 0 | D21: =D15 -> 0 | E21: =E15 -> 0 | F21: =F15 -> 0
A22: Total Expenses | B22: =B19+B20+B21 -> 0 | C22: =C19+C20+C21 -> 0 | D22: =D19+D20+D21 -> 0 | E22: =E19+E20+E21 -> 0 | F22: =F19+F20+F21 -> 0
A24: Profit / (Loss) | B24: =B18-B22 -> 0 | C24: =C18-C22 -> 0 | D24: =D18-D22 -> 0 | E24: =E18-E22 -> 0 | F24: =F18-F22 -> 0
A25: Profit Margin % | B25: =IF(B18=0,"",B24/B18) -> 0 | C25: =IF(C18=0,"",C24/C18) -> 0 | D25: =IF(D18=0,"",D24/D18) -> 0 | E25: =IF(E18=0,"",E24/E18) -> 0 | F25: =IF(F18=0,"",F24/F18) -> 0
A26: Cumulative Profit | B26: =B24 -> 0 | C26: =B26+C24 -> 0 | D26: =C26+D24 -> 0 | E26: =D26+E24 -> 0 | F26: =E26+F24 -> 0
A28: CASH FLOW & DEBT COVERAGE
A29: CFADS (Cash Flow Available for Debt Service) | B29: =B18-B19-B20 -> 0 | C29: =C18-C19-C20 -> 0 | D29: =D18-D19-D20 -> 0 | E29: =E18-E19-E20 -> 0 | F29: =F18-F19-F20 -> 0
A30: Debt Service | B30: =B21 -> 0 | C30: =C21 -> 0 | D30: =D21 -> 0 | E30: =E21 -> 0 | F30: =F21 -> 0
A31: DSCR (Debt Service Coverage Ratio) | B31: =IF(B30=0,"N/A",B29/B30) -> 0 | C31: =IF(C30=0,"N/A",C29/C30) -> 0 | D31: =IF(D30=0,"N/A",D29/D30) -> 0 | E31: =IF(E30=0,"N/A",E29/E30) -> 0 | F31: =IF(F30=0,"N/A",F29/F30) -> 0
A32: Starting Cash | B32: =Assumptions!B37 -> 10000 | C32: =B33 -> 0 | D32: =C33 -> 0 | E32: =D33 -> 0 | F32: =E33 -> 0
A33: Ending Cash | B33: =B32+B24 -> 0 | C33: =C32+C24 -> 0 | D33: =D32+D24 -> 0 | E33: =E32+E24 -> 0 | F33: =F32+F24 -> 0
A34: Days Cash on Hand | B34: =IF(B22=0,"",B33/B22*365) -> 0 | C34: =IF(C22=0,"",C33/C22*365) -> 0 | D34: =IF(D22=0,"",D33/D22*365) -> 0 | E34: =IF(E22=0,"",E33/E22*365) -> 0 | F34: =IF(F22=0,"",F33/F22*365) -> 0
A35: Months of Runway | B35: =IF(B22=0,"",B33/(B22/12)) -> 0 | C35: =IF(C22=0,"",C33/(C22/12)) -> 0 | D35: =IF(D22=0,"",D33/(D22/12)) -> 0 | E35: =IF(E22=0,"",E33/(E22/12)) -> 0 | F35: =IF(F22=0,"",F33/(F22/12)) -> 0
A36: Capacity Utilization % | B36: =IF(Assumptions!B11=0,"",B3/Assumptions!B11) -> 0 | C36: =IF(Assumptions!B11=0,"",C3/Assumptions!B11) -> 0 | D36: =IF(Assumptions!B11=0,"",D3/Assumptions!B11) -> 0 | E36: =IF(Assumptions!B11=0,"",E3/Assumptions!B11) -> 0 | F36: =IF(Assumptions!B11=0,"",F3/Assumptions!B11) -> 0
A38: COVENANT & HEALTH CHECKS
A39: DSCR ≥ 1.20x | B39: =IF(B30=0,"N/A",IF(B31>=1.2,"PASS","FAIL")) -> 0 | C39: =IF(C30=0,"N/A",IF(C31>=1.2,"PASS","FAIL")) -> 0 | D39: =IF(D30=0,"N/A",IF(D31>=1.2,"PASS","FAIL")) -> 0 | E39: =IF(E30=0,"N/A",IF(E31>=1.2,"PASS","FAIL")) -> 0 | F39: =IF(F30=0,"N/A",IF(F31>=1.2,"PASS","FAIL")) -> 0
A40: Positive Net Income | B40: =IF(B24>0,"PASS","FAIL") -> 0 | C40: =IF(C24>0,"PASS","FAIL") -> 0 | D40: =IF(D24>0,"PASS","FAIL") -> 0 | E40: =IF(E24>0,"PASS","FAIL") -> 0 | F40: =IF(F24>0,"PASS","FAIL") -> 0
A41: Enrollment ≥ 70% Capacity | B41: =IF(Assumptions!B11=0,"N/A",IF(B3/Assumptions!B11>=0.7,"PASS","FAIL")) -> 0 | C41: =IF(Assumptions!B11=0,"N/A",IF(C3/Assumptions!B11>=0.7,"PASS","FAIL")) -> 0 | D41: =IF(Assumptions!B11=0,"N/A",IF(D3/Assumptions!B11>=0.7,"PASS","FAIL")) -> 0 | E41: =IF(Assumptions!B11=0,"N/A",IF(E3/Assumptions!B11>=0.7,"PASS","FAIL")) -> 0 | F41: =IF(Assumptions!B11=0,"N/A",IF(F3/Assumptions!B11>=0.7,"PASS","FAIL")) -> 0
A42: Cash Reserve ≥ 2 Months | B42: =IF(B22=0,"N/A",IF(B33/(B22/12)>=2,"PASS","FAIL")) -> 0 | C42: =IF(C22=0,"N/A",IF(C33/(C22/12)>=2,"PASS","FAIL")) -> 0 | D42: =IF(D22=0,"N/A",IF(D33/(D22/12)>=2,"PASS","FAIL")) -> 0 | E42: =IF(E22=0,"N/A",IF(E33/(E22/12)>=2,"PASS","FAIL")) -> 0 | F42: =IF(F22=0,"N/A",IF(F33/(F22/12)>=2,"PASS","FAIL")) -> 0
A44: BREAK-EVEN ANALYSIS
A45: Revenue Per Student | B45: =IF(B3=0,"",B6/B3) -> 0 | C45: =IF(C3=0,"",C6/C3) -> 0 | D45: =IF(D3=0,"",D6/D3) -> 0 | E45: =IF(E3=0,"",E6/E3) -> 0 | F45: =IF(F3=0,"",F6/F3) -> 0
A46: Cost Per Student | B46: =IF(B3=0,"",B22/B3) -> 0 | C46: =IF(C3=0,"",C22/C3) -> 0 | D46: =IF(D3=0,"",D22/D3) -> 0 | E46: =IF(E3=0,"",E22/E3) -> 0 | F46: =IF(F3=0,"",F22/F3) -> 0
A47: Fixed Costs (Personnel + Debt) | B47: =B19+B21 -> 0 | C47: =C19+C21 -> 0 | D47: =D19+D21 -> 0 | E47: =E19+E21 -> 0 | F47: =F19+F21 -> 0
A48: Variable Cost Per Student | B48: =IF(B3=0,"",B20/B3) -> 0 | C48: =IF(C3=0,"",C20/C3) -> 0 | D48: =IF(D3=0,"",D20/D3) -> 0 | E48: =IF(E3=0,"",E20/E3) -> 0 | F48: =IF(F3=0,"",F20/F3) -> 0
A49: Contribution Margin Per Student | B49: =IF(B3=0,"",B45-B48) -> 0 | C49: =IF(C3=0,"",C45-C48) -> 0 | D49: =IF(D3=0,"",D45-D48) -> 0 | E49: =IF(E3=0,"",E45-E48) -> 0 | F49: =IF(F3=0,"",F45-F48) -> 0
...

Sheet Year 1 Pro Forma
A1: Test School Automation — Year 1 Pro Forma
B2: July | C2: August | D2: September | E2: October | F2: November | G2: December | H2: January | I2: February | J2: March | K2: April | L2: May | M2: June | N2: Year 1 Total
A3: REVENUE
A4: TOTAL REVENUE | B4: 0 | C4: 0 | D4: 0 | E4: 0 | F4: 0 | G4: 0 | H4: 0 | I4: 0 | J4: 0 | K4: 0 | L4: 0 | M4: 0 | N4: =SUM(B4:M4) -> 0
A6: PERSONNEL
A7: TOTAL PERSONNEL | B7: 0 | C7: 0 | D7: 0 | E7: 0 | F7: 0 | G7: 0 | H7: 0 | I7: 0 | J7: 0 | K7: 0 | L7: 0 | M7: 0 | N7: =SUM(B7:M7) -> 0
A9: OPERATING EXPENSES
A10: TOTAL OPERATING EXPENSES | B10: 0 | C10: 0 | D10: 0 | E10: 0 | F10: 0 | G10: 0 | H10: 0 | I10: 0 | J10: 0 | K10: 0 | L10: 0 | M10: 0 | N10: =SUM(B10:M10) -> 0
A12: Capital & Debt Service | B12: 0 | C12: 0 | D12: 0 | E12: 0 | F12: 0 | G12: 0 | H12: 0 | I12: 0 | J12: 0 | K12: 0 | L12: 0 | M12: 0 | N12: =SUM(B12:M12) -> 0
A14: MONTHLY CASH FLOW
A15: Total Expenses | B15: =B7+B10+B12 -> 0 | C15: =C7+C10+C12 -> 0 | D15: =D7+D10+D12 -> 0 | E15: =E7+E10+E12 -> 0 | F15: =F7+F10+F12 -> 0 | G15: =G7+G10+G12 -> 0 | H15: =H7+H10+H12 -> 0 | I15: =I7+I10+I12 -> 0 | ... M15: =M7+M10+M12 -> 0 | N15: =SUM(B15:M15) -> 0
A16: Net Cash Flow | B16: =B4-B15 -> 0 | C16: =C4-C15 -> 0 | D16: =D4-D15 -> 0 | E16: =E4-E15 -> 0 | F16: =F4-F15 -> 0 | G16: =G4-G15 -> 0 | H16: =H4-H15 -> 0 | I16: =I4-I15 -> 0 | ... M16: =M4-M15 -> 0 | N16: =SUM(B16:M16) -> 0
A17: Cumulative Cash | B17: =10000+B16 -> 0 | C17: =B17+C16 -> 0 | D17: =C17+D16 -> 0 | E17: =D17+E16 -> 0 | F17: =E17+F16 -> 0 | G17: =F17+G16 -> 0 | H17: =G17+H16 -> 0 | I17: =H17+I16 -> 0 | J17: =I17+J16 -> 0 | ... M17: =L17+M16 -> 0 | N17: =M17 -> 0
A19: CASH FLOW METRICS
A20: Starting Cash | B20: 10000
A21: Ending Cash (Month 12) | B21: =M17 -> 0
A22: Minimum Cash Month | B22: =MIN(B17:M17) -> 0
A24: Built by SchoolStack Budget • budget.schoolstack.ai

Sheet Actuals vs. Projections
A1: Test School Automation — Actuals vs. Projections
B2: Prior Year (Actual) | C2: Year 1 (Projected) | D2: Year 2 (Projected) | E2: Yr 1 vs Prior/Current
A3: KEY METRICS
A4: Enrollment | B4: 8 | C4: 0 | D4: 0 | E4: -1
A5: Total Revenue | B5: 50000 | C5: 0 | D5: 0 | E5: -1
A6: Total Expenses | B6: 40000 | C6: 0 | D6: 0
A7: Net Income | B7: 10000 | C7: 0 | D7: 0
A8: Cash Position | B8: 10000
A10: PER-STUDENT METRICS
A11: Revenue Per Student | B11: 6250
A12: Expense Per Student | B12: 5000
A13: Net Margin % | B13: 0.2
A14: Personnel as % of Revenue | B14: N/A
A16: REALITY CHECK FLAGS
A17: ⚠ Enrollment growth > 30% | C17: Within range
A18: ⚠ Revenue growth > 25% | C18: Within range
A19: ⚠ First-year positive income (rare) | C19: Operating school — less unusual
A21: Built by SchoolStack Budget • budget.schoolstack.ai
