Workbook

Sheet Cover
B3: SCHOOLSTACK BUDGET
B4: Lender-Ready Pro Forma
B6: Civic Scholars Charter
B8: TABLE OF CONTENTS
B9: Assumptions
B10: Drivers
B11: 5-Year P&L
B12: Cash Flow & DSCR
B13: Staffing
B14: Loan Snapshot
B15: Summary
B18: Generated March 16, 2026
B19: Generated by SchoolStack Budget • budget.schoolstack.ai

Sheet Assumptions
B1: SchoolStack Budget — Lender Pro Forma Assumptions
B3: SCHOOL PROFILE
C5: School Name | D5: Civic Scholars Charter
C6: State | D6: OH
C7: School Type | D7: Charter School
C8: First Operating Year | D8: 2026
B10: ENROLLMENT FORECAST
C12: Year 1 Enrollment | D12: 120
C13: Year 2 Enrollment | D13: 200
C14: Year 3 Enrollment | D14: 300
C15: Year 4 Enrollment | D15: 375
C16: Year 5 Enrollment | D16: 400
B18: REVENUE ASSUMPTIONS
C20: Tuition per Student (Year 1) | D20: 0
C21: Tuition Annual Growth % | D21: 0.03
C22: ESA per Student (Year 1) | D22: 11500
C23: ESA Annual Growth % | D23: 0.02
C24: Other Per-Student Revenue (Year 1) | D24: 300
C25: Other Revenue Growth % | D25: 0.03
C26: Collection Rate % | D26: 0.95
C27: Grants & Contributions (Year 1) | D27: 130000
C28: Grants Growth % | D28: 0
B30: STAFFING ASSUMPTIONS
C32: Students per Teacher | D32: 12
C33: Avg Teacher Salary (Year 1) | D33: 45667
C34: Teacher Salary Growth % | D34: 0.03
C35: Admin FTE — Year 1 | D35: 7
C36: Admin FTE — Year 2 | D36: 7
C37: Admin FTE — Year 3 | D37: 7
C38: Admin FTE — Year 4 | D38: 7
C39: Admin FTE — Year 5 | D39: 7
C40: Avg Admin Salary (Year 1) | D40: 70000
C41: Admin Salary Growth % | D41: 0.03
C42: Benefits Burden % | D42: 0.26777778
B44: OPERATING EXPENSE ASSUMPTIONS
C46: Annual Rent (Year 1) | D46: 282000
C47: Rent Growth % | D47: 0.03
C48: Other Facility Cost (Year 1) | D48: 0
C49: Other Facility Growth % | D49: 0.03
C50: Program Cost per Student (Year 1) | D50: 700
...

Sheet Drivers
B1: Revenue & Expense Drivers
C3: Year 1 | D3: Year 2 | E3: Year 3 | F3: Year 4 | G3: Year 5
B4: Enrollment | C4: =Assumptions!D12 -> 120 | D4: =Assumptions!D13 -> 200 | E4: =Assumptions!D14 -> 300 | F4: =Assumptions!D15 -> 375 | G4: =Assumptions!D16 -> 400
B5: Tuition Revenue (Net) | C5: =Assumptions!D12*Assumptions!D20 -> 0 | D5: =Assumptions!D13*Assumptions!D20*(1+Assumptions!D21)^1 -> 0 | E5: =Assumptions!D14*Assumptions!D20*(1+Assumptions!D21)^2 -> 0 | F5: =Assumptions!D15*Assumptions!D20*(1+Assumptions!D21)^3 -> 0 | G5: =Assumptions!D16*Assumptions!D20*(1+Assumptions!D21)^4 -> 0
B6: × Collection Rate Applied | C6: =C5*Assumptions!D26 -> 0 | D6: =D5*Assumptions!D26 -> 0 | E6: =E5*Assumptions!D26 -> 0 | F6: =F5*Assumptions!D26 -> 0 | G6: =G5*Assumptions!D26 -> 0
B7: ESA / School Choice Revenue | C7: =Assumptions!D12*Assumptions!D22 -> 1380000 | D7: =Assumptions!D13*Assumptions!D22*(1+Assumptions!D23)^1 -> 2346000 | E7: =Assumptions!D14*Assumptions!D22*(1+Assumptions!D23)^2 -> 3589380 | F7: =Assumptions!D15*Assumptions!D22*(1+Assumptions!D23)^3 -> 4576459.5 | G7: =Assumptions!D16*Assumptions!D22*(1+Assumptions!D23)^4 -> 4979187.9
B8: Other Earned Revenue | C8: =Assumptions!D12*Assumptions!D24 -> 36000 | D8: =Assumptions!D13*Assumptions!D24*(1+Assumptions!D25)^1 -> 61800 | E8: =Assumptions!D14*Assumptions!D24*(1+Assumptions!D25)^2 -> 95481 | F8: =Assumptions!D15*Assumptions!D24*(1+Assumptions!D25)^3 -> 122931.79 | G8: =Assumptions!D16*Assumptions!D24*(1+Assumptions!D25)^4 -> 135061.06
B9: Grants & Contributions | C9: =Assumptions!D27 -> 130000 | D9: =Assumptions!D27*(1+Assumptions!D28)^1 -> 130000 | E9: =Assumptions!D27*(1+Assumptions!D28)^2 -> 130000 | F9: =Assumptions!D27*(1+Assumptions!D28)^3 -> 130000 | G9: =Assumptions!D27*(1+Assumptions!D28)^4 -> 130000
B10: Total Revenue | C10: =C6+C7+C8+C9 -> 1546000 | D10: =D6+D7+D8+D9 -> 2537800 | E10: =E6+E7+E8+E9 -> 3814861 | F10: =F6+F7+F8+F9 -> 4829391.3 | G10: =G6+G7+G8+G9 -> 5244249
B12: Teacher FTE (Enrollment ÷ Ratio) | C12: =CEILING(Assumptions!D12/Assumptions!D32,1) -> 10 | D12: =CEILING(Assumptions!D13/Assumptions!D32,1) -> 17 | E12: =CEILING(Assumptions!D14/Assumptions!D32,1) -> 25 | F12: =CEILING(Assumptions!D15/Assumptions!D32,1) -> 32 | G12: =CEILING(Assumptions!D16/Assumptions!D32,1) -> 34
B13: Teacher Salaries | C13: =C12*Assumptions!D33 -> 456670 | D13: =D12*Assumptions!D33*(1+Assumptions!D34)^1 -> 799629.17 | E13: =E12*Assumptions!D33*(1+Assumptions!D34)^2 -> 1211203 | F13: =F12*Assumptions!D33*(1+Assumptions!D34)^3 -> 1596850 | G13: =G12*Assumptions!D33*(1+Assumptions!D34)^4 -> 1747552.8
B14: Admin Salaries | C14: =Assumptions!D35*Assumptions!D40 -> 490000 | D14: =Assumptions!D36*Assumptions!D40*(1+Assumptions!D41)^1 -> 504700 | E14: =Assumptions!D37*Assumptions!D40*(1+Assumptions!D41)^2 -> 519841 | F14: =Assumptions!D38*Assumptions!D40*(1+Assumptions!D41)^3 -> 535436.23 | G14: =Assumptions!D39*Assumptions!D40*(1+Assumptions!D41)^4 -> 551499.32
B15: Benefits & Payroll Taxes | C15: =(C13+C14)*Assumptions!D42 -> 253497.19 | D15: =(D13+D14)*Assumptions!D42 -> 349270.37 | E15: =(E13+E14)*Assumptions!D42 -> 463535.12 | F15: =(F13+F14)*Assumptions!D42 -> 570978.88 | G15: =(G13+G14)*Assumptions!D42 -> 615635.06
B16: Total Staffing Cost | C16: =C13+C14+C15 -> 1200167.2 | D16: =D13+D14+D15 -> 1653599.5 | E16: =E13+E14+E15 -> 2194579.1 | F16: =F13+F14+F15 -> 2703265.2 | G16: =G13+G14+G15 -> 2914687.1
B18: Rent / Lease | C18: =Assumptions!D46 -> 282000 | D18: =Assumptions!D46*(1+Assumptions!D47)^1 -> 290460 | E18: =Assumptions!D46*(1+Assumptions!D47)^2 -> 299173.8 | F18: =Assumptions!D46*(1+Assumptions!D47)^3 -> 308149.01 | G18: =Assumptions!D46*(1+Assumptions!D47)^4 -> 317393.48
B19: Other Facility Costs | C19: =Assumptions!D48 -> 0 | D19: =Assumptions!D48*(1+Assumptions!D49)^1 -> 0 | E19: =Assumptions!D48*(1+Assumptions!D49)^2 -> 0 | F19: =Assumptions!D48*(1+Assumptions!D49)^3 -> 0 | G19: =Assumptions!D48*(1+Assumptions!D49)^4 -> 0
B20: Program / Curriculum | C20: =Assumptions!D12*Assumptions!D50 -> 84000 | D20: =Assumptions!D13*Assumptions!D50*(1+Assumptions!D51)^1 -> 240333.33 | E20: =Assumptions!D14*Assumptions!D50*(1+Assumptions!D51)^2 -> 618858.33 | F20: =Assumptions!D15*Assumptions!D50*(1+Assumptions!D51)^3 -> 1327966.8 | G20: =Assumptions!D16*Assumptions!D50*(1+Assumptions!D51)^4 -> 2431654.8
B21: G&A / Technology | C21: =Assumptions!D52 -> 288000 | D21: =Assumptions!D52*(1+Assumptions!D53)^1 -> 453200 | E21: =Assumptions!D52*(1+Assumptions!D53)^2 -> 713160.56 | F21: =Assumptions!D52*(1+Assumptions!D53)^3 -> 1122237.4 | G21: =Assumptions!D52*(1+Assumptions!D53)^4 -> 1765965.2
B22: Total Operating Expenses | C22: =C18+C19+C20+C21 -> 654000 | D22: =D18+D19+D20+D21 -> 983993.33 | E22: =E18+E19+E20+E21 -> 1631192.7 | F22: =F18+F19+F20+F21 -> 2758353.2 | G22: =G18+G19+G20+G21 -> 4515013.5

Sheet 5-Year P&L
B1: 5-Year Pro Forma Profit & Loss
C3: Year 1 | D3: Year 2 | E3: Year 3 | F3: Year 4 | G3: Year 5
B5: Enrollment | C5: =Drivers!C4 -> 120 | D5: =Drivers!D4 -> 200 | E5: =Drivers!E4 -> 300 | F5: =Drivers!F4 -> 375 | G5: =Drivers!G4 -> 400
B6: Tuition Revenue (Net) | C6: =Drivers!C6 -> 0 | D6: =Drivers!D6 -> 0 | E6: =Drivers!E6 -> 0 | F6: =Drivers!F6 -> 0 | G6: =Drivers!G6 -> 0
B7: ESA / School Choice | C7: =Drivers!C7 -> 1380000 | D7: =Drivers!D7 -> 2346000 | E7: =Drivers!E7 -> 3589380 | F7: =Drivers!F7 -> 4576459.5 | G7: =Drivers!G7 -> 4979187.9
B8: Other Revenue | C8: =Drivers!C8 -> 36000 | D8: =Drivers!D8 -> 61800 | E8: =Drivers!E8 -> 95481 | F8: =Drivers!F8 -> 122931.79 | G8: =Drivers!G8 -> 135061.06
B9: Grants & Contributions | C9: =Drivers!C9 -> 130000 | D9: =Drivers!D9 -> 130000 | E9: =Drivers!E9 -> 130000 | F9: =Drivers!F9 -> 130000 | G9: =Drivers!G9 -> 130000
B10: Total Revenue | C10: =Drivers!C10 -> 1546000 | D10: =Drivers!D10 -> 2537800 | E10: =Drivers!E10 -> 3814861 | F10: =Drivers!F10 -> 4829391.3 | G10: =Drivers!G10 -> 5244249
B12: Total Staffing | C12: =Drivers!C16 -> 1200167.2 | D12: =Drivers!D16 -> 1653599.5 | E12: =Drivers!E16 -> 2194579.1 | F12: =Drivers!F16 -> 2703265.2 | G12: =Drivers!G16 -> 2914687.1
B13: Total Operating Expenses | C13: =Drivers!C22 -> 654000 | D13: =Drivers!D22 -> 983993.33 | E13: =Drivers!E22 -> 1631192.7 | F13: =Drivers!F22 -> 2758353.2 | G13: =Drivers!G22 -> 4515013.5
B15: Total Expenses | C15: =C12+C13 -> 1854167.2 | D15: =D12+D13 -> 2637592.9 | E15: =E12+E13 -> 3825771.8 | F15: =F12+F13 -> 5461618.4 | G15: =G12+G13 -> 7429700.7
B16: Net Operating Income (NOI) | C16: =C10-C15 -> -308167.19 | D16: =D10-D15 -> -99792.87 | E16: =E10-E15 -> -10910.814 | F16: =F10-F15 -> -632227.1 | G16: =G10-G15 -> -2185451.7
B17: Operating Margin | C17: =IF(C10>0,C16/C10,0) -> -0.19933195 | D17: =IF(D10>0,D16/D10,0) -> -0.03932259 | E17: =IF(E10>0,E16/E10,0) -> -0.00286008 | F17: =IF(F10>0,F16/F10,0) -> -0.13091238 | G17: =IF(G10>0,G16/G10,0) -> -0.41673301

Sheet Cash Flow & DSCR
B1: Cash Flow & Debt Service Coverage
C3: Year 1 | D3: Year 2 | E3: Year 3 | F3: Year 4 | G3: Year 5
B4: Net Operating Income | C4: ='5-Year P&L'!C16 -> -308167.19 | D4: ='5-Year P&L'!D16 -> -99792.87 | E4: ='5-Year P&L'!E16 -> -10910.814 | F4: ='5-Year P&L'!F16 -> -632227.1 | G4: ='5-Year P&L'!G16 -> -2185451.7
B6: Existing Debt Service | C6: =Assumptions!D58 -> 115000 | D6: =Assumptions!D58 -> 115000 | E6: =Assumptions!D58 -> 115000 | F6: =Assumptions!D58 -> 115000 | G6: =Assumptions!D58 -> 115000
B7: Proposed Loan Debt Service | C7: =IF(Assumptions!D59>0,PMT(Assumptions!D60/12,Assumptions!D61*12,-Assumptions!D59)*12,0) -> 49824.605 | D7: =IF(Assumptions!D59>0,PMT(Assumptions!D60/12,Assumptions!D61*12,-Assumptions!D59)*12,0) -> 49824.605 | E7: =IF(Assumptions!D59>0,PMT(Assumptions!D60/12,Assumptions!D61*12,-Assumptions!D59)*12,0) -> 49824.605 | F7: =IF(Assumptions!D59>0,PMT(Assumptions!D60/12,Assumptions!D61*12,-Assumptions!D59)*12,0) -> 49824.605 | G7: =IF(Assumptions!D59>0,PMT(Assumptions!D60/12,Assumptions!D61*12,-Assumptions!D59)*12,0) -> 49824.605
B8: Total Debt Service | C8: =C6+C7 -> 164824.61 | D8: =D6+D7 -> 164824.61 | E8: =E6+E7 -> 164824.61 | F8: =F6+F7 -> 164824.61 | G8: =G6+G7 -> 164824.61
B10: DSCR (NOI ÷ Total Debt Service) | C10: =IF(C8>0,C4/C8,IF(C4>0,99.9,0)) -> -1.8696674 | D10: =IF(D8>0,D4/D8,IF(D4>0,99.9,0)) -> -0.60544886 | E10: =IF(E8>0,E4/E8,IF(E4>0,99.9,0)) -> -0.06619651 | F10: =IF(F8>0,F4/F8,IF(F4>0,99.9,0)) -> -3.8357568 | G10: =IF(G8>0,G4/G8,IF(G4>0,99.9,0)) -> -13.259256
B12: Net Income After Debt | C12: =C4-C8 -> -472991.79 | D12: =D4-D8 -> -264617.48 | E12: =E4-E8 -> -175735.42 | F12: =F4-F8 -> -797051.7 | G12: =G4-G8 -> -2350276.3
B14: Cumulative Cash | C14: =Assumptions!D57+C12 -> -472991.79 | D14: =C14+D12 -> -737609.27 | E14: =D14+E12 -> -913344.69 | F14: =E14+F12 -> -1710396.4 | G14: =F14+G12 -> -4060672.7

Sheet Staffing
B1: Staffing Detail
C3: Year 1 | D3: Year 2 | E3: Year 3 | F3: Year 4 | G3: Year 5
B4: Teacher FTE | C4: =Drivers!C12 -> 10 | D4: =Drivers!D12 -> 17 | E4: =Drivers!E12 -> 25 | F4: =Drivers!F12 -> 32 | G4: =Drivers!G12 -> 34
B5: Admin FTE | C5: =Assumptions!D35 -> 7 | D5: =Assumptions!D36 -> 7 | E5: =Assumptions!D37 -> 7 | F5: =Assumptions!D38 -> 7 | G5: =Assumptions!D39 -> 7
B6: Total FTE | C6: =C4+C5 -> 17 | D6: =D4+D5 -> 24 | E6: =E4+E5 -> 32 | F6: =F4+F5 -> 39 | G6: =G4+G5 -> 41

Sheet Loan Snapshot
B1: Proposed Loan Summary
B3: Loan Amount | C3: =Assumptions!D59 -> 500000
B4: Interest Rate | C4: =Assumptions!D60 -> 0.0575
B5: Term (Years) | C5: =Assumptions!D61 -> 15
B6: Annual Debt Service | C6: =IF(Assumptions!D59>0,PMT(Assumptions!D60/12,Assumptions!D61*12,-Assumptions!D59)*12,0) -> 49824.605
B8: Year 1 DSCR | C8: ='Cash Flow & DSCR'!C10 -> -1.8696674

Sheet Summary
B1: Model Summary
B3: School Name | C3: =Assumptions!D5 -> Civic Scholars Charter
B4: School Type | C4: =Assumptions!D7 -> Charter School
B5: State | C5: =Assumptions!D6 -> OH
B6: Opening Year | C6: =Assumptions!D8 -> 2026
B8: Year 5 Enrollment | C8: =Assumptions!D16 -> 400
B9: Year 5 Revenue | C9: =Drivers!G10 -> 5244249
B10: Year 5 NOI | C10: ='5-Year P&L'!G16 -> -2185451.7
B12: Generated by SchoolStack Budget (budget.schoolstack.ai)
