Workbook

Sheet Assumptions
B1: SchoolStack Budget — Lender Pro Forma Assumptions
B3: SCHOOL PROFILE
C5: School Name
C6: State
C7: School Type
C8: First Operating Year | D8: 2026
B10: ENROLLMENT FORECAST
C12: Year 1 Enrollment | D12: 0
C13: Year 2 Enrollment | D13: 0
C14: Year 3 Enrollment | D14: 0
C15: Year 4 Enrollment | D15: 0
C16: Year 5 Enrollment | D16: 0
B18: REVENUE ASSUMPTIONS
C20: Tuition per Student (Year 1) | D20: 0
C21: Tuition Annual Growth % | D21: 0.03
C22: ESA per Student (Year 1) | D22: 0
C23: ESA Annual Growth % | D23: 0
C24: Other Per-Student Revenue (Year 1) | D24: 0
C25: Other Revenue Growth % | D25: 0.02
C26: Collection Rate % | D26: 0.95
C27: Grants & Contributions (Year 1) | D27: 0
C28: Grants Growth % | D28: 0
B30: STAFFING ASSUMPTIONS
C32: Students per Teacher | D32: 12
C33: Avg Teacher Salary (Year 1) | D33: 0
C34: Teacher Salary Growth % | D34: 0.03
C35: Admin FTE — Year 1 | D35: 0
C36: Admin FTE — Year 2 | D36: 0
C37: Admin FTE — Year 3 | D37: 0
C38: Admin FTE — Year 4 | D38: 0
C39: Admin FTE — Year 5 | D39: 0
C40: Avg Admin Salary (Year 1) | D40: 0
C41: Admin Salary Growth % | D41: 0.03
C42: Benefits Burden % | D42: 0.1
B44: OPERATING EXPENSE ASSUMPTIONS
C46: Annual Rent (Year 1) | D46: 0
C47: Rent Growth % | D47: 0.03
C48: Other Facility Cost (Year 1) | D48: 0
C49: Other Facility Growth % | D49: 0.03
C50: Program Cost per Student (Year 1) | D50: 0
...

Sheet Drivers
B1: Revenue & Expense Drivers
C3: Year 1 | D3: Year 2 | E3: Year 3 | F3: Year 4 | G3: Year 5
B4: Enrollment | C4: ==Assumptions!D11 | D4: ==Assumptions!D12 | E4: ==Assumptions!D13 | F4: ==Assumptions!D14 | G4: ==Assumptions!D15
B5: Tuition Revenue (Net) | C5: ==Assumptions!D11*Assumptions!D18 | D5: ==Assumptions!D12*Assumptions!D18*(1+Assumptions!D19)^1 | E5: ==Assumptions!D13*Assumptions!D18*(1+Assumptions!D19)^2 | F5: ==Assumptions!D14*Assumptions!D18*(1+Assumptions!D19)^3 | G5: ==Assumptions!D15*Assumptions!D18*(1+Assumptions!D19)^4
B6: × Collection Rate Applied | C6: ==C5*Assumptions!D24 | D6: ==D5*Assumptions!D24 | E6: ==E5*Assumptions!D24 | F6: ==F5*Assumptions!D24 | G6: ==G5*Assumptions!D24
B7: ESA / School Choice Revenue | C7: ==Assumptions!D11*Assumptions!D20 | D7: ==Assumptions!D12*Assumptions!D20*(1+Assumptions!D21)^1 | E7: ==Assumptions!D13*Assumptions!D20*(1+Assumptions!D21)^2 | F7: ==Assumptions!D14*Assumptions!D20*(1+Assumptions!D21)^3 | G7: ==Assumptions!D15*Assumptions!D20*(1+Assumptions!D21)^4
B8: Other Earned Revenue | C8: ==Assumptions!D11*Assumptions!D22 | D8: ==Assumptions!D12*Assumptions!D22*(1+Assumptions!D23)^1 | E8: ==Assumptions!D13*Assumptions!D22*(1+Assumptions!D23)^2 | F8: ==Assumptions!D14*Assumptions!D22*(1+Assumptions!D23)^3 | G8: ==Assumptions!D15*Assumptions!D22*(1+Assumptions!D23)^4
B9: Grants & Contributions | C9: ==Assumptions!D25 | D9: ==Assumptions!D25*(1+Assumptions!D26)^1 | E9: ==Assumptions!D25*(1+Assumptions!D26)^2 | F9: ==Assumptions!D25*(1+Assumptions!D26)^3 | G9: ==Assumptions!D25*(1+Assumptions!D26)^4
B10: Total Revenue | C10: ==C6+C7+C8+C9 | D10: ==D6+D7+D8+D9 | E10: ==E6+E7+E8+E9 | F10: ==F6+F7+F8+F9 | G10: ==G6+G7+G8+G9
B12: Teacher FTE (Enrollment ÷ Ratio) | C12: ==CEILING(Assumptions!D11/Assumptions!D29,1) | D12: ==CEILING(Assumptions!D12/Assumptions!D29,1) | E12: ==CEILING(Assumptions!D13/Assumptions!D29,1) | F12: ==CEILING(Assumptions!D14/Assumptions!D29,1) | G12: ==CEILING(Assumptions!D15/Assumptions!D29,1)
B13: Teacher Salaries | C13: ==C12*Assumptions!D30 | D13: ==D12*Assumptions!D30*(1+Assumptions!D31)^1 | E13: ==E12*Assumptions!D30*(1+Assumptions!D31)^2 | F13: ==F12*Assumptions!D30*(1+Assumptions!D31)^3 | G13: ==G12*Assumptions!D30*(1+Assumptions!D31)^4
B14: Admin Salaries | C14: ==Assumptions!D32*Assumptions!D37 | D14: ==Assumptions!D33*Assumptions!D37*(1+Assumptions!D38)^1 | E14: ==Assumptions!D34*Assumptions!D37*(1+Assumptions!D38)^2 | F14: ==Assumptions!D35*Assumptions!D37*(1+Assumptions!D38)^3 | G14: ==Assumptions!D36*Assumptions!D37*(1+Assumptions!D38)^4
B15: Benefits & Payroll Taxes | C15: ==(C13+C14)*Assumptions!D39 | D15: ==(D13+D14)*Assumptions!D39 | E15: ==(E13+E14)*Assumptions!D39 | F15: ==(F13+F14)*Assumptions!D39 | G15: ==(G13+G14)*Assumptions!D39
B16: Total Staffing Cost | C16: ==C13+C14+C15 | D16: ==D13+D14+D15 | E16: ==E13+E14+E15 | F16: ==F13+F14+F15 | G16: ==G13+G14+G15
B18: Rent / Lease | C18: ==Assumptions!D42 | D18: ==Assumptions!D42*(1+Assumptions!D43)^1 | E18: ==Assumptions!D42*(1+Assumptions!D43)^2 | F18: ==Assumptions!D42*(1+Assumptions!D43)^3 | G18: ==Assumptions!D42*(1+Assumptions!D43)^4
B19: Other Facility Costs | C19: ==Assumptions!D44 | D19: ==Assumptions!D44*(1+Assumptions!D45)^1 | E19: ==Assumptions!D44*(1+Assumptions!D45)^2 | F19: ==Assumptions!D44*(1+Assumptions!D45)^3 | G19: ==Assumptions!D44*(1+Assumptions!D45)^4
B20: Program / Curriculum | C20: ==Assumptions!D11*Assumptions!D46 | D20: ==Assumptions!D12*Assumptions!D46*(1+Assumptions!D47)^1 | E20: ==Assumptions!D13*Assumptions!D46*(1+Assumptions!D47)^2 | F20: ==Assumptions!D14*Assumptions!D46*(1+Assumptions!D47)^3 | G20: ==Assumptions!D15*Assumptions!D46*(1+Assumptions!D47)^4
B21: G&A / Technology | C21: ==Assumptions!D48 | D21: ==Assumptions!D48*(1+Assumptions!D49)^1 | E21: ==Assumptions!D48*(1+Assumptions!D49)^2 | F21: ==Assumptions!D48*(1+Assumptions!D49)^3 | G21: ==Assumptions!D48*(1+Assumptions!D49)^4
B22: Total Operating Expenses | C22: ==C18+C19+C20+C21 | D22: ==D18+D19+D20+D21 | E22: ==E18+E19+E20+E21 | F22: ==F18+F19+F20+F21 | G22: ==G18+G19+G20+G21

Sheet 5-Year P&L
B1: 5-Year Pro Forma Profit & Loss
C3: Year 1 | D3: Year 2 | E3: Year 3 | F3: Year 4 | G3: Year 5
B4: Enrollment | C4: ==Assumptions!D11 | D4: ==Assumptions!D12 | E4: ==Assumptions!D13 | F4: ==Assumptions!D14 | G4: ==Assumptions!D15
B6: Tuition Revenue (Net) | C6: ==Drivers!C6 | D6: ==Drivers!D6 | E6: ==Drivers!E6 | F6: ==Drivers!F6 | G6: ==Drivers!G6
B7: ESA / School Choice | C7: ==Drivers!C7 | D7: ==Drivers!D7 | E7: ==Drivers!E7 | F7: ==Drivers!F7 | G7: ==Drivers!G7
B8: Other Revenue | C8: ==Drivers!C8 | D8: ==Drivers!D8 | E8: ==Drivers!E8 | F8: ==Drivers!F8 | G8: ==Drivers!G8
B9: Grants & Contributions | C9: ==Drivers!C9 | D9: ==Drivers!D9 | E9: ==Drivers!E9 | F9: ==Drivers!F9 | G9: ==Drivers!G9
B10: Total Revenue | C10: ==Drivers!C10 | D10: ==Drivers!D10 | E10: ==Drivers!E10 | F10: ==Drivers!F10 | G10: ==Drivers!G10
B12: Total Staffing | C12: ==Drivers!C16 | D12: ==Drivers!D16 | E12: ==Drivers!E16 | F12: ==Drivers!F16 | G12: ==Drivers!G16
B13: Total Operating Expenses | C13: ==Drivers!C22 | D13: ==Drivers!D22 | E13: ==Drivers!E22 | F13: ==Drivers!F22 | G13: ==Drivers!G22
B15: Total Expenses | C15: ==C12+C13 | D15: ==D12+D13 | E15: ==E12+E13 | F15: ==F12+F13 | G15: ==G12+G13
B16: Net Operating Income (NOI) | C16: ==C10-C15 | D16: ==D10-D15 | E16: ==E10-E15 | F16: ==F10-F15 | G16: ==G10-G15
B17: Operating Margin | C17: ==IF(C10>0,C16/C10,0) | D17: ==IF(D10>0,D16/D10,0) | E17: ==IF(E10>0,E16/E10,0) | F17: ==IF(F10>0,F16/F10,0) | G17: ==IF(G10>0,G16/G10,0)

Sheet Cash Flow & DSCR
B1: Cash Flow & Debt Service Coverage
C3: Year 1 | D3: Year 2 | E3: Year 3 | F3: Year 4 | G3: Year 5
B4: Net Operating Income | C4: =='5-Year P&L'!C16 | D4: =='5-Year P&L'!D16 | E4: =='5-Year P&L'!E16 | F4: =='5-Year P&L'!F16 | G4: =='5-Year P&L'!G16
B6: Existing Debt Service | C6: ==Assumptions!D53 | D6: ==Assumptions!D53 | E6: ==Assumptions!D53 | F6: ==Assumptions!D53 | G6: ==Assumptions!D53
B7: Proposed Loan Debt Service | C7: ==IF(Assumptions!D54>0,PMT(Assumptions!D55/12,Assumptions!D56*12,-Assumptions!D54)*12,0) | D7: ==IF(Assumptions!D54>0,PMT(Assumptions!D55/12,Assumptions!D56*12,-Assumptions!D54)*12,0) | E7: ==IF(Assumptions!D54>0,PMT(Assumptions!D55/12,Assumptions!D56*12,-Assumptions!D54)*12,0) | F7: ==IF(Assumptions!D54>0,PMT(Assumptions!D55/12,Assumptions!D56*12,-Assumptions!D54)*12,0) | G7: ==IF(Assumptions!D54>0,PMT(Assumptions!D55/12,Assumptions!D56*12,-Assumptions!D54)*12,0)
B8: Total Debt Service | C8: ==C6+C7 | D8: ==D6+D7 | E8: ==E6+E7 | F8: ==F6+F7 | G8: ==G6+G7
B10: DSCR (NOI ÷ Total Debt Service) | C10: ==IF(C8>0,C4/C8,IF(C4>0,99.9,0)) | D10: ==IF(D8>0,D4/D8,IF(D4>0,99.9,0)) | E10: ==IF(E8>0,E4/E8,IF(E4>0,99.9,0)) | F10: ==IF(F8>0,F4/F8,IF(F4>0,99.9,0)) | G10: ==IF(G8>0,G4/G8,IF(G4>0,99.9,0))
B12: Net Income After Debt | C12: ==C4-C8 | D12: ==D4-D8 | E12: ==E4-E8 | F12: ==F4-F8 | G12: ==G4-G8
B14: Cumulative Cash | C14: ==Assumptions!D52+C12 | D14: ==C14+D12 | E14: ==D14+E12 | F14: ==E14+F12 | G14: ==F14+G12

Sheet Staffing
B1: Staffing Detail
C3: Year 1 | D3: Year 2 | E3: Year 3 | F3: Year 4 | G3: Year 5
B4: Teacher FTE | C4: ==Drivers!C12 | D4: ==Drivers!D12 | E4: ==Drivers!E12 | F4: ==Drivers!F12 | G4: ==Drivers!G12
B5: Admin FTE | C5: ==Assumptions!D32 | D5: ==Assumptions!D33 | E5: ==Assumptions!D34 | F5: ==Assumptions!D35 | G5: ==Assumptions!D36
B6: Total FTE | C6: ==C4+C5 | D6: ==D4+D5 | E6: ==E4+E5 | F6: ==F4+F5 | G6: ==G4+G5

Sheet Loan Snapshot
B1: Proposed Loan Summary
B3: Loan Amount | C3: ==Assumptions!D54
B4: Interest Rate | C4: ==Assumptions!D55
B5: Term (Years) | C5: ==Assumptions!D56
B6: Annual Debt Service | C6: ==IF(Assumptions!D54>0,PMT(Assumptions!D55/12,Assumptions!D56*12,-Assumptions!D54)*12,0)
B8: Year 1 DSCR | C8: =='Cash Flow & DSCR'!C10

Sheet Summary
B1: Model Summary
B3: School Name | C3: ==Assumptions!D5
B4: School Type | C4: ==Assumptions!D7
B5: State | C5: ==Assumptions!D6
B6: Opening Year | C6: ==Assumptions!D8
B8: Year 5 Enrollment | C8: ==Assumptions!D15
B9: Year 5 Revenue | C9: ==Drivers!G10
B10: Year 5 NOI | C10: =='5-Year P&L'!G16
B12: Generated by SchoolStack Budget (schoolstack.ai)
