Workbook

Sheet Cover
B3: SchoolStack Budget
B5: 5-Year Financial Model & Underwriting Workbook
B8: School Name | C8: Liberty STEM Charter School
B9: School Type | C9: Charter School
B10: Entity Type | C10: 501(c)(3) Nonprofit
B11: State | C11: AZ
B12: Fiscal Year Start | C12: Month 7
B13: Model Date | C13: March 25, 2026
B14: Stage | C14: Startup / Pre-Opening
B15: Funding Profile
B18: Table of Contents
B19: 1. | C19: Cover
B20: 2. | C20: Instructions
B21: 3. | C21: Assumptions
B22: 4. | C22: Program Profile
B23: 5. | C23: Enrollment Drivers
B24: 6. | C24: Tuition & Funding
B25: 7. | C25: Staffing Drivers
B26: 8. | C26: OpEx Drivers
B27: 9. | C27: Capital Stack
B28: 10. | C28: Enrollment Tuition Fcst
B29: 11. | C29: Staffing Costs Fcst
B30: 12. | C30: Budget Detail
... B39: 21. | C39: Underwriting Snapshot
B42: CONFIDENTIAL - Prepared by SchoolStack Budget (budget.schoolstack.ai)

Sheet Instructions
B2: How to Use This Workbook
B4: Cell Color Legend
B5: Yellow cells are editable inputs — change these to update your model.
B6: White cells contain formulas — do not edit (they recalculate automatically).
B7: Green cells are key outputs and summary metrics.
B9: Navigation
B10: The Assumptions tab is the central control panel — all other tabs reference it.
B12: Structure
B13: Tabs 5-9: Drivers & inputs
B14: Tabs 10-13: Forecasts & budgets
B15: Tabs 14-17: Financial statements
B16: Tabs 18-21: Analysis & underwriting
... B32: user-provided assumptions and should be independently verified.

Sheet Assumptions
A1: Liberty STEM Charter School - Assumptions
A2: Yellow cells are editable inputs. All other cells are formulas.
A4: SCHOOL PROFILE
A5: School Name | B5: Liberty STEM Charter School
A6: School Type | B6: Charter School
A7: Entity Type | B7: 501(c)(3) Nonprofit
A8: State | B8: AZ
A9: EIN
A10: Stage | B10: Startup / Pre-Opening
A11: Funding Profile
A12: Fiscal Year Start Month | B12: 7
A13: Max Capacity | B13: 600
A15: ENROLLMENT
B16: Year 1 | C16: Year 2 | D16: Year 3 | E16: Year 4 | F16: Year 5
A17: Total Students | B17: 200 | C17: 300 | D17: 400 | E17: 500 | F17: 600
A19: REVENUE DRIVERS
A20: Line Item | B20: Category | C20: Driver | D20: Amount | E20: Escalation %
A21: State Per-Pupil Funding (K-5) | B21: Public Funding | C21: Per Student | D21: 8200 | E21: 0.02
A22: State Per-Pupil Funding (6-8) | B22: Public Funding | C22: Per Student | D22: 8800 | E22: 0.02
A23: Title I Federal Funding | B23: Public Funding | C23: Per Student | D23: 1200 | E23: 0
A24: Charter Startup Grant (CSPP) | B24: Philanthropy | C24: Annual Fixed | D24: 250000 | E24: 0
A25: After-School & Summer Programs | B25: Other Revenue | C25: Per Student | D25: 300 | E25: 0.02
A27: STAFFING
A28: Role | B28: Category | C28: Type | D28: FTE | E28: Rate | F28: Benefits % | G28: Tax %
A29: Executive Director | B29: School Leadership | C29: full_time | D29: 1 | E29: 110000 | F29: 0.25 | G29: 0.0765
A30: Principal | B30: School Leadership | C30: full_time | D30: 1 | E30: 90000 | F30: 0.25 | G30: 0.0765
A31: Dean of Students | B31: School Leadership | C31: full_time | D31: 1 | E31: 75000 | F31: 0.25 | G31: 0.0765
A32: STEM Teachers | B32: Instructional | C32: full_time | D32: 1 | E32: 55000 | F32: 0.22 | G32: 0.0765
A33: General Teachers | B33: Instructional | C33: full_time | D33: 1 | E33: 48000 | F33: 0.22 | G33: 0.0765
A34: Special Education Staff | B34: Student Support | C34: full_time | D34: 1 | E34: 52000 | F34: 0.22 | G34: 0.0765
A35: Office & Finance Staff | B35: Administrative | C35: full_time | D35: 1 | E35: 45000 | F35: 0.2 | G35: 0.0765
A36: Custodial / Maintenance | B36: Operations | C36: full_time | D36: 1 | E36: 35000 | F36: 0 | G36: 0.0765
A38: OPERATING EXPENSES
A39: Line Item | B39: Category | C39: Driver | D39: Amount | E39: Escalation %
A40: STEM Lab Equipment & Curriculum | B40: Instructional / Program | C40: Per Student | D40: 800 | E40: 0.02
A41: 1:1 Chromebooks + Infrastructure | B41: Technology | C41: Per Student | D41: 450 | E41: 0
A42: Utilities & Building Maintenance | B42: Occupancy / Facility | C42: Annual Fixed | D42: 48000 | E42: 0
A43: Insurance (GL, D&O, Workers Comp) | B43: Administrative / General | C43: Annual Fixed | D43: 35000 | E43: 0
A44: Legal, Audit & Compliance | B44: Administrative / General | C44: Annual Fixed | D44: 25000 | E44: 0
A45: Student Transportation | B45: Instructional / Program | C45: Per Student | D45: 400 | E45: 0.03
...

Sheet Program Profile
A1: Program Profile
A3: School Model | B3: charter
A4: School Type | B4: Charter School
A5: Entity Type | B5: 501(c)(3) Nonprofit
A6: Financial Label Convention | B6: Nonprofit (Change in Net Assets / Net Assets)
A7: Stage | B7: Startup / Pre-Opening
A8: Funding Mix
A9: Fiscal Year Start Month | B9: 7
A10: Year 1 Operating Months | B10: 10
A11: Proration Factor | B11: 83.3%
A12: Debt Included | B12: Yes
A13: Max Capacity | B13: 600
A14: Accredited | B14: No
A15: Location | B15: , ,
A16: Facility | B16: Leased

Sheet Enrollment Drivers
A1: Enrollment Drivers
B3: Year 1 | C3: Year 2 | D3: Year 3 | E3: Year 4 | F3: Year 5
A5: TOTAL ENROLLMENT
A6: Total Students | B6: 200 | C6: 300 | D6: 400 | E6: 500 | F6: 600
A7: Max Capacity | B7: 600
A8: Capacity Utilization | B8: 0.33333333 | C8: 0.5 | D8: 0.66666667 | E8: 0.83333333 | F8: 1
A10: Enrollment Growth Rate | B10: - | C10: 0.5 | D10: 0.33333333 | E10: 0.25 | F10: 0.2

Sheet Tuition & Funding
A1: Tuition & Funding Drivers
B3: Year 1 | C3: Year 2 | D3: Year 3 | E3: Year 4 | F3: Year 5
A4: REVENUE BY LINE ITEM
A5: State Per-Pupil Funding (K-5) (Public Funding) | B5: 1640000 | C5: 2509200 | D5: 3412512 | E5: 4350953 | F5: 5325566
A6: State Per-Pupil Funding (6-8) (Public Funding) | B6: 1760000 | C6: 2692800 | D6: 3662208 | E6: 4669315 | F6: 5715242
A7: Title I Federal Funding (Public Funding) | B7: 240000 | C7: 370800 | D7: 509232 | E7: 655636 | F7: 810366
A8: Charter Startup Grant (CSPP) (Philanthropy) | B8: 250000 | C8: 257500 | D8: 265225 | E8: 273182 | F8: 281377
A9: After-School & Summer Programs (Other Revenue) | B9: 60000 | C9: 91800 | D9: 124848 | E9: 159181 | F9: 194838
A10: TOTAL REVENUE | B10: =SUM(B5:B9) -> 3950000 | C10: =SUM(C5:C9) -> 5922100 | D10: =SUM(D5:D9) -> 7974025 | E10: =SUM(E5:E9) -> 10108267 | F10: =SUM(F5:F9) -> 12327389

Sheet Staffing Drivers
A1: Staffing Drivers
A3: Role | B3: Category | C3: FTE | D3: Base Rate | E3: Benefits % | F3: Tax % | G3: Loaded Cost
A4: Executive Director | B4: School Leadership | C4: 1 | D4: 110000 | E4: 0.25 | F4: 0.0765 | G4: 145915
A5: Principal | B5: School Leadership | C5: 1 | D5: 90000 | E5: 0.25 | F5: 0.0765 | G5: 119385
A6: Dean of Students | B6: School Leadership | C6: 1 | D6: 75000 | E6: 0.25 | F6: 0.0765 | G6: 99488
A7: STEM Teachers | B7: Instructional | C7: 1 | D7: 55000 | E7: 0.22 | F7: 0.0765 | G7: 71308
A8: General Teachers | B8: Instructional | C8: 1 | D8: 48000 | E8: 0.22 | F8: 0.0765 | G8: 62232
A9: Special Education Staff | B9: Student Support | C9: 1 | D9: 52000 | E9: 0.22 | F9: 0.0765 | G9: 67418
A10: Office & Finance Staff | B10: Administrative | C10: 1 | D10: 45000 | E10: 0.2 | F10: 0.0765 | G10: 57443
A11: Custodial / Maintenance | B11: Operations | C11: 1 | D11: 35000 | E11: 0 | F11: 0.0765 | G11: 37678
A13: 5-YEAR TOTAL PERSONNEL COST
B14: Year 1 | C14: Year 2 | D14: Year 3 | E14: Year 4 | F14: Year 5
A15: Total Personnel | B15: 550721 | C15: 680691 | D15: 701112 | E15: 722145 | F15: 743809
A16: Personnel as % of Revenue | B16: 0.139423 | C16: 0.11494081 | D16: 0.087924439 | E16: 0.071441031 | F16: 0.060337948
A17: Students per FTE | B17: 25 | C17: 37.5 | D17: 50 | E17: 62.5 | F17: 75

Sheet OpEx Drivers
A1: Operating Expense Drivers
B3: Year 1 | C3: Year 2 | D3: Year 3 | E3: Year 4 | F3: Year 5
A4: Instructional / Program
A5: STEM Lab Equipment & Curriculum | B5: 160000 | C5: 244800 | D5: 332928 | E5: 424483 | F5: 519567
A6: Student Transportation | B6: 80000 | C6: 123600 | D6: 169744 | E6: 218545 | F6: 270122
A7: Food Service (subsidized) | B7: 120000 | C7: 183600 | D7: 249696 | E7: 318362 | F7: 389676
A8: Total Instructional / Program | B8: =SUM(B5:B7) -> 360000 | C8: =SUM(C5:C7) -> 552000 | D8: =SUM(D5:D7) -> 752368 | E8: =SUM(E5:E7) -> 961391 | F8: =SUM(F5:F7) -> 1179365
A9: Technology
A10: 1:1 Chromebooks + Infrastructure | B10: 90000 | C10: 139050 | D10: 190962 | E10: 245864 | F10: 303887
A11: Total Technology | B11: =SUM(B10:B10) -> 90000 | C11: =SUM(C10:C10) -> 139050 | D11: =SUM(D10:D10) -> 190962 | E11: =SUM(E10:E10) -> 245864 | F11: =SUM(F10:F10) -> 303887
A12: Occupancy / Facility
A13: Utilities & Building Maintenance | B13: 48000 | C13: 49440 | D13: 50923 | E13: 52451 | F13: 54024
A14: Total Occupancy / Facility | B14: =SUM(B13:B13) -> 48000 | C14: =SUM(C13:C13) -> 49440 | D14: =SUM(D13:D13) -> 50923 | E14: =SUM(E13:E13) -> 52451 | F14: =SUM(F13:F13) -> 54024
A15: Administrative / General
A16: Insurance (GL, D&O, Workers Comp) | B16: 35000 | C16: 36050 | D16: 37132 | E16: 38245 | F16: 39393
A17: Legal, Audit & Compliance | B17: 25000 | C17: 25750 | D17: 26523 | E17: 27318 | F17: 28138
A18: Marketing & Community Outreach | B18: 20000 | C18: 20600 | D18: 21218 | E18: 21855 | F18: 22510
A19: Total Administrative / General | B19: =SUM(B16:B18) -> 80000 | C19: =SUM(C16:C18) -> 82400 | D19: =SUM(D16:D18) -> 84872 | E19: =SUM(E16:E18) -> 87418 | F19: =SUM(F16:F18) -> 90041
A21: TOTAL OPERATING EXPENSES | B21: =B8+B11+B14+B19 -> 578000 | C21: =C8+C11+C14+C19 -> 822890 | D21: =D8+D11+D14+D19 -> 1079125 | E21: =E8+E11+E14+E19 -> 1347124 | F21: =F8+F11+F14+F19 -> 1627318

Sheet Capital Stack
A1: Capital Stack & Loan Terms
A3: Instrument | B3: Type | C3: Principal | D3: Rate | E3: Term (Yrs) | F3: Annual Payment
A4: Facility Build-Out (Phase 1) | B4: Capital Expense | C4: 350000 | D4: 0 | E4: 0 | F4: 350000
A5: Facility Expansion Loan | B5: Loan | C5: 500000 | D5: 0.065 | E5: 15 | F5: 52266
A6: Equipment Financing | B6: Loan | C6: 75000 | D6: 0.055 | E6: 5 | F6: 17191
A8: Total Annual Debt Service | F8: 69457
A9: Total Loan Principal | F9: 575000

Sheet Enrollment Tuition Fcst
A1: Enrollment & Tuition Forecast
B3: Year 1 | C3: Year 2 | D3: Year 3 | E3: Year 4 | F3: Year 5
A4: Total Students | B4: 200 | C4: 300 | D4: 400 | E4: 500 | F4: 600
A6: REVENUE FORECAST
A7: State Per-Pupil Funding (K-5) | B7: 1640000 | C7: 2509200 | D7: 3412512 | E7: 4350953 | F7: 5325566
A8: State Per-Pupil Funding (6-8) | B8: 1760000 | C8: 2692800 | D8: 3662208 | E8: 4669315 | F8: 5715242
A9: Title I Federal Funding | B9: 240000 | C9: 370800 | D9: 509232 | E9: 655636 | F9: 810366
A10: Charter Startup Grant (CSPP) | B10: 250000 | C10: 257500 | D10: 265225 | E10: 273182 | F10: 281377
A11: After-School & Summer Programs | B11: 60000 | C11: 91800 | D11: 124848 | E11: 159181 | F11: 194838
A12: TOTAL REVENUE | B12: =SUM(B7:B11) -> 3950000 | C12: =SUM(C7:C11) -> 5922100 | D12: =SUM(D7:D11) -> 7974025 | E12: =SUM(E7:E11) -> 10108267 | F12: =SUM(F7:F11) -> 12327389
A14: Revenue per Student | B14: 19750 | C14: 19740 | D14: 19935 | E14: 20217 | F14: 20546

Sheet Staffing Costs Fcst
A1: Staffing Costs Forecast
B3: Year 1 | C3: Year 2 | D3: Year 3 | E3: Year 4 | F3: Year 5
A4: Instructional
A5: STEM Teachers | B5: 59423 | C5: 73447 | D5: 75650 | E5: 77920 | F5: 80257
A6: General Teachers | B6: 51860 | C6: 64099 | D6: 66022 | E6: 68003 | F6: 70043
A7: Total Instructional | B7: =SUM(B5:B6) -> 111283 | C7: =SUM(C5:C6) -> 137546 | D7: =SUM(D5:D6) -> 141672 | E7: =SUM(E5:E6) -> 145922 | F7: =SUM(F5:F6) -> 150300
A8: School Leadership
A9: Executive Director | B9: 121596 | C9: 150292 | D9: 154801 | E9: 159445 | F9: 164229
A10: Principal | B10: 99488 | C10: 122967 | D10: 126656 | E10: 130455 | F10: 134369
A11: Dean of Students | B11: 82906 | C11: 102472 | D11: 105546 | E11: 108713 | F11: 111974
A12: Total School Leadership | B12: =SUM(B9:B11) -> 303990 | C12: =SUM(C9:C11) -> 375731 | D12: =SUM(D9:D11) -> 387003 | E12: =SUM(E9:E11) -> 398613 | F12: =SUM(F9:F11) -> 410572
A13: Student Support
A14: Special Education Staff | B14: 56182 | C14: 69441 | D14: 71524 | E14: 73669 | F14: 75880
A15: Total Student Support | B15: =SUM(B14:B14) -> 56182 | C15: =SUM(C14:C14) -> 69441 | D15: =SUM(D14:D14) -> 71524 | E15: =SUM(E14:E14) -> 73669 | F15: =SUM(F14:F14) -> 75880
A16: Operations
A17: Custodial / Maintenance | B17: 31398 | C17: 38808 | D17: 39972 | E17: 41171 | F17: 42406
A18: Total Operations | B18: =SUM(B17:B17) -> 31398 | C18: =SUM(C17:C17) -> 38808 | D18: =SUM(D17:D17) -> 39972 | E18: =SUM(E17:E17) -> 41171 | F18: =SUM(F17:F17) -> 42406
A19: Administrative
A20: Office & Finance Staff | B20: 47869 | C20: 59166 | D20: 60941 | E20: 62769 | F20: 64652
A21: Total Administrative | B21: =SUM(B20:B20) -> 47869 | C21: =SUM(C20:C20) -> 59166 | D21: =SUM(D20:D20) -> 60941 | E21: =SUM(E20:E20) -> 62769 | F21: =SUM(F20:F20) -> 64652
A23: TOTAL PERSONNEL | B23: =B7+B12+B15+B18+B21 -> 550721 | C23: =C7+C12+C15+C18+C21 -> 680691 | D23: =D7+D12+D15+D18+D21 -> 701112 | E23: =E7+E12+E15+E18+E21 -> 722145 | F23: =F7+F12+F15+F18+F21 -> 743809

Sheet Budget Detail
A1: Liberty STEM Charter School - Budget Detail
B3: Year 1 | C3: Year 2 | D3: Year 3 | E3: Year 4 | F3: Year 5
A4: REVENUE
A5: State Per-Pupil Funding (K-5) | B5: 1366667 | C5: 2509200 | D5: 3412512 | E5: 4350953 | F5: 5325566
A6: State Per-Pupil Funding (6-8) | B6: 1466667 | C6: 2692800 | D6: 3662208 | E6: 4669315 | F6: 5715242
A7: Title I Federal Funding | B7: 200000 | C7: 370800 | D7: 509232 | E7: 655636 | F7: 810366
A8: Charter Startup Grant (CSPP) | B8: 208333 | C8: 257500 | D8: 265225 | E8: 273182 | F8: 281377
A9: After-School & Summer Programs | B9: 50000 | C9: 91800 | D9: 124848 | E9: 159181 | F9: 194838
A10: Total Revenue | B10: =SUM(B5:B9) -> 3291667 | C10: =SUM(C5:C9) -> 5922100 | D10: =SUM(D5:D9) -> 7974025 | E10: =SUM(E5:E9) -> 10108267 | F10: =SUM(F5:F9) -> 12327389
A12: PERSONNEL
A13: Executive Director | B13: 121596 | C13: 150292 | D13: 154801 | E13: 159445 | F13: 164229
A14: Principal | B14: 99488 | C14: 122967 | D14: 126656 | E14: 130455 | F14: 134369
A15: Dean of Students | B15: 82906 | C15: 102472 | D15: 105546 | E15: 108713 | F15: 111974
A16: STEM Teachers | B16: 59423 | C16: 73447 | D16: 75650 | E16: 77920 | F16: 80257
A17: General Teachers | B17: 51860 | C17: 64099 | D17: 66022 | E17: 68003 | F17: 70043
A18: Special Education Staff | B18: 56182 | C18: 69441 | D18: 71524 | E18: 73669 | F18: 75880
A19: Office & Finance Staff | B19: 47869 | C19: 59166 | D19: 60941 | E19: 62769 | F19: 64652
A20: Custodial / Maintenance | B20: 31398 | C20: 38808 | D20: 39972 | E20: 41171 | F20: 42406
A21: Total Personnel | B21: =SUM(B13:B20) -> 550721 | C21: =SUM(C13:C20) -> 680691 | D21: =SUM(D13:D20) -> 701112 | E21: =SUM(E13:E20) -> 722145 | F21: =SUM(F13:F20) -> 743809
A23: OPERATING EXPENSES
A24: Instructional / Program
A25: STEM Lab Equipment & Curriculum | B25: 133333 | C25: 244800 | D25: 332928 | E25: 424483 | F25: 519567
A26: Student Transportation | B26: 66667 | C26: 123600 | D26: 169744 | E26: 218545 | F26: 270122
A27: Food Service (subsidized) | B27: 100000 | C27: 183600 | D27: 249696 | E27: 318362 | F27: 389676
A28: Total Instructional / Program | B28: =SUM(B25:B27) -> 300000 | C28: =SUM(C25:C27) -> 552000 | D28: =SUM(D25:D27) -> 752368 | E28: =SUM(E25:E27) -> 961391 | F28: =SUM(F25:F27) -> 1179365
A29: Technology
A30: 1:1 Chromebooks + Infrastructure | B30: 75000 | C30: 139050 | D30: 190962 | E30: 245864 | F30: 303887
A31: Occupancy / Facility
A32: Utilities & Building Maintenance | B32: 40000 | C32: 49440 | D32: 50923 | E32: 52451 | F32: 54024
A33: Administrative / General
A34: Insurance (GL, D&O, Workers Comp) | B34: 29167 | C34: 36050 | D34: 37132 | E34: 38245 | F34: 39393
A35: Legal, Audit & Compliance | B35: 20833 | C35: 25750 | D35: 26523 | E35: 27318 | F35: 28138
A36: Marketing & Community Outreach | B36: 16667 | C36: 20600 | D36: 21218 | E36: 21855 | F36: 22510
A37: Total Administrative / General | B37: =SUM(B34:B36) -> 66667 | C37: =SUM(C34:C36) -> 82400 | D37: =SUM(D34:D36) -> 84872 | E37: =SUM(E34:E36) -> 87418 | F37: =SUM(F34:F36) -> 90041
A38: Total Operating Expenses | B38: =B28+B30+B32+B37 -> 481667 | C38: =C28+C30+C32+C37 -> 822890 | D38: =D28+D30+D32+D37 -> 1079125 | E38: =E28+E30+E32+E37 -> 1347124 | F38: =F28+F30+F32+F37 -> 1627318
A40: CAPITAL & DEBT SERVICE
A41: Facility Build-Out (Phase 1) | B41: 350000 | C41: 0 | D41: 0 | E41: 0 | F41: 0
A42: Facility Expansion Loan | B42: 52266 | C42: 52266 | D42: 52266 | E42: 52266 | F42: 52266
A43: Equipment Financing | B43: 17191 | C43: 17191 | D43: 17191 | E43: 17191 | F43: 17191
A44: Total Capital & Debt | B44: =SUM(B41:B43) -> 419457 | C44: =SUM(C41:C43) -> 69457 | D44: =SUM(D41:D43) -> 69457 | E44: =SUM(E41:E43) -> 69457 | F44: =SUM(F41:F43) -> 69457

Sheet Budget Summary
A1: Liberty STEM Charter School - Budget Summary
B3: Year 1 | C3: Year 2 | D3: Year 3 | E3: Year 4 | F3: Year 5
A4: Total Revenue | B4: ='Budget Detail'!B10 -> 3291667 | C4: ='Budget Detail'!C10 -> 5922100 | D4: ='Budget Detail'!D10 -> 7974025 | E4: ='Budget Detail'!E10 -> 10108267 | F4: ='Budget Detail'!F10 -> 12327389
A5: Total Personnel | B5: ='Budget Detail'!B21 -> 550721 | C5: ='Budget Detail'!C21 -> 680691 | D5: ='Budget Detail'!D21 -> 701112 | E5: ='Budget Detail'!E21 -> 722145 | F5: ='Budget Detail'!F21 -> 743809
A6: Total Operating Expenses | B6: ='Budget Detail'!B38 -> 481667 | C6: ='Budget Detail'!C38 -> 822890 | D6: ='Budget Detail'!D38 -> 1079125 | E6: ='Budget Detail'!E38 -> 1347124 | F6: ='Budget Detail'!F38 -> 1627318
A7: Total Capital & Debt Service | B7: ='Budget Detail'!B44 -> 419457 | C7: ='Budget Detail'!C44 -> 69457 | D7: ='Budget Detail'!D44 -> 69457 | E7: ='Budget Detail'!E44 -> 69457 | F7: ='Budget Detail'!F44 -> 69457
A8: Total Expenses | B8: =SUM(B5:B7) -> 1451845 | C8: =SUM(C5:C7) -> 1573038 | D8: =SUM(D5:D7) -> 1849694 | E8: =SUM(E5:E7) -> 2138726 | F8: =SUM(F5:F7) -> 2440585
A10: KEY METRICS
A11: Change in Net Assets | B11: =B4-B8 -> 1839822 | C11: =C4-C8 -> 4349062 | D11: =D4-D8 -> 6124331 | E11: =E4-E8 -> 7969541 | F11: =F4-F8 -> 9886805
A12: Net Margin % | B12: =IF(B4=0,0,B11/B4) -> 0.55893317 | C12: =IF(C4=0,0,C11/C4) -> 0.73437827 | D12: =IF(D4=0,0,D11/D4) -> 0.76803504 | E12: =IF(E4=0,0,E11/E4) -> 0.78841812 | F12: =IF(F4=0,0,F11/F4) -> 0.80201935
A13: Cumulative Change in Net Assets | B13: 1839822 | C13: 6188883 | D13: 12313214 | E13: 20282755 | F13: 30169560
A14: Revenue per Student | B14: 16458 | C14: 19740 | D14: 19935 | E14: 20217 | F14: 20546
A15: Cost per Student | B15: 7259 | C15: 5243 | D15: 4624 | E15: 4277 | F15: 4068

Sheet Monthly Cash Flow Y1
A1: Liberty STEM Charter School - Year 1 Monthly Cash Flow
B2: July | C2: August | D2: September | E2: October | F2: November | G2: December | H2: January | I2: February | J2: March | K2: April | L2: May | M2: June | N2: Annual Total
A3: REVENUE
A4: Total Revenue | B4: 395000 | C4: 395000 | D4: 395000 | E4: 395000 | F4: 395000 | G4: 395000 | H4: 395000 | I4: 395000 | J4: 395000 | K4: 395000 | L4: 0 | M4: 0 | N4: =SUM(B4:M4) -> 3950000
A6: EXPENSES
A7: Personnel | B7: 55072 | C7: 55072 | D7: 55072 | E7: 55072 | F7: 55072 | G7: 55072 | H7: 55072 | I7: 55072 | J7: 55072 | K7: 55072 | L7: 0 | M7: 0 | N7: =SUM(B7:M7) -> 550721
A8: Operating Expenses | B8: 48167 | C8: 48167 | D8: 48167 | E8: 48167 | F8: 48167 | G8: 48167 | H8: 48167 | I8: 48167 | J8: 48167 | K8: 48167 | L8: 0 | M8: 0 | N8: =SUM(B8:M8) -> 481667
A9: Debt Service | B9: 34955 | C9: 34955 | D9: 34955 | E9: 34955 | F9: 34955 | G9: 34955 | H9: 34955 | I9: 34955 | J9: 34955 | K9: 34955 | L9: 34955 | M9: 34955 | N9: =SUM(B9:M9) -> 419457
A11: CASH FLOW
A12: Total Expenses | B12: =B7+B8+B9 -> 138194 | C12: =C7+C8+C9 -> 138194 | D12: =D7+D8+D9 -> 138194 | E12: =E7+E8+E9 -> 138194 | F12: =F7+F8+F9 -> 138194 | G12: =G7+G8+G9 -> 138194 | H12: =H7+H8+H9 -> 138194 | I12: =I7+I8+I9 -> 138194 | ... M12: =M7+M8+M9 -> 34955 | N12: =SUM(B12:M12) -> 1451850
A13: Net Cash Flow | B13: =B4-B12 -> 256806 | C13: =C4-C12 -> 256806 | D13: =D4-D12 -> 256806 | E13: =E4-E12 -> 256806 | F13: =F4-F12 -> 256806 | G13: =G4-G12 -> 256806 | H13: =H4-H12 -> 256806 | I13: =I4-I12 -> 256806 | ... M13: =M4-M12 -> -34955 | N13: =SUM(B13:M13) -> 2498150
A14: Cumulative Cash | B14: =B17+B13 -> 256806 | C14: =B14+C13 -> 513612 | D14: =C14+D13 -> 770418 | E14: =D14+E13 -> 1027224 | F14: =E14+F13 -> 1284030 | G14: =F14+G13 -> 1540836 | H14: =G14+H13 -> 1797642 | I14: =H14+I13 -> 2054448 | J14: =I14+J13 -> 2311254 | ... M14: =L14+M13 -> 2498150 | N14: =M14 -> 2498150
A16: CASH FLOW METRICS
A17: Starting Cash | B17: 0
A18: Ending Cash (Month 12) | B18: =M14 -> 2498150
A19: Minimum Cash Month | B19: =MIN(B14:M14) -> 256806

Sheet 5-Year Operating Stmt
A1: Liberty STEM Charter School - 5-Year Operating Statement
B3: Year 1 | C3: Year 2 | D3: Year 3 | E3: Year 4 | F3: Year 5
A4: REVENUE
A5: Total Revenue | B5: 3291667 | C5: 5922100 | D5: 7974025 | E5: 10108267 | F5: 12327389
A7: EXPENSES
A8: Personnel | B8: 550721 | C8: 680691 | D8: 701112 | E8: 722145 | F8: 743809
A9: Operating Expenses | B9: 481667 | C9: 822890 | D9: 1079125 | E9: 1347124 | F9: 1627318
A10: Capital & Debt Service | B10: 419457 | C10: 69457 | D10: 69457 | E10: 69457 | F10: 69457
A11: Total Expenses | B11: =SUM(B8:B10) -> 1451845 | C11: =SUM(C8:C10) -> 1573038 | D11: =SUM(D8:D10) -> 1849694 | E11: =SUM(E8:E10) -> 2138726 | F11: =SUM(F8:F10) -> 2440585
A13: BOTTOM LINE
A14: Change in Net Assets | B14: =B5-B11 -> 1839822 | C14: =C5-C11 -> 4349062 | D14: =D5-D11 -> 6124331 | E14: =E5-E11 -> 7969541 | F14: =F5-F11 -> 9886805
A15: Net Margin % | B15: =IF(B5=0,0,B14/B5) -> 0.55893317 | C15: =IF(C5=0,0,C14/C5) -> 0.73437827 | D15: =IF(D5=0,0,D14/D5) -> 0.76803504 | E15: =IF(E5=0,0,E14/E5) -> 0.78841812 | F15: =IF(F5=0,0,F14/F5) -> 0.80201935

Sheet Debt Schedule
A1: Debt Schedule
B3: Year 1 | C3: Year 2 | D3: Year 3 | E3: Year 4 | F3: Year 5
A4: LOAN TERMS
A5: Loan Name | B5: Principal | C5: Annual Rate | D5: Term (Years) | E5: Annual Payment
A6: Facility Expansion Loan | B6: 500000 | C6: 0.065 | D6: 15 | E6: =IF(OR(B6=0,D6=0),0,IF(C6=0,B6/D6,-PMT(C6/12,D6*12,B6)*12)) -> 52266
A7: Equipment Financing | B7: 75000 | C7: 0.055 | D7: 5 | E7: =IF(OR(B7=0,D7=0),0,IF(C7=0,B7/D7,-PMT(C7/12,D7*12,B7)*12)) -> 17191
A9: AMORTIZATION: Facility Expansion Loan
A10: Beginning Balance | B10: =B6 -> 500000 | C10: =B14 -> 479634 | D10: =C14 -> 457904 | E10: =D14 -> 434719 | F10: =E14 -> 409980
A11: Interest | B11: =IF(OR(D6=0,1>D6*12),0,IF(C6=0,0,-CUMIPMT(C6/12,D6*12,B6,1,12,0))) -> 31900 | C11: =IF(OR(D6=0,13>D6*12),0,IF(C6=0,0,-CUMIPMT(C6/12,D6*12,B6,13,24,0))) -> 30536 | D11: =IF(OR(D6=0,25>D6*12),0,IF(C6=0,0,-CUMIPMT(C6/12,D6*12,B6,25,36,0))) -> 29081 | E11: =IF(OR(D6=0,37>D6*12),0,IF(C6=0,0,-CUMIPMT(C6/12,D6*12,B6,37,48,0))) -> 27528 | F11: =IF(OR(D6=0,49>D6*12),0,IF(C6=0,0,-CUMIPMT(C6/12,D6*12,B6,49,60,0))) -> 25872
A12: Principal Payment | B12: =IF(OR(D6=0,1>D6*12),0,IF(C6=0,B6/D6,-CUMPRINC(C6/12,D6*12,B6,1,12,0))) -> 20366 | C12: =IF(OR(D6=0,13>D6*12),0,IF(C6=0,B6/D6,-CUMPRINC(C6/12,D6*12,B6,13,24,0))) -> 21730 | D12: =IF(OR(D6=0,25>D6*12),0,IF(C6=0,B6/D6,-CUMPRINC(C6/12,D6*12,B6,25,36,0))) -> 23185 | E12: =IF(OR(D6=0,37>D6*12),0,IF(C6=0,B6/D6,-CUMPRINC(C6/12,D6*12,B6,37,48,0))) -> 24738 | F12: =IF(OR(D6=0,49>D6*12),0,IF(C6=0,B6/D6,-CUMPRINC(C6/12,D6*12,B6,49,60,0))) -> 26395
A13: Total Payment | B13: =B11+B12 -> 52266 | C13: =C11+C12 -> 52266 | D13: =D11+D12 -> 52266 | E13: =E11+E12 -> 52266 | F13: =F11+F12 -> 52266
A14: Ending Balance | B14: =MAX(0,B10-B12) -> 479634 | C14: =MAX(0,C10-C12) -> 457904 | D14: =MAX(0,D10-D12) -> 434719 | E14: =MAX(0,E10-E12) -> 409980 | F14: =MAX(0,F10-F12) -> 383586
A16: AMORTIZATION: Equipment Financing
A17: Beginning Balance | B17: =B7 -> 75000 | C17: =B21 -> 61599 | D17: =C21 -> 47443 | E17: =D21 -> 32488 | F17: =E21 -> 16690
A18: Interest | B18: =IF(OR(D7=0,1>D7*12),0,IF(C7=0,0,-CUMIPMT(C7/12,D7*12,B7,1,12,0))) -> 3791 | C18: =IF(OR(D7=0,13>D7*12),0,IF(C7=0,0,-CUMIPMT(C7/12,D7*12,B7,13,24,0))) -> 3035 | D18: =IF(OR(D7=0,25>D7*12),0,IF(C7=0,0,-CUMIPMT(C7/12,D7*12,B7,25,36,0))) -> 2236 | E18: =IF(OR(D7=0,37>D7*12),0,IF(C7=0,0,-CUMIPMT(C7/12,D7*12,B7,37,48,0))) -> 1393 | F18: =IF(OR(D7=0,49>D7*12),0,IF(C7=0,0,-CUMIPMT(C7/12,D7*12,B7,49,60,0))) -> 501
A19: Principal Payment | B19: =IF(OR(D7=0,1>D7*12),0,IF(C7=0,B7/D7,-CUMPRINC(C7/12,D7*12,B7,1,12,0))) -> 13401 | C19: =IF(OR(D7=0,13>D7*12),0,IF(C7=0,B7/D7,-CUMPRINC(C7/12,D7*12,B7,13,24,0))) -> 14156 | D19: =IF(OR(D7=0,25>D7*12),0,IF(C7=0,B7/D7,-CUMPRINC(C7/12,D7*12,B7,25,36,0))) -> 14955 | E19: =IF(OR(D7=0,37>D7*12),0,IF(C7=0,B7/D7,-CUMPRINC(C7/12,D7*12,B7,37,48,0))) -> 15799 | F19: =IF(OR(D7=0,49>D7*12),0,IF(C7=0,B7/D7,-CUMPRINC(C7/12,D7*12,B7,49,60,0))) -> 16690
A20: Total Payment | B20: =B18+B19 -> 17191 | C20: =C18+C19 -> 17191 | D20: =D18+D19 -> 17191 | E20: =E18+E19 -> 17191 | F20: =F18+F19 -> 17191
A21: Ending Balance | B21: =MAX(0,B17-B19) -> 61599 | C21: =MAX(0,C17-C19) -> 47443 | D21: =MAX(0,D17-D19) -> 32488 | E21: =MAX(0,E17-E19) -> 16690 | F21: =MAX(0,F17-F19) -> 0
A23: TOTAL ALL LOANS
A24: Total Debt Service | B24: =B13+B20 -> 69457 | C24: =C13+C20 -> 69457 | D24: =D13+D20 -> 69457 | E24: =E13+E20 -> 69457 | F24: =F13+F20 -> 69457
A25: Total Outstanding Debt | B25: =B14+B21 -> 541233 | C25: =C14+C21 -> 505347 | D25: =D14+D21 -> 467207 | E25: =E14+E21 -> 426670 | F25: =F14+F21 -> 383586

Sheet Balance Sheet
A1: Liberty STEM Charter School - Balance Sheet
B3: Year 1 | C3: Year 2 | D3: Year 3 | E3: Year 4 | F3: Year 5
A4: ASSETS
A5: Cash & Equivalents | B5: ='Monthly Cash Flow Y1'!M14 -> 2498150 | C5: =B5+'5-Year Operating Stmt'!C14 -> 6847212 | D5: =B5+'5-Year Operating Stmt'!C14+'5-Year Operating Stmt'!D14 -> 12971542 | E5: =B5+'5-Year Operating Stmt'!C14+'5-Year Operating Stmt'!D14+'5-Year Operating Stmt'!E14 -> 20941083 | F5: =B5+'5-Year Operating Stmt'!C14+'5-Year Operating Stmt'!D14+'5-Year Operating Stmt'!E14+'5-Year Operating Stmt'!F14 -> 30827888
A6: Accounts Receivable | B6: 0 | C6: 0 | D6: 0 | E6: 0 | F6: 0
A7: Fixed Assets | B7: 100000 | C7: 100000 | D7: 100000 | E7: 100000 | F7: 100000
A8: Other Assets | B8: 0 | C8: 0 | D8: 0 | E8: 0 | F8: 0
A9: Total Assets | B9: =SUM(B5:B8) -> 2598150 | C9: =SUM(C5:C8) -> 6947212 | D9: =SUM(D5:D8) -> 13071542 | E9: =SUM(E5:E8) -> 21041083 | F9: =SUM(F5:F8) -> 30927888
A11: LIABILITIES
A12: Accounts Payable | B12: 0 | C12: 0 | D12: 0 | E12: 0 | F12: 0
A13: Long-Term Debt | B13: ='Debt Schedule'!B25 -> 541233 | C13: ='Debt Schedule'!C25 -> 505347 | D13: ='Debt Schedule'!D25 -> 467207 | E13: ='Debt Schedule'!E25 -> 426670 | F13: ='Debt Schedule'!F25 -> 383586
A14: Total Liabilities | B14: =SUM(B12:B13) -> 541233 | C14: =SUM(C12:C13) -> 505347 | D14: =SUM(D12:D13) -> 467207 | E14: =SUM(E12:E13) -> 426670 | F14: =SUM(F12:F13) -> 383586
A16: NET ASSETS
A17: Net Assets | B17: =B9-B14 -> 2056917 | C17: =C9-C14 -> 6441865 | D17: =D9-D14 -> 12604335 | E17: =E9-E14 -> 20614413 | F17: =F9-F14 -> 30544302
A19: Balance Check (should = 0) | B19: =B9-B14-B17 -> 0 | C19: =C9-C14-C17 -> 0 | D19: =D9-D14-D17 -> 0 | E19: =E9-E14-E17 -> 0 | F19: =F9-F14-F17 -> 0

Sheet DSCR & Covenants
A1: DSCR & Covenant Checks
B3: Year 1 | C3: Year 2 | D3: Year 3 | E3: Year 4 | F3: Year 5
A4: CASH FLOW & DEBT
A5: Revenue | B5: 3291667 | C5: 5922100 | D5: 7974025 | E5: 10108267 | F5: 12327389
A6: Personnel | B6: 550721 | C6: 680691 | D6: 701112 | E6: 722145 | F6: 743809
A7: Operating Expenses | B7: 481667 | C7: 822890 | D7: 1079125 | E7: 1347124 | F7: 1627318
A8: CFADS (Rev - Pers - OpEx) | B8: =B5-B6-B7 -> 2259279 | C8: =C5-C6-C7 -> 4418519 | D8: =D5-D6-D7 -> 6193788 | E8: =E5-E6-E7 -> 8038998 | F8: =F5-F6-F7 -> 9956262
A9: Debt Service | B9: 69457 | C9: 69457 | D9: 69457 | E9: 69457 | F9: 69457
A10: DSCR | B10: =IF(B9=0,"N/A",B8/B9) -> 32.53 | C10: =IF(C9=0,"N/A",C8/C9) -> 63.61 | D10: =IF(D9=0,"N/A",D8/D9) -> 89.17 | E10: =IF(E9=0,"N/A",E8/E9) -> 115.74 | F10: =IF(F9=0,"N/A",F8/F9) -> 143.34
A12: LIQUIDITY METRICS
A13: Ending Cash | B13: 2498150 | C13: 6847212 | D13: 12971542 | E13: 20941083 | F13: 30827888
A14: Days Cash on Hand | B14: =IF((B6+B7+B9)=0,0,(B13/(B6+B7+B9))*365) -> 828 | C14: =IF((C6+C7+C9)=0,0,(C13/(C6+C7+C9))*365) -> 1589 | D14: =IF((D6+D7+D9)=0,0,(D13/(D6+D7+D9))*365) -> 2560 | E14: =IF((E6+E7+E9)=0,0,(E13/(E6+E7+E9))*365) -> 3574 | F14: =IF((F6+F7+F9)=0,0,(F13/(F6+F7+F9))*365) -> 4610
A15: Months of Runway | B15: =IF((B6+B7+B9)=0,0,B13/((B6+B7+B9)/12)) -> 27.2 | C15: =IF((C6+C7+C9)=0,0,C13/((C6+C7+C9)/12)) -> 52.2 | D15: =IF((D6+D7+D9)=0,0,D13/((D6+D7+D9)/12)) -> 84.2 | E15: =IF((E6+E7+E9)=0,0,E13/((E6+E7+E9)/12)) -> 117.5 | F15: =IF((F6+F7+F9)=0,0,F13/((F6+F7+F9)/12)) -> 151.6
A16: Capacity Utilization | B16: 0.33333333 | C16: 0.5 | D16: 0.66666667 | E16: 0.83333333 | F16: 1
A18: BREAK-EVEN ANALYSIS
A19: Revenue per Student | B19: 16458 | C19: 19740 | D19: 19935 | E19: 20217 | F19: 20546
A20: Fixed Costs (Pers + Debt) | B20: 620178 | C20: 750148 | D20: 770569 | E20: 791603 | F20: 813267
A21: Variable Cost per Student (OpEx) | B21: 2408 | C21: 2743 | D21: 2698 | E21: 2694 | F21: 2712
A22: Break-Even Enrollment | B22: 45 | C22: 45 | D22: 45 | E22: 46 | F22: 46
A24: COVENANT CHECKS
A25: DSCR ≥ 1.15x | B25: PASS | C25: PASS | D25: PASS | E25: PASS | F25: PASS
A26: Positive Net Income | B26: PASS | C26: PASS | D26: PASS | E26: PASS | F26: PASS
A27: Capacity ≥ 70% | B27: FAIL | C27: FAIL | D27: FAIL | E27: PASS | F27: PASS
A28: Cash Reserve ≥ 3 months | B28: PASS | C28: PASS | D28: PASS | E28: PASS | F28: PASS
A29: Days Cash ≥ 45 | B29: PASS | C29: PASS | D29: PASS | E29: PASS | F29: PASS

Sheet Sources & Uses
A1: Sources & Uses
A3: SOURCES | B3: Amount | D3: USES | E3: Amount
A4: Facility Expansion Loan | B4: 500000 | D4: Working Capital | E4: 575000
A5: Equipment Financing | B5: 75000
A7: Total Sources | B7: 575000 | D7: Total Uses | E7: 575000
A8: Sources - Uses (should = 0) | B8: 0

Sheet Scenarios
A1: Scenario Analysis
A3: CONSERVATIVE (25% FEWER STUDENTS)
A4: Enrollment: -25% | Revenue: +0% | Staffing: -10% | Facility: +0% | Expenses: +0%
B5: Year 1 | C5: Year 2 | D5: Year 3 | E5: Year 4 | F5: Year 5
A6: Revenue | B6: 2468750 | C6: 4441575 | D6: 5980519 | E6: 7581200 | F6: 9245542
A7: Total Expenses | B7: 1046773 | C7: 1504969 | D7: 1779583 | E7: 2066512 | F7: 2366204
A8: Change in Net Assets | B8: 1421977 | C8: 2936606 | D8: 4200936 | E8: 5514689 | F8: 6879338
A9: Net Margin % | B9: 0.57599072 | C9: 0.66116314 | D9: 0.70243665 | E9: 0.7274163 | F9: 0.74407087
A10: DSCR | B10: 21.47 | C10: 43.28 | D10: 61.48 | E10: 80.4 | F10: 100.04
A11: Break-Even Enrollment | B11: 43 | C11: 43 | D11: 43 | E11: 44 | F11: 44
A13: STATE FUNDING CUT (-10%)
A14: Enrollment: +0% | Revenue: -10% | Staffing: +0% | Facility: +0% | Expenses: +0%
B15: Year 1 | C15: Year 2 | D15: Year 3 | E15: Year 4 | F15: Year 5
A16: Revenue | B16: 2962500 | C16: 5329890 | D16: 7176623 | E16: 9097440 | F16: 11094650
A17: Total Expenses | B17: 1101845 | C17: 1573038 | D17: 1849694 | E17: 2138726 | F17: 2440585
A18: Change in Net Assets | B18: 1860655 | C18: 3756852 | D18: 5326928 | E18: 6958714 | F18: 8654066
A19: Net Margin % | B19: 0.6280692 | C19: 0.70486475 | D19: 0.74226116 | E19: 0.76490902 | F19: 0.78002151
A20: DSCR | B20: 27.79 | C20: 55.09 | D20: 77.69 | E20: 101.19 | F20: 125.6
A21: Break-Even Enrollment | B21: 50 | C21: 50 | D21: 51 | E21: 52 | F21: 52
A23: FULL CAPACITY AHEAD OF PLAN
A24: Enrollment: +15% | Revenue: +0% | Staffing: +10% | Facility: +0% | Expenses: +5%
B25: Year 1 | C25: Year 2 | D25: Year 3 | E25: Year 4 | F25: Year 5
A26: Revenue | B26: 3785417 | C26: 6810415 | D26: 9170129 | E26: 11624507 | F26: 14176498
A27: Total Expenses | B27: 1179000 | C27: 1679780 | D27: 1971216 | E27: 2275674 | F27: 2593630
A28: Change in Net Assets | B28: 2606416 | C28: 5130635 | D28: 7198913 | E28: 9348833 | F28: 11582868
A29: Net Margin % | B29: 0.68854145 | C29: 0.7533513 | D29: 0.78503948 | E29: 0.80423477 | F29: 0.81704719
A30: DSCR | B30: 38.53 | C30: 74.87 | D30: 104.64 | E30: 135.6 | F30: 167.76
A31: Break-Even Enrollment | B31: 48 | C31: 48 | D31: 49 | E31: 49 | F31: 50

Sheet Underwriting Snapshot
A1: Underwriting Snapshot - Loan Committee Summary
A3: SCHOOL PROFILE
A4: School Name | B4: Liberty STEM Charter School
A5: Type | B5: Charter School
A6: Entity | B6: 501(c)(3) Nonprofit
A7: Stage | B7: Startup / Pre-Opening
A8: State | B8: AZ
A9: Funding
A11: 5-YEAR FINANCIAL TREND
D12: Year 1 | E12: Year 2 | F12: Year 3 | G12: Year 4 | H12: Year 5
A13: Revenue | D13: 3291667 | E13: 5922100 | F13: 7974025 | G13: 10108267 | H13: 12327389
A14: Total Expenses | D14: 1101845 | E14: 1573038 | F14: 1849694 | G14: 2138726 | H14: 2440585
A15: Change in Net Assets | D15: 1839822 | E15: 4349062 | F15: 6124331 | G15: 7969541 | H15: 9886805
A16: Cash Position | D16: 2498150 | E16: 6847212 | F16: 12971542 | G16: 20941083 | H16: 30827888
A17: Outstanding Debt | D17: 541233 | E17: 505347 | F17: 467207 | G17: 426670 | H17: 383586
A19: KEY RATIOS
D20: Year 1 | E20: Year 2 | F20: Year 3 | G20: Year 4 | H20: Year 5
A21: Net Margin | D21: 0.55893317 | E21: 0.73437827 | F21: 0.76803504 | G21: 0.78841812 | H21: 0.80201935
A22: DSCR | D22: 32.53 | E22: 63.61 | F22: 89.17 | G22: 115.74 | H22: 143.34
A23: Capacity Utilization | D23: 0.33333333 | E23: 0.5 | F23: 0.66666667 | G23: 0.83333333 | H23: 1
A24: Enrollment | D24: 200 | E24: 300 | F24: 400 | G24: 500 | H24: 600
A26: Prepared by SchoolStack Budget - budget.schoolstack.ai
