Workbook

Sheet Instructions
B2: How to Use This Workbook
B3: Bright Horizons Microschool
B4: Generated May 9, 2026 · llc_single
B6: Cell Color Legend
B7: Blue cells are editable inputs — change these to update your model.
B8: White cells contain formulas — do not edit (they recalculate automatically).
B9: Green cells are key outputs and summary metrics.
B11: Navigation
B12: The Assumptions tab is the central control panel — all other tabs reference it.
B14: Structure
B15: 5-Year Model: Detailed revenue, expense, and cash projections
B16: Pro Forma: Consolidated income statement
... B37: user-provided assumptions and should be independently verified.

Sheet Assumptions
A1: Bright Horizons Microschool - Financial Model Assumptions
B2: Editable assumption — change this value | E2: Calculated — driven by formula
A4: SCHOOL PROFILE
A5: School Name | B5: Bright Horizons Microschool
A6: State | B6: AZ
A7: School Type | B7: Microschool
A8: Legal Entity | B8: LLC (Single Member)
A9: EIN | B9: 88-1234567
A10: Website | B10: N/A
A11: Fiscal Year Start | B11: July
A12: Maximum Capacity | B12: 25
A13: School Stage | B13: New School
A14: Location | B14: 123 Main St, Scottsdale, AZ, 85251
A16: ENROLLMENT | B16: 2026-27 | C16: 2027-28 | D16: 2028-29 | E16: 2029-30 | F16: 2030-31
A17: Students Enrolled | B17: 12 | C17: 18 | D17: 22 | E17: 25 | F17: 25
A19: REVENUE SOURCES | B19: Category | C19: Driver | D19: Yr 1 Amount | E19: Escalation % | F19: Billing Mo. | G19: Collection % | H19: Note
A20: Tuition | B20: Tuition & Fees | C20: Per Student | D20: 12000 | E20: 0 | F20: 10 | G20: 1
A21: Registration Fee | B21: Tuition & Fees | C21: Per Student | D21: 250 | E21: 0 | F21: 12 | G21: 1
A22: AZ ESA Funds | B22: School Choice | C22: Per Student | D22: 7000 | E22: 0 | F22: 12 | G22: 1
A23: Annual Fundraising | B23: Philanthropy | C23: Annual Fixed | D23: 5000 | E23: 0 | F23: 12 | G23: 1
A24: Scholarship Discount | B24: Tuition Offsets | C24: % of Base | D24: 10 | E24: 0 | F24: 12 | G24: 1
A27: STAFFING ROSTER | B27: Function | C27: Type | D27: FTE | E27: Annual Rate | F27: Benefits % | G27: Payroll Tax % | H27: Benefits Elig. | I27: Notes
A28: Founder / Head of School | B28: School Leadership | C28: FT | D28: 1 | E28: 55000 | F28: 0.2 | G28: 0.0765 | H28: Yes
A29: Lead Teacher | B29: Instructional | C29: FT | D29: 1 | E29: 45000 | F29: 0.2 | G29: 0.0765 | H29: Yes
A30: Teaching Assistant | B30: Instructional | C30: PT | D30: 0.5 | E30: 28000 | F30: 0 | G30: 0.0765 | H30: No
A32: FACILITIES & OCCUPANCY | B32: Amount | C32: Frequency
A33: Ownership Type | B33: Rent
A34: Monthly Rent | B34: 2500 | C34: Monthly
A35: Annual Rent Escalation | B35: 0.03
A37: OPERATING EXPENSES | B37: Category | C37: Driver | D37: Yr 1 Amount | E37: Escalation % | F37: Note
A38: Rent | B38: Occupancy / Facility | C38: Monthly | D38: 2500 | E38: 0.03
A39: Utilities | B39: Occupancy / Facility | C39: Monthly | D39: 300 | E39: 0
A40: Insurance | B40: Occupancy / Facility | C40: Annual Fixed | D40: 2400 | E40: 0
A41: Curriculum & Materials | B41: Instructional / Program | C41: Per Student | D41: 500 | E41: 0
A42: Technology | B42: Technology | C42: Per Student | D42: 300 | E42: 0
A43: Marketing | B43: Administrative / General | C43: Annual Fixed | D43: 3000 | E43: 0
A45: CAPITAL & DEBT | B45: Is Loan? | C45: Yr 1 Amount | D45: Principal | E45: Interest Rate | F45: Term (Yrs) | G45: Annual Payment | H45: Note
A46: Equipment Loan | B46: Yes | C46: 0 | D46: 30000 | E46: 0.06 | F46: 5 | G46: 6960
A48: GROWTH & TIMING ASSUMPTIONS
A49: Annual Salary Escalation | B49: 0.03
...

Sheet 5-Year Model
A1: Bright Horizons Microschool - 5-Year Financial Model
A2: Projections prepared on an accrual basis. School currently keeps books on a undetermined basis.
B3: 2026-27 | C3: 2027-28 | D3: 2028-29 | E3: 2029-30 | F3: 2030-31
A4: Students Enrolled | B4: =Assumptions!B17 -> 12 | C4: =Assumptions!C17 -> 18 | D4: =Assumptions!D17 -> 22 | E4: =Assumptions!E17 -> 25 | F4: =Assumptions!F17 -> 25
A6: REVENUE
A7: Tuition | B7: 120000 | C7: 221400 | D7: 277365 | E7: 323067 | F7: 331144
A8: Registration Fee | B8: 2500 | C8: 4613 | D8: 5778 | E8: 6731 | F8: 6899
A9: AZ ESA Funds | B9: 70000 | C9: 129150 | D9: 161796 | E9: 188456 | F9: 193167
A10: Annual Fundraising | B10: 4167 | C10: 5125 | D10: 5253 | E10: 5384 | F10: 5519
A11: Scholarship Discount | B11: -12000 | C11: -22140 | D11: -27736 | E11: -32307 | F11: -33114
A12: TOTAL REVENUE | B12: =SUM(B7:B11) -> 184667 | C12: =SUM(C7:C11) -> 337594 | D12: =SUM(D7:D11) -> 421052 | E12: =SUM(E7:E11) -> 488847 | F12: =SUM(F7:F11) -> 500177
A14: PERSONNEL
A15: Founder / Head of School (School Leadership) | B15: 58506 | C15: 72314 | D15: 74483 | E15: 76718 | F15: 79019
A16: Lead Teacher (Instructional) | B16: 47869 | C16: 59166 | D16: 60941 | E16: 62769 | F16: 64652
A17: Teaching Assistant (Instructional) | B17: 12559 | C17: 15523 | D17: 15989 | E17: 16468 | F17: 16963
A18: TOTAL PERSONNEL | B18: =SUM(B15:B17) -> 118934 | C18: =SUM(C15:C17) -> 147003 | D18: =SUM(D15:D17) -> 151413 | E18: =SUM(E15:E17) -> 155955 | F18: =SUM(F15:F17) -> 160634
A20: OPERATING EXPENSES
A21: Instructional / Program
A22: Curriculum & Materials (Per Student) | B22: 5000 | C22: 9225 | D22: 11557 | E22: 13461 | F22: 13798
A23: Total Instructional / Program | B23: 5000 | C23: 9225 | D23: 11557 | E23: 13461 | F23: 13798
A24: Technology
A25: Technology (Per Student) | B25: 3000 | C25: 5535 | D25: 6934 | E25: 8077 | F25: 8279
A26: Total Technology | B26: 3000 | C26: 5535 | D26: 6934 | E26: 8077 | F26: 8279
A27: Occupancy / Facility
A28: Rent (Monthly) | B28: 25000 | C28: 30900 | D28: 31827 | E28: 32782 | F28: 33765
A29: Utilities (Monthly) | B29: 3000 | C29: 3690 | D29: 3782 | E29: 3877 | F29: 3974
A30: Insurance (Annual Fixed) | B30: 2000 | C30: 2460 | D30: 2522 | E30: 2585 | F30: 2649
A31: Total Occupancy / Facility | B31: 30000 | C31: 37050 | D31: 38131 | E31: 39244 | F31: 40388
A32: Administrative / General
A33: Marketing (Annual Fixed) | B33: 2500 | C33: 3075 | D33: 3152 | E33: 3231 | F33: 3311
A34: Total Administrative / General | B34: 2500 | C34: 3075 | D34: 3152 | E34: 3231 | F34: 3311
A35: TOTAL OPERATING EXPENSES | B35: =B23+B26+B31+B34 -> 40500 | C35: =C23+C26+C31+C34 -> 54885 | D35: =D23+D26+D31+D34 -> 59774 | E35: =E23+E26+E31+E34 -> 64012 | F35: =F23+F26+F31+F34 -> 65776
A37: CAPITAL & DEBT SERVICE
A38: Equipment Loan | B38: 6960 | C38: 6960 | D38: 6960 | E38: 6960 | F38: 6960
A39: TOTAL CAPITAL & DEBT SERVICE | B39: =SUM(B38:B38) -> 6960 | C39: =SUM(C38:C38) -> 6960 | D39: =SUM(D38:D38) -> 6960 | E39: =SUM(E38:E38) -> 6960 | F39: =SUM(F38:F38) -> 6960
A41: INCOME STATEMENT SUMMARY
A42: Total Revenue | B42: =B12 -> 184667 | C42: =C12 -> 337594 | D42: =D12 -> 421052 | E42: =E12 -> 488847 | F42: =F12 -> 500177
A43: Total Personnel | B43: =B18 -> 118934 | C43: =C18 -> 147003 | D43: =D18 -> 151413 | E43: =E18 -> 155955 | F43: =F18 -> 160634
A44: Total Operating Expenses | B44: =B35 -> 40500 | C44: =C35 -> 54885 | D44: =D35 -> 59774 | E44: =E35 -> 64012 | F44: =F35 -> 65776
A45: Total Capital & Debt Service | B45: =B39 -> 6960 | C45: =C39 -> 6960 | D45: =D39 -> 6960 | E45: =E39 -> 6960 | F45: =F39 -> 6960
...

Sheet Year 1 Pro Forma
A1: Bright Horizons Microschool - 2026-27 Pro Forma
B2: July | C2: August | D2: September | E2: October | F2: November | G2: December | H2: January | I2: February | J2: March | K2: April | L2: May | M2: June | N2: 2026-27 Total
A3: REVENUE
A4: Tuition | B4: 14400 | C4: 14400 | D4: 14400 | E4: 14400 | F4: 14400 | G4: 14400 | H4: 14400 | I4: 14400 | J4: 14400 | K4: 14400 | L4: 0 | M4: 0 | N4: =SUM(B4:M4) -> 120000
A5: Registration Fee | B5: 300 | C5: 300 | D5: 300 | E5: 300 | F5: 300 | G5: 300 | H5: 300 | I5: 300 | J5: 300 | K5: 300 | L5: 0 | M5: 0 | N5: =SUM(B5:M5) -> 2500
A6: AZ ESA Funds | B6: 8400 | C6: 8400 | D6: 8400 | E6: 8400 | F6: 8400 | G6: 8400 | H6: 8400 | I6: 8400 | J6: 8400 | K6: 8400 | L6: 0 | M6: 0 | N6: =SUM(B6:M6) -> 70000
A7: Annual Fundraising | B7: 500 | C7: 500 | D7: 500 | E7: 500 | F7: 500 | G7: 500 | H7: 500 | I7: 500 | J7: 500 | K7: 500 | L7: 0 | M7: 0 | N7: =SUM(B7:M7) -> 4167
A8: Scholarship Discount | B8: 0 | C8: 0 | D8: 0 | E8: 0 | F8: 0 | G8: 0 | H8: 0 | I8: 0 | J8: 0 | K8: 0 | L8: 0 | M8: 0 | N8: =SUM(B8:M8) -> 0
A9: TOTAL REVENUE | B9: =SUM(B4:B8) -> 155900 | C9: =SUM(C4:C8) -> 7460 | D9: =SUM(D4:D8) -> 7460 | E9: =SUM(E4:E8) -> 7460 | F9: =SUM(F4:F8) -> 7460 | G9: =SUM(G4:G8) -> 7460 | H9: =SUM(H4:H8) -> 7460 | I9: =SUM(I4:I8) -> 7460 | ... M9: =SUM(M4:M8) -> 0 | N9: =SUM(B9:M9) -> 221600
A11: PERSONNEL
A12: Founder / Head of School | B12: 5851 | C12: 5851 | D12: 5851 | E12: 5851 | F12: 5851 | G12: 5851 | H12: 5851 | I12: 5851 | J12: 5851 | K12: 5851 | L12: 0 | M12: 0 | N12: =SUM(B12:M12) -> 58506
A13: Lead Teacher | B13: 4787 | C13: 4787 | D13: 4787 | E13: 4787 | F13: 4787 | G13: 4787 | H13: 4787 | I13: 4787 | J13: 4787 | K13: 4787 | L13: 0 | M13: 0 | N13: =SUM(B13:M13) -> 47869
A14: Teaching Assistant | B14: 1256 | C14: 1256 | D14: 1256 | E14: 1256 | F14: 1256 | G14: 1256 | H14: 1256 | I14: 1256 | J14: 1256 | K14: 1256 | L14: 0 | M14: 0 | N14: =SUM(B14:M14) -> 12559
A15: TOTAL PERSONNEL | B15: =SUM(B12:B14) -> 11893 | C15: =SUM(C12:C14) -> 11893 | D15: =SUM(D12:D14) -> 11893 | E15: =SUM(E12:E14) -> 11893 | F15: =SUM(F12:F14) -> 11893 | G15: =SUM(G12:G14) -> 11893 | H15: =SUM(H12:H14) -> 11893 | I15: =SUM(I12:I14) -> 11893 | ... M15: =SUM(M12:M14) -> 0 | N15: =SUM(B15:M15) -> 118934
A17: OPERATING EXPENSES
A18: Instructional / Program
A19: Curriculum & Materials | B19: 500 | C19: 500 | D19: 500 | E19: 500 | F19: 500 | G19: 500 | H19: 500 | I19: 500 | J19: 500 | K19: 500 | L19: 0 | M19: 0 | N19: =SUM(B19:M19) -> 5000
A20: Total Instructional / Program | B20: 500 | C20: 500 | D20: 500 | E20: 500 | F20: 500 | G20: 500 | H20: 500 | I20: 500 | J20: 500 | K20: 500 | L20: 0 | M20: 0 | N20: =SUM(B20:M20) -> 5000
A21: Technology
A22: Technology | B22: 300 | C22: 300 | D22: 300 | E22: 300 | F22: 300 | G22: 300 | H22: 300 | I22: 300 | J22: 300 | K22: 300 | L22: 0 | M22: 0 | N22: =SUM(B22:M22) -> 3000
A23: Total Technology | B23: 300 | C23: 300 | D23: 300 | E23: 300 | F23: 300 | G23: 300 | H23: 300 | I23: 300 | J23: 300 | K23: 300 | L23: 0 | M23: 0 | N23: =SUM(B23:M23) -> 3000
A24: Occupancy / Facility
A25: Rent | B25: 2500 | C25: 2500 | D25: 2500 | E25: 2500 | F25: 2500 | G25: 2500 | H25: 2500 | I25: 2500 | J25: 2500 | K25: 2500 | L25: 0 | M25: 0 | N25: =SUM(B25:M25) -> 25000
A26: Utilities | B26: 300 | C26: 300 | D26: 300 | E26: 300 | F26: 300 | G26: 300 | H26: 300 | I26: 300 | J26: 300 | K26: 300 | L26: 0 | M26: 0 | N26: =SUM(B26:M26) -> 3000
A27: Insurance | B27: 200 | C27: 200 | D27: 200 | E27: 200 | F27: 200 | G27: 200 | H27: 200 | I27: 200 | J27: 200 | K27: 200 | L27: 0 | M27: 0 | N27: =SUM(B27:M27) -> 2000
A28: Total Occupancy / Facility | B28: 3000 | C28: 3000 | D28: 3000 | E28: 3000 | F28: 3000 | G28: 3000 | H28: 3000 | I28: 3000 | J28: 3000 | K28: 3000 | L28: 0 | M28: 0 | N28: =SUM(B28:M28) -> 30000
A29: Administrative / General
A30: Marketing | B30: 250 | C30: 250 | D30: 250 | E30: 250 | F30: 250 | G30: 250 | H30: 250 | I30: 250 | J30: 250 | K30: 250 | L30: 0 | M30: 0 | N30: =SUM(B30:M30) -> 2500
A31: Total Administrative / General | B31: 250 | C31: 250 | D31: 250 | E31: 250 | F31: 250 | G31: 250 | H31: 250 | I31: 250 | J31: 250 | K31: 250 | L31: 0 | M31: 0 | N31: =SUM(B31:M31) -> 2500
A32: TOTAL OPERATING EXPENSES | B32: =B20+B23+B28+B31 -> 4050 | C32: =C20+C23+C28+C31 -> 4050 | D32: =D20+D23+D28+D31 -> 4050 | E32: =E20+E23+E28+E31 -> 4050 | F32: =F20+F23+F28+F31 -> 4050 | G32: =G20+G23+G28+G31 -> 4050 | H32: =H20+H23+H28+H31 -> 4050 | I32: =I20+I23+I28+I31 -> 4050 | ... M32: =M20+M23+M28+M31 -> 0 | N32: =SUM(B32:M32) -> 40500
A34: Capital & Debt Service | B34: 580 | C34: 580 | D34: 580 | E34: 580 | F34: 580 | G34: 580 | H34: 580 | I34: 580 | J34: 580 | K34: 580 | L34: 580 | M34: 580 | N34: =SUM(B34:M34) -> 6960
A36: MONTHLY CASH FLOW
A37: Total Expenses | B37: =B15+B32+B34 -> 16523 | C37: =C15+C32+C34 -> 16523 | D37: =D15+D32+D34 -> 16523 | E37: =E15+E32+E34 -> 16523 | F37: =F15+F32+F34 -> 16523 | G37: =G15+G32+G34 -> 16523 | H37: =H15+H32+H34 -> 16523 | I37: =I15+I32+I34 -> 16523 | ... M37: =M15+M32+M34 -> 580 | N37: =SUM(B37:M37) -> 166390
A38: Net Cash Flow | B38: =B9-B37 -> 139377 | C38: =C9-C37 -> -9063 | D38: =D9-D37 -> -9063 | E38: =E9-E37 -> -9063 | F38: =F9-F37 -> -9063 | G38: =G9-G37 -> -9063 | H38: =H9-H37 -> -9063 | I38: =I9-I37 -> -9063 | ... M38: =M9-M37 -> -580 | N38: =SUM(B38:M38) -> 55210
A39: Cumulative Cash | B39: =0+B38 -> 139377 | C39: =B39+C38 -> 130314 | D39: =C39+D38 -> 121251 | E39: =D39+E38 -> 112188 | F39: =E39+F38 -> 103125 | G39: =F39+G38 -> 94062 | H39: =G39+H38 -> 84999 | I39: =H39+I38 -> 75936 | J39: =I39+J38 -> 66873 | ... M39: =L39+M38 -> 55210 | N39: =M39 -> 55210
A41: CASH FLOW METRICS
A42: Starting Cash | B42: 0
A43: Ending Cash (Month 12) | B43: =M39 -> 55210
A44: Minimum Cash Month | B44: =MIN(B39:M39) -> 55210
A46: Built by SchoolStack Budget • budget.schoolstack.ai

Sheet Decision History
B1: Decision History
B2: Track record of 5 tracked decisions (2 pursued, 1 on hold, 2 declined). Each entry shows the modeled change, the outcome the team logged, and any retrospective notes captured after the fact.
B4: Decision | C4: Type | D4: Outcome | E4: Applied to base model? | F4: Outcome logged | G4: Modeled change | H4: What happened (retrospective)
B5: Add Middle School program | C5: Add a program | D5: Pursued | E5: [APPLIED] Folded into the base model on Apr 12, 2025 | F5: Apr 10, 2025 | G5: • Program: Middle School (6-8) • Tuition $14,000/yr • Adds 72 cumulative students (5 yrs) • +2 FTE | H5: Launched in fall 2025; enrollment hit plan within 1 student.
B6: Increase retention focus | C6: Change enrollment | D6: Pursued | E6: [PENDING] Pending apply to base model | F6: Mar 5, 2025 | G6: • Enrollment +14 cumulative • Retention 92% | H6: Retention initiatives approved; planner will reflect after Q2 board review.
B7: Evaluate downtown campus | C7: Evaluate a site | D7: On hold | E7: — | F7: Mar 25, 2025 | G7: • Rent $8,500/mo • Rent escalation 4% • Sqft +1500 • Fit-out $75,000 (Y1) | H7: Landlord negotiations paused while waiting on city zoning ruling.
B8: Reduce K cohort | C8: Change enrollment | D8: Declined | E8: — | F8: Mar 15, 2025 | G8: • Enrollment -8 cumulative • Tuition -$500/student | H8: Board declined; enrollment goals retained as originally modeled.
B9: Move to larger building | C9: Evaluate a site | D9: Declined | E9: — | F9: Feb 10, 2025 | G9: • Rent $12,000/mo • Sqft +4000 | H9: Costs out of reach; revisited next year after capital campaign.
B11: Generated by SchoolStack Budget (budget.schoolstack.ai)

Sheet Financial Health
B2: Bright Horizons Microschool — Financial Health Dashboard
B3: Generated May 9, 2026
B4: ● Green = healthy | D4: ◐ Yellow = monitor | F4: ○ Red = action needed
B6: Metric | C6: Year 1 | D6: Year 2 | E6: Year 3 | F6: Year 4 | G6: Year 5 | H6: Benchmark
B7: Enrollment | C7: 12 | D7: 18 | E7: 22 | F7: 25 | G7: 25
B8: Revenue | C8: 221600 | D8: 337594 | E8: 421052.15 | F8: 488847.26 | G8: 500176.93
B9: Personnel | C9: 118934.17 | D9: 147002.63 | E9: 151412.71 | F9: 155955.09 | G9: 160633.74
B10: Operating Expenses | C10: 37600 | D10: 48735 | E10: 53469.875 | F10: 57550.294 | G10: 59152.961
B11: Debt Service | C11: 6959.8086 | D11: 6959.8086 | E11: 6959.8086 | F11: 6959.8086 | G11: 6959.8086
B12: Net Income | C12: 58106.025 | D12: 134896.56 | E12: 209209.76 | F12: 268382.07 | G12: 273430.42
B13: Ending Cash | C13: 58106.025 | D13: 193002.59 | E13: 402212.35 | F13: 670594.42 | G13: 944024.84
B14: Net Margin | C14: 0.2622113 | D14: 0.39958222 | E14: 0.49687375 | F14: 0.54901007 | G14: 0.54666739
B15: Revenue per Student | C15: 18466.667 | D15: 18755.222 | E15: 19138.734 | F15: 19553.891 | G15: 20007.077 | H15: ≥ $10,000
B16: Cost per Student | C16: 13624.498 | D16: 11260.969 | E16: 9629.1997 | F16: 8818.6077 | G16: 9069.8605
B17: Instructional / Student | C17: 500 | D17: 512.5 | E17: 525.3125 | F17: 538.44531 | G17: 551.90645
B18: Facility / Student | C18: 2083.3333 | D18: 1716.6667 | E18: 1446.6818 | F18: 1311.2724 | G18: 1350.6106 | H18: ≤ $2,000 / $2k–$3.5k / > $3,500
B19: Surplus per Student | C19: 4842.1687 | D19: 7494.2534 | E19: 9509.5345 | F19: 10735.283 | G19: 10937.217
B20: Payroll % | C20: 0.53670653 | D20: 0.43544207 | E20: 0.35960559 | F20: 0.31902621 | G20: 0.32115384 | H20: ≤ 55%
B21: Facility % | C21: 0.11281588 | D21: 0.091530063 | E21: 0.075589211 | F21: 0.067059412 | G21: 0.067506641 | H21: ≤ 15%
B22: Operating Margin | C22: 0.29361838 | D22: 0.42019814 | E22: 0.51340331 | F22: 0.56324725 | G22: 0.56058209 | H22: ≥ 10%
B23: Revenue Sources | C23: 3 | D23: 3 | E23: 3 | F23: 3 | G23: 3 | H23: ≥ 3 sources
B24: DSCR | C24: 9.3487964 | D24: 20.382223 | E24: 31.0597 | F24: 39.561703 | G24: 40.28706 | H24: ≥ 1.25x
B25: Break-even Year | C25: =IF('5-Year Model'!B50>=0,"✓ Break-even","") -> ✓ Break-even | D25: =IF(AND('5-Year Model'!C50>=0,'5-Year Model'!B50<0),"✓ Break-even","") -> 0 | E25: =IF(AND('5-Year Model'!D50>=0,'5-Year Model'!C50<0),"✓ Break-even","") -> 0 | F25: =IF(AND('5-Year Model'!E50>=0,'5-Year Model'!D50<0),"✓ Break-even","") -> 0 | G25: =IF(AND('5-Year Model'!F50>=0,'5-Year Model'!E50<0),"✓ Break-even","") -> 0 | H25: Year 1
B26: Cash Runway (Months) | C26: 4 | D26: 11 | E26: 23 | F26: 37 | G26: 50 | H26: ≥ 24 months
B27: Days Cash on Hand | C27: 130 | D27: 348 | E27: 693 | F27: 1110 | G27: 1520 | H27: ≥ 90 days
B29: FINANCIAL HEALTH SIGNALS | C29: Status | D29: Assessment | F29: Watch Item
B30: Viability | C30: ● Healthy | D30: The model reaches profit early and sustains strong margins through Year 5. | F30: Compare your real Year 1 enrollment against this projection as students enroll.
B31: Liquidity | C31: ● Healthy | D31: Cash stays positive throughout the projection and reserves exceed 3 months of expenses. | F31: Maintain reserves as a buffer against seasonal revenue dips.
B32: Staffing Burden | C32: ● Healthy | D32: Staffing at 32% of revenue leaves room for facilities, programs, and reserves. | F32: As you add staff, ensure staffing stays below 60% of revenue.
B33: Facility Burden | C33: ● Healthy | D33: Facility costs at 7% of revenue are well-managed and leave budget for programs. | F33: Watch for rent escalation clauses that could push this higher over time.
B34: Debt Affordability | C34: ● Healthy | D34: DSCR of 40.29x provides comfortable coverage of debt payments with room to spare. | F34: Maintain this ratio as you take on any additional debt.
B35: Revenue Concentration | C35: ● Healthy | D35: Revenue is anchored to enrollment-driven income — the strongest foundation for a school model. A focused revenue stream is a strength when backed by dependable demand. | F35: Continue to pressure-test enrollment assumptions: recruitment pipeline, waitlist depth, retention rates, and collection reliability.
B36: Reserve Strength | C36: ● Healthy | D36: 50.0 months of reserves by Year 5 — a strong buffer for unexpected costs. | F36: Continue growing reserves toward 6 months for best-in-class financial health.
B38: Summary | C38: 7 Healthy | 0 Watch | 0 Needs Attention
B40: Built by SchoolStack Budget • budget.schoolstack.ai
