Workbook

Sheet Instructions
B2: How to Use This Workbook
B3: Liberty Learning Co-Op
B4: Generated March 27, 2026 · llc_single
B6: Cell Color Legend
B7: Blue cells are editable inputs — change these to update your model.
B8: White cells contain formulas — do not edit (they recalculate automatically).
B9: Green cells are key outputs and summary metrics.
B11: Navigation
B12: The Assumptions tab is the central control panel — all other tabs reference it.
B14: Structure
B15: 5-Year Model: Detailed revenue, expense, and cash projections
B16: Pro Forma: Consolidated income statement
... B37: user-provided assumptions and should be independently verified.

Sheet Assumptions
A1: Liberty Learning Co-Op - Financial Model Assumptions
B2: Editable assumption — change this value | E2: Calculated — driven by formula
A4: SCHOOL PROFILE
A5: School Name | B5: Liberty Learning Co-Op
A6: State | B6: AZ
A7: School Type | B7: Homeschool Co-Op
A8: Legal Entity | B8: LLC (Single Member)
A9: EIN | B9: 86-5551234
A10: Website | B10: N/A
A11: Fiscal Year Start | B11: July
A12: Maximum Capacity | B12: 40
A13: School Stage | B13: New School
A14: Location | B14: 789 Desert Way, Mesa, AZ, 85201
A16: ENROLLMENT | B16: 2026-27 | C16: 2027-28 | D16: 2028-29 | E16: 2029-30 | F16: 2030-31
A17: Students Enrolled | B17: 15 | C17: 22 | D17: 30 | E17: 36 | F17: 40
A19: REVENUE SOURCES | B19: Category | C19: Driver | D19: Yr 1 Amount | E19: Escalation % | F19: Billing Mo. | G19: Collection % | H19: Note
A20: Co-Op Tuition | B20: Tuition & Fees | C20: Per Student | D20: 6000 | E20: 0 | F20: 10 | G20: 1
A21: Materials Fee | B21: Tuition & Fees | C21: Per Student | D21: 200 | E21: 0 | F21: 12 | G21: 1
A22: ESA Revenue | B22: School Choice | C22: Per Student | D22: 7000 | E22: 0 | F22: 12 | G22: 1
A23: Annual Fundraising | B23: Philanthropy | C23: Annual Fixed | D23: 3000 | E23: 0 | F23: 12 | G23: 1
A26: STAFFING ROSTER | B26: Function | C26: Type | D26: FTE | E26: Annual Rate | F26: Benefits % | G26: Payroll Tax % | H26: Benefits Elig. | I26: Notes
A27: Director / Lead Educator | B27: School Leadership | C27: FT | D27: 1 | E27: 48000 | F27: 0.2 | G27: 0.0765 | H27: Yes
A28: Assistant Educator | B28: Instructional | C28: PT | D28: 0.5 | E28: 30000 | F28: 0 | G28: 0.0765 | H28: No
A30: FACILITIES & OCCUPANCY | B30: Amount | C30: Frequency
A31: Ownership Type | B31: Rent
A32: Monthly Rent | B32: 1800 | C32: Monthly
A33: Annual Rent Escalation | B33: 0.03
A35: OPERATING EXPENSES | B35: Category | C35: Driver | D35: Yr 1 Amount | E35: Escalation % | F35: Note
A36: Rent | B36: Occupancy / Facility | C36: Monthly | D36: 1800 | E36: 0.03
A37: Utilities | B37: Occupancy / Facility | C37: Monthly | D37: 200 | E37: 0
A38: Insurance | B38: Occupancy / Facility | C38: Annual Fixed | D38: 1800 | E38: 0
A39: Curriculum & Materials | B39: Instructional / Program | C39: Per Student | D39: 400 | E39: 0
A40: Technology | B40: Technology | C40: Per Student | D40: 250 | E40: 0
A42: CAPITAL & DEBT | B42: Is Loan? | C42: Yr 1 Amount | D42: Principal | E42: Interest Rate | F42: Term (Yrs) | G42: Annual Payment | H42: Note
A44: GROWTH & TIMING ASSUMPTIONS
A45: Annual Salary Escalation | B45: 0.03
A46: General Cost Inflation | B46: 0.025
A47: Year 1 Proration Factor | B47: 0.83333333 | C47: (10 of 12 months)
A48: Tuition Escalation Rate | B48: 0.03
A49: Management Fee % | B49: 0
...

Sheet 5-Year Model
A1: Liberty Learning Co-Op - 5-Year Financial Model
B2: 2026-27 | C2: 2027-28 | D2: 2028-29 | E2: 2029-30 | F2: 2030-31
A3: Students Enrolled | B3: =Assumptions!B17 -> 15 | C3: =Assumptions!C17 -> 22 | D3: =Assumptions!D17 -> 30 | E3: =Assumptions!E17 -> 36 | F3: =Assumptions!F17 -> 40
A5: REVENUE
A6: Co-Op Tuition | B6: 75000 | C6: 135300 | D6: 189112 | E6: 232608 | F6: 264915
A7: Materials Fee | B7: 2500 | C7: 4510 | D7: 6304 | E7: 7754 | F7: 8831
A8: ESA Revenue | B8: 87500 | C8: 157850 | D8: 220631 | E8: 271376 | F8: 309068
A9: Annual Fundraising | B9: 2500 | C9: 3075 | D9: 3152 | E9: 3231 | F9: 3311
A10: TOTAL REVENUE | B10: =SUM(B6:B9) -> 167500 | C10: =SUM(C6:C9) -> 300735 | D10: =SUM(D6:D9) -> 419199 | E10: =SUM(E6:E9) -> 514969 | F10: =SUM(F6:F9) -> 586125
A12: PERSONNEL
A13: Director / Lead Educator (School Leadership) | B13: 51060 | C13: 63110 | D13: 65003 | E13: 66954 | F13: 68962
A14: Assistant Educator (Instructional) | B14: 13456 | C14: 16632 | D14: 17131 | E14: 17645 | F14: 18174
A15: TOTAL PERSONNEL | B15: =SUM(B13:B14) -> 64516 | C15: =SUM(C13:C14) -> 79742 | D15: =SUM(D13:D14) -> 82134 | E15: =SUM(E13:E14) -> 84598 | F15: =SUM(F13:F14) -> 87136
A17: OPERATING EXPENSES
A18: Instructional / Program
A19: Curriculum & Materials (Per Student) | B19: 5000 | C19: 9020 | D19: 12607 | E19: 15507 | F19: 17661
A20: Total Instructional / Program | B20: 5000 | C20: 9020 | D20: 12607 | E20: 15507 | F20: 17661
A21: Technology
A22: Technology (Per Student) | B22: 3125 | C22: 5638 | D22: 7880 | E22: 9692 | F22: 11038
A23: Total Technology | B23: 3125 | C23: 5638 | D23: 7880 | E23: 9692 | F23: 11038
A24: Occupancy / Facility
A25: Rent (Monthly) | B25: 18000 | C25: 22248 | D25: 22915 | E25: 23603 | F25: 24311
A26: Utilities (Monthly) | B26: 2000 | C26: 2460 | D26: 2521 | E26: 2585 | F26: 2649
A27: Insurance (Annual Fixed) | B27: 1500 | C27: 1845 | D27: 1891 | E27: 1938 | F27: 1987
A28: Total Occupancy / Facility | B28: 21500 | C28: 26553 | D28: 27327 | E28: 28126 | F28: 28947
A29: TOTAL OPERATING EXPENSES | B29: =B20+B23+B28 -> 29625 | C29: =C20+C23+C28 -> 41211 | D29: =D20+D23+D28 -> 47815 | E29: =E20+E23+E28 -> 53325 | F29: =F20+F23+F28 -> 57646
A31: CAPITAL & DEBT SERVICE
A32: TOTAL CAPITAL & DEBT SERVICE | B32: 0 | C32: 0 | D32: 0 | E32: 0 | F32: 0
A34: INCOME STATEMENT SUMMARY
A35: Total Revenue | B35: =B10 -> 167500 | C35: =C10 -> 300735 | D35: =D10 -> 419199 | E35: =E10 -> 514969 | F35: =F10 -> 586125
A36: Total Personnel | B36: =B15 -> 64516 | C36: =C15 -> 79742 | D36: =D15 -> 82134 | E36: =E15 -> 84598 | F36: =F15 -> 87136
A37: Total Operating Expenses | B37: =B29 -> 29625 | C37: =C29 -> 41211 | D37: =D29 -> 47815 | E37: =E29 -> 53325 | F37: =F29 -> 57646
A38: Total Capital & Debt Service | B38: =B32 -> 0 | C38: =C32 -> 0 | D38: =D32 -> 0 | E38: =E32 -> 0 | F38: =F32 -> 0
A39: Total Expenses | B39: =B36+B37+B38 -> 94141 | C39: =C36+C37+C38 -> 120953 | D39: =D36+D37+D38 -> 129949 | E39: =E36+E37+E38 -> 137923 | F39: =F36+F37+F38 -> 144782
A41: Profit / (Loss) | B41: =B35-B39 -> 73359 | C41: =C35-C39 -> 179782 | D41: =D35-D39 -> 289250 | E41: =E35-E39 -> 377046 | F41: =F35-F39 -> 441343
A42: Profit Margin % | B42: =IF(B35=0,"",B41/B35) -> 0.44 | C42: =IF(C35=0,"",C41/C35) -> 0.6 | D42: =IF(D35=0,"",D41/D35) -> 0.69 | E42: =IF(E35=0,"",E41/E35) -> 0.73 | F42: =IF(F35=0,"",F41/F35) -> 0.75
A43: Cumulative Profit | B43: =B41 -> 73359 | C43: =B43+C41 -> 253141 | D43: =C43+D41 -> 542391 | E43: =D43+E41 -> 919437 | F43: =E43+F41 -> 1360780
A44: Break-even | B44: ✓ Break-even
A46: CASH FLOW & DEBT COVERAGE
A47: CFADS (Cash Flow Available for Debt Service) | B47: =B35-B36-B37 -> 73359 | C47: =C35-C36-C37 -> 179782 | D47: =D35-D36-D37 -> 289250 | E47: =E35-E36-E37 -> 377046 | F47: =F35-F36-F37 -> 441343
...

Sheet Year 1 Pro Forma
A1: Liberty Learning Co-Op - 2026-27 Pro Forma
B2: July | C2: August | D2: September | E2: October | F2: November | G2: December | H2: January | I2: February | J2: March | K2: April | L2: May | M2: June | N2: 2026-27 Total
A3: REVENUE
A4: Co-Op Tuition | B4: 9000 | C4: 9000 | D4: 9000 | E4: 9000 | F4: 9000 | G4: 9000 | H4: 9000 | I4: 9000 | J4: 9000 | K4: 9000 | L4: 0 | M4: 0 | N4: =SUM(B4:M4) -> 75000
A5: Materials Fee | B5: 300 | C5: 300 | D5: 300 | E5: 300 | F5: 300 | G5: 300 | H5: 300 | I5: 300 | J5: 300 | K5: 300 | L5: 0 | M5: 0 | N5: =SUM(B5:M5) -> 2500
A6: ESA Revenue | B6: 10500 | C6: 10500 | D6: 10500 | E6: 10500 | F6: 10500 | G6: 10500 | H6: 10500 | I6: 10500 | J6: 10500 | K6: 10500 | L6: 0 | M6: 0 | N6: =SUM(B6:M6) -> 87500
A7: Annual Fundraising | B7: 300 | C7: 300 | D7: 300 | E7: 300 | F7: 300 | G7: 300 | H7: 300 | I7: 300 | J7: 300 | K7: 300 | L7: 0 | M7: 0 | N7: =SUM(B7:M7) -> 2500
A8: TOTAL REVENUE | B8: =SUM(B4:B7) -> 103800 | C8: =SUM(C4:C7) -> 10800 | D8: =SUM(D4:D7) -> 10800 | E8: =SUM(E4:E7) -> 10800 | F8: =SUM(F4:F7) -> 10800 | G8: =SUM(G4:G7) -> 10800 | H8: =SUM(H4:H7) -> 10800 | I8: =SUM(I4:I7) -> 10800 | ... M8: =SUM(M4:M7) -> 0 | N8: =SUM(B8:M8) -> 201000
A10: PERSONNEL
A11: Director / Lead Educator | B11: 5106 | C11: 5106 | D11: 5106 | E11: 5106 | F11: 5106 | G11: 5106 | H11: 5106 | I11: 5106 | J11: 5106 | K11: 5106 | L11: 0 | M11: 0 | N11: =SUM(B11:M11) -> 51060
A12: Assistant Educator | B12: 1346 | C12: 1346 | D12: 1346 | E12: 1346 | F12: 1346 | G12: 1346 | H12: 1346 | I12: 1346 | J12: 1346 | K12: 1346 | L12: 0 | M12: 0 | N12: =SUM(B12:M12) -> 13456
A13: TOTAL PERSONNEL | B13: =SUM(B11:B12) -> 6452 | C13: =SUM(C11:C12) -> 6452 | D13: =SUM(D11:D12) -> 6452 | E13: =SUM(E11:E12) -> 6452 | F13: =SUM(F11:F12) -> 6452 | G13: =SUM(G11:G12) -> 6452 | H13: =SUM(H11:H12) -> 6452 | I13: =SUM(I11:I12) -> 6452 | ... M13: =SUM(M11:M12) -> 0 | N13: =SUM(B13:M13) -> 64516
A15: OPERATING EXPENSES
A16: Instructional / Program
A17: Curriculum & Materials | B17: 500 | C17: 500 | D17: 500 | E17: 500 | F17: 500 | G17: 500 | H17: 500 | I17: 500 | J17: 500 | K17: 500 | L17: 0 | M17: 0 | N17: =SUM(B17:M17) -> 5000
A18: Total Instructional / Program | B18: 500 | C18: 500 | D18: 500 | E18: 500 | F18: 500 | G18: 500 | H18: 500 | I18: 500 | J18: 500 | K18: 500 | L18: 0 | M18: 0 | N18: =SUM(B18:M18) -> 5000
A19: Technology
A20: Technology | B20: 313 | C20: 313 | D20: 313 | E20: 313 | F20: 313 | G20: 313 | H20: 313 | I20: 313 | J20: 313 | K20: 313 | L20: 0 | M20: 0 | N20: =SUM(B20:M20) -> 3125
A21: Total Technology | B21: 313 | C21: 313 | D21: 313 | E21: 313 | F21: 313 | G21: 313 | H21: 313 | I21: 313 | J21: 313 | K21: 313 | L21: 0 | M21: 0 | N21: =SUM(B21:M21) -> 3125
A22: Occupancy / Facility
A23: Rent | B23: 1800 | C23: 1800 | D23: 1800 | E23: 1800 | F23: 1800 | G23: 1800 | H23: 1800 | I23: 1800 | J23: 1800 | K23: 1800 | L23: 0 | M23: 0 | N23: =SUM(B23:M23) -> 18000
A24: Utilities | B24: 200 | C24: 200 | D24: 200 | E24: 200 | F24: 200 | G24: 200 | H24: 200 | I24: 200 | J24: 200 | K24: 200 | L24: 0 | M24: 0 | N24: =SUM(B24:M24) -> 2000
A25: Insurance | B25: 150 | C25: 150 | D25: 150 | E25: 150 | F25: 150 | G25: 150 | H25: 150 | I25: 150 | J25: 150 | K25: 150 | L25: 0 | M25: 0 | N25: =SUM(B25:M25) -> 1500
A26: Total Occupancy / Facility | B26: 2150 | C26: 2150 | D26: 2150 | E26: 2150 | F26: 2150 | G26: 2150 | H26: 2150 | I26: 2150 | J26: 2150 | K26: 2150 | L26: 0 | M26: 0 | N26: =SUM(B26:M26) -> 21500
A27: TOTAL OPERATING EXPENSES | B27: =B18+B21+B26 -> 2963 | C27: =C18+C21+C26 -> 2963 | D27: =D18+D21+D26 -> 2963 | E27: =E18+E21+E26 -> 2963 | F27: =F18+F21+F26 -> 2963 | G27: =G18+G21+G26 -> 2963 | H27: =H18+H21+H26 -> 2963 | I27: =I18+I21+I26 -> 2963 | ... M27: =M18+M21+M26 -> 0 | N27: =SUM(B27:M27) -> 29625
A29: Capital & Debt Service | B29: 0 | C29: 0 | D29: 0 | E29: 0 | F29: 0 | G29: 0 | H29: 0 | I29: 0 | J29: 0 | K29: 0 | L29: 0 | M29: 0 | N29: =SUM(B29:M29) -> 0
A31: MONTHLY CASH FLOW
A32: Total Expenses | B32: =B13+B27+B29 -> 9415 | C32: =C13+C27+C29 -> 9415 | D32: =D13+D27+D29 -> 9415 | E32: =E13+E27+E29 -> 9415 | F32: =F13+F27+F29 -> 9415 | G32: =G13+G27+G29 -> 9415 | H32: =H13+H27+H29 -> 9415 | I32: =I13+I27+I29 -> 9415 | ... M32: =M13+M27+M29 -> 0 | N32: =SUM(B32:M32) -> 94150
A33: Net Cash Flow | B33: =B8-B32 -> 94385 | C33: =C8-C32 -> 1385 | D33: =D8-D32 -> 1385 | E33: =E8-E32 -> 1385 | F33: =F8-F32 -> 1385 | G33: =G8-G32 -> 1385 | H33: =H8-H32 -> 1385 | I33: =I8-I32 -> 1385 | ... M33: =M8-M32 -> 0 | N33: =SUM(B33:M33) -> 106850
A34: Cumulative Cash | B34: =0+B33 -> 94385 | C34: =B34+C33 -> 95770 | D34: =C34+D33 -> 97155 | E34: =D34+E33 -> 98540 | F34: =E34+F33 -> 99925 | G34: =F34+G33 -> 101310 | H34: =G34+H33 -> 102695 | I34: =H34+I33 -> 104080 | J34: =I34+J33 -> 105465 | ... M34: =L34+M33 -> 106850 | N34: =M34 -> 106850
A36: CASH FLOW METRICS
A37: Starting Cash | B37: 0
A38: Ending Cash (Month 12) | B38: =M34 -> 106850
A39: Minimum Cash Month | B39: =MIN(B34:M34) -> 94385
A41: Built by SchoolStack Budget • budget.schoolstack.ai

Sheet Financial Health
B2: Liberty Learning Co-Op — Financial Health Dashboard
B3: Generated March 27, 2026
B4: ● Green = healthy | D4: ◐ Yellow = monitor | F4: ○ Red = action needed
B6: Metric | C6: Year 1 | D6: Year 2 | E6: Year 3 | F6: Year 4 | G6: Year 5 | H6: Benchmark
B7: Enrollment | C7: 15 | D7: 22 | E7: 30 | F7: 36 | G7: 40
B8: Revenue | C8: 201000 | D8: 300735 | E8: 419199.37 | F8: 514969.1 | G8: 586124.64
B9: Personnel | C9: 64516.25 | D9: 79742.085 | E9: 82134.348 | F9: 84598.378 | G9: 87136.329
B10: Operating Expenses | C10: 35550 | D10: 41210.5 | E10: 47815.252 | F10: 53325.084 | G10: 57646.14
B11: Debt Service | C11: 0 | D11: 0 | E11: 0 | F11: 0 | G11: 0
B12: Net Income | C12: 100933.75 | D12: 179782.41 | E12: 289249.77 | F12: 377045.63 | G12: 441342.18
B13: Ending Cash | C13: 100933.75 | D13: 280716.16 | E13: 569965.94 | F13: 947011.57 | G13: 1388353.8
B14: Net Margin | C14: 0.50215796 | D14: 0.59781008 | E14: 0.69000526 | F14: 0.73217138 | G14: 0.75298348
B15: Revenue per Student | C15: 13400 | D15: 13669.773 | E15: 13973.312 | F15: 14304.697 | G15: 14653.116 | H15: ≥ $10,000
B16: Cost per Student | C16: 6671.0833 | D16: 5497.8448 | E16: 4331.6533 | F16: 3831.2073 | G16: 3619.5617
B17: Instructional / Student | C17: 400 | D17: 410 | E17: 420.25 | F17: 430.75625 | G17: 441.52516
B18: Facility / Student | C18: 1720 | D18: 1206.9545 | E18: 910.9355 | F18: 781.27344 | G18: 723.67511 | H18: ≤ $2,000 / $2k–$3.5k / > $3,500
B19: Surplus per Student | C19: 6728.9167 | D19: 8171.928 | E19: 9641.6592 | F19: 10473.49 | G19: 11033.554
B20: Payroll % | C20: 0.32097637 | D20: 0.26515731 | E20: 0.19593146 | F20: 0.16427855 | G20: 0.14866519 | H20: ≤ 55%
B21: Facility % | C21: 0.12835821 | D21: 0.08829368 | E21: 0.065191092 | F21: 0.054616566 | G21: 0.049387114 | H21: ≤ 15%
B22: Operating Margin | C22: 0.50215796 | D22: 0.59781008 | E22: 0.69000526 | F22: 0.73217138 | G22: 0.75298348 | H22: ≥ 10%
B23: Revenue Sources | C23: 3 | D23: 3 | E23: 3 | F23: 3 | G23: 3 | H23: ≥ 3 sources
B24: DSCR | C24: N/A | D24: N/A | E24: N/A | F24: N/A | G24: N/A | H24: N/A
B25: Break-even Year | C25: =IF('5-Year Model'!B43>=0,"✓ Break-even","") -> ✓ Break-even | D25: =IF(AND('5-Year Model'!C43>=0,'5-Year Model'!B43<0),"✓ Break-even","") -> 0 | E25: =IF(AND('5-Year Model'!D43>=0,'5-Year Model'!C43<0),"✓ Break-even","") -> 0 | F25: =IF(AND('5-Year Model'!E43>=0,'5-Year Model'!D43<0),"✓ Break-even","") -> 0 | G25: =IF(AND('5-Year Model'!F43>=0,'5-Year Model'!E43<0),"✓ Break-even","") -> 0 | H25: Year 1
B26: Cash Runway (Months) | C26: 12 | D26: 28 | E26: 53 | F26: 60+ | G26: 60+ | H26: ≥ 24 months
B27: Days Cash on Hand | C27: 368 | D27: 847 | E27: 1601 | F27: 2506 | G27: 3500 | H27: ≥ 90 days
B29: FINANCIAL HEALTH SIGNALS | C29: Status | D29: Assessment | F29: Watch Item
B30: Viability | C30: ● Healthy | D30: The model reaches profit early and sustains strong margins through Year 5. | F30: Monitor enrollment actuals vs. projections in Year 1.
B31: Liquidity | C31: ● Healthy | D31: Cash stays positive throughout the projection and reserves exceed 3 months of expenses. | F31: Maintain reserves as a buffer against seasonal revenue dips.
B32: Staffing Burden | C32: ● Healthy | D32: Staffing at 15% of revenue leaves room for facilities, programs, and reserves. | F32: As you add staff, ensure staffing stays below 60% of revenue.
B33: Facility Burden | C33: ● Healthy | D33: Facility costs at 5% of revenue are well-managed and leave budget for programs. | F33: Watch for rent escalation clauses that could push this higher over time.
B34: Revenue Concentration | C34: ● Healthy | D34: Revenue is anchored to enrollment-driven income — the strongest foundation for a school model. A focused revenue stream is a strength when backed by dependable demand. | F34: Continue to pressure-test enrollment assumptions: recruitment pipeline, waitlist depth, retention rates, and collection reliability.
B35: Reserve Strength | C35: ● Healthy | D35: 115.1 months of reserves by Year 5 — a strong buffer for unexpected costs. | F35: Continue growing reserves toward 6 months for best-in-class financial health.
B37: Summary | C37: 6 Healthy | 0 Watch | 0 Needs Attention
B39: Built by SchoolStack Budget • budget.schoolstack.ai
