Workbook

Sheet Instructions
B2: How to Use This Workbook
B3: Bright Horizons Microschool
B4: Generated May 9, 2026 · llc_single
B6: Cell Color Legend
B7: Blue cells are editable inputs — change these to update your model.
B8: White cells contain formulas — do not edit (they recalculate automatically).
B9: Green cells are key outputs and summary metrics.
B11: Navigation
B12: The Assumptions tab is the central control panel — all other tabs reference it.
B14: Structure
B15: Assumptions & Drivers: Model inputs and calculations
B16: 5-Year P&L & Cash Flow: Financial projections
... B37: user-provided assumptions and should be independently verified.

Sheet Cover
B3: SCHOOLSTACK BUDGET
B4: Lender-Ready Pro Forma
B6: Bright Horizons Microschool
B8: TABLE OF CONTENTS
B9: Assumptions
B10: Drivers
B11: 5-Year P&L
B12: Cash Flow & DSCR
B13: Staffing
B14: Loan Snapshot
B15: Summary
B18: Generated May 9, 2026
B19: Generated by SchoolStack Budget • budget.schoolstack.ai

Sheet Assumptions
B1: SchoolStack Budget - Lender Pro Forma Assumptions
C2: Editable assumption — change this value | E2: Calculated — driven by formula
B3: SCHOOL PROFILE
C5: School Name | D5: Bright Horizons Microschool
C6: State | D6: AZ
C7: School Type | D7: Microschool
C8: First Operating Year | D8: 2026
B10: ENROLLMENT FORECAST
C12: Year 1 Enrollment | D12: 12
C13: Year 2 Enrollment | D13: 18
C14: Year 3 Enrollment | D14: 22
C15: Year 4 Enrollment | D15: 25
C16: Year 5 Enrollment | D16: 25
B18: REVENUE ASSUMPTIONS
C20: Tuition per Student (Year 1) | D20: 0
C21: Tuition Annual Growth % | D21: 0.03
C22: ESA per Student (Year 1) | D22: 7000
C23: ESA Annual Growth % | D23: 0.03
C24: Other Per-Student Revenue (Year 1) | D24: 0
C25: Other Revenue Growth % | D25: 0.02
C26: Collection Rate % | D26: 1
C27: Grants & Contributions (Year 1) | D27: 5000
C28: Grants Growth % | D28: 0
B30: STAFFING ASSUMPTIONS
C32: Students per Teacher | D32: 8
C33: Avg Teacher Salary (Year 1) | D33: 36500
C34: Teacher Salary Growth % | D34: 0.03
C35: Admin FTE - Year 1 | D35: 1
C36: Admin FTE - Year 2 | D36: 1
C37: Admin FTE - Year 3 | D37: 1
C38: Admin FTE - Year 4 | D38: 1
C39: Admin FTE - Year 5 | D39: 1
C40: Avg Admin Salary (Year 1) | D40: 55000
C41: Admin Salary Growth % | D41: 0.03
C42: Benefits Burden % | D42: 0.2
B44: OPERATING EXPENSE ASSUMPTIONS
C46: Annual Rent (Year 1) | D46: 30000
C47: Rent Growth % | D47: 0.029333333
C48: Other Facility Cost (Year 1) | D48: 6000
C49: Other Facility Growth % | D49: 0.029333333
...

Sheet Drivers
B1: Revenue & Expense Drivers
C3: Year 1 | D3: Year 2 | E3: Year 3 | F3: Year 4 | G3: Year 5
B4: Enrollment | C4: =Assumptions!D12 -> 12 | D4: =Assumptions!D13 -> 18 | E4: =Assumptions!D14 -> 22 | F4: =Assumptions!D15 -> 25 | G4: =Assumptions!D16 -> 25
B5: Tuition Revenue (Net) | C5: =Assumptions!D12*Assumptions!D20 -> 0 | D5: =Assumptions!D13*Assumptions!D20*(1+Assumptions!D21)^1 -> 0 | E5: =Assumptions!D14*Assumptions!D20*(1+Assumptions!D21)^2 -> 0 | F5: =Assumptions!D15*Assumptions!D20*(1+Assumptions!D21)^3 -> 0 | G5: =Assumptions!D16*Assumptions!D20*(1+Assumptions!D21)^4 -> 0
B6: × Collection Rate Applied | C6: =C5*Assumptions!D26 -> 0 | D6: =D5*Assumptions!D26 -> 0 | E6: =E5*Assumptions!D26 -> 0 | F6: =F5*Assumptions!D26 -> 0 | G6: =G5*Assumptions!D26 -> 0
B7: ESA / School Choice Revenue | C7: =Assumptions!D12*Assumptions!D22 -> 84000 | D7: =Assumptions!D13*Assumptions!D22*(1+Assumptions!D23)^1 -> 129780 | E7: =Assumptions!D14*Assumptions!D22*(1+Assumptions!D23)^2 -> 163378.6 | F7: =Assumptions!D15*Assumptions!D22*(1+Assumptions!D23)^3 -> 191227.23 | G7: =Assumptions!D16*Assumptions!D22*(1+Assumptions!D23)^4 -> 196964.04
B8: Other Earned Revenue | C8: =Assumptions!D12*Assumptions!D24 -> 0 | D8: =Assumptions!D13*Assumptions!D24*(1+Assumptions!D25)^1 -> 0 | E8: =Assumptions!D14*Assumptions!D24*(1+Assumptions!D25)^2 -> 0 | F8: =Assumptions!D15*Assumptions!D24*(1+Assumptions!D25)^3 -> 0 | G8: =Assumptions!D16*Assumptions!D24*(1+Assumptions!D25)^4 -> 0
B9: Grants & Contributions | C9: =Assumptions!D27 -> 5000 | D9: =Assumptions!D27*(1+Assumptions!D28)^1 -> 5000 | E9: =Assumptions!D27*(1+Assumptions!D28)^2 -> 5000 | F9: =Assumptions!D27*(1+Assumptions!D28)^3 -> 5000 | G9: =Assumptions!D27*(1+Assumptions!D28)^4 -> 5000
B10: Total Revenue | C10: =C6+C7+C8+C9 -> 89000 | D10: =D6+D7+D8+D9 -> 134780 | E10: =E6+E7+E8+E9 -> 168378.6 | F10: =F6+F7+F8+F9 -> 196227.23 | G10: =G6+G7+G8+G9 -> 201964.04
B12: Teacher FTE (Enrollment ÷ Ratio) | C12: =CEILING(Assumptions!D12/Assumptions!D32,1) -> 2 | D12: =CEILING(Assumptions!D13/Assumptions!D32,1) -> 3 | E12: =CEILING(Assumptions!D14/Assumptions!D32,1) -> 3 | F12: =CEILING(Assumptions!D15/Assumptions!D32,1) -> 4 | G12: =CEILING(Assumptions!D16/Assumptions!D32,1) -> 4
B13: Teacher Salaries | C13: =C12*Assumptions!D33 -> 73000 | D13: =D12*Assumptions!D33*(1+Assumptions!D34)^1 -> 112785 | E13: =E12*Assumptions!D33*(1+Assumptions!D34)^2 -> 116168.55 | F13: =F12*Assumptions!D33*(1+Assumptions!D34)^3 -> 159538.14 | G13: =G12*Assumptions!D33*(1+Assumptions!D34)^4 -> 164324.29
B14: Admin Salaries | C14: =Assumptions!D35*Assumptions!D40 -> 55000 | D14: =Assumptions!D36*Assumptions!D40*(1+Assumptions!D41)^1 -> 56650 | E14: =Assumptions!D37*Assumptions!D40*(1+Assumptions!D41)^2 -> 58349.5 | F14: =Assumptions!D38*Assumptions!D40*(1+Assumptions!D41)^3 -> 60099.985 | G14: =Assumptions!D39*Assumptions!D40*(1+Assumptions!D41)^4 -> 61902.985
B15: Benefits & Payroll Taxes | C15: =(C13+C14)*Assumptions!D42 -> 25600 | D15: =(D13+D14)*Assumptions!D42 -> 33887 | E15: =(E13+E14)*Assumptions!D42 -> 34903.61 | F15: =(F13+F14)*Assumptions!D42 -> 43927.625 | G15: =(G13+G14)*Assumptions!D42 -> 45245.454
B16: Total Staffing Cost | C16: =C13+C14+C15 -> 153600 | D16: =D13+D14+D15 -> 203322 | E16: =E13+E14+E15 -> 209421.66 | F16: =F13+F14+F15 -> 263565.75 | G16: =G13+G14+G15 -> 271472.72
B18: Rent / Lease | C18: =Assumptions!D46 -> 30000 | D18: =Assumptions!D46*(1+Assumptions!D47)^1 -> 30880 | E18: =Assumptions!D46*(1+Assumptions!D47)^2 -> 31785.813 | F18: =Assumptions!D46*(1+Assumptions!D47)^3 -> 32718.197 | G18: =Assumptions!D46*(1+Assumptions!D47)^4 -> 33677.931
B19: Other Facility Costs | C19: =Assumptions!D48 -> 6000 | D19: =Assumptions!D48*(1+Assumptions!D49)^1 -> 6176 | E19: =Assumptions!D48*(1+Assumptions!D49)^2 -> 6357.1627 | F19: =Assumptions!D48*(1+Assumptions!D49)^3 -> 6543.6394 | G19: =Assumptions!D48*(1+Assumptions!D49)^4 -> 6735.5862
B20: Program / Curriculum | C20: =Assumptions!D12*Assumptions!D50 -> 6000 | D20: =Assumptions!D13*Assumptions!D50*(1+Assumptions!D51)^1 -> 13905 | E20: =Assumptions!D14*Assumptions!D50*(1+Assumptions!D51)^2 -> 26257.275 | F20: =Assumptions!D15*Assumptions!D50*(1+Assumptions!D51)^3 -> 46099.42 | G20: =Assumptions!D16*Assumptions!D50*(1+Assumptions!D51)^4 -> 71223.604
B21: G&A / Technology | C21: =Assumptions!D52 -> 6600 | D21: =Assumptions!D52*(1+Assumptions!D53)^1 -> 8637 | E21: =Assumptions!D52*(1+Assumptions!D53)^2 -> 11302.692 | F21: =Assumptions!D52*(1+Assumptions!D53)^3 -> 14791.114 | G21: =Assumptions!D52*(1+Assumptions!D53)^4 -> 19356.19
B22: Total Operating Expenses | C22: =C18+C19+C20+C21 -> 48600 | D22: =D18+D19+D20+D21 -> 59598 | E22: =E18+E19+E20+E21 -> 75702.943 | F22: =F18+F19+F20+F21 -> 100152.37 | G22: =G18+G19+G20+G21 -> 130993.31

Sheet 5-Year P&L
B1: 5-Year Pro Forma Profit & Loss
C3: Year 1 | D3: Year 2 | E3: Year 3 | F3: Year 4 | G3: Year 5
B5: Enrollment | C5: =Drivers!C4 -> 12 | D5: =Drivers!D4 -> 18 | E5: =Drivers!E4 -> 22 | F5: =Drivers!F4 -> 25 | G5: =Drivers!G4 -> 25
B6: Tuition Revenue (Net) | C6: =Drivers!C6 -> 0 | D6: =Drivers!D6 -> 0 | E6: =Drivers!E6 -> 0 | F6: =Drivers!F6 -> 0 | G6: =Drivers!G6 -> 0
B7: ESA / School Choice | C7: =Drivers!C7 -> 84000 | D7: =Drivers!D7 -> 129780 | E7: =Drivers!E7 -> 163378.6 | F7: =Drivers!F7 -> 191227.23 | G7: =Drivers!G7 -> 196964.04
B8: Other Revenue | C8: =Drivers!C8 -> 0 | D8: =Drivers!D8 -> 0 | E8: =Drivers!E8 -> 0 | F8: =Drivers!F8 -> 0 | G8: =Drivers!G8 -> 0
B9: Grants & Contributions | C9: =Drivers!C9 -> 5000 | D9: =Drivers!D9 -> 5000 | E9: =Drivers!E9 -> 5000 | F9: =Drivers!F9 -> 5000 | G9: =Drivers!G9 -> 5000
B10: Total Revenue | C10: =Drivers!C10 -> 89000 | D10: =Drivers!D10 -> 134780 | E10: =Drivers!E10 -> 168378.6 | F10: =Drivers!F10 -> 196227.23 | G10: =Drivers!G10 -> 201964.04
B12: Total Staffing | C12: =Drivers!C16 -> 153600 | D12: =Drivers!D16 -> 203322 | E12: =Drivers!E16 -> 209421.66 | F12: =Drivers!F16 -> 263565.75 | G12: =Drivers!G16 -> 271472.72
B13: Total Operating Expenses | C13: =Drivers!C22 -> 48600 | D13: =Drivers!D22 -> 59598 | E13: =Drivers!E22 -> 75702.943 | F13: =Drivers!F22 -> 100152.37 | G13: =Drivers!G22 -> 130993.31
B15: Total Expenses | C15: =C12+C13 -> 202200 | D15: =D12+D13 -> 262920 | E15: =E12+E13 -> 285124.6 | F15: =F12+F13 -> 363718.12 | G15: =G12+G13 -> 402466.04
B16: Net Operating Income (NOI) | C16: =C10-C15 -> -113200 | D16: =D10-D15 -> -128140 | E16: =E10-E15 -> -116746 | F16: =F10-F15 -> -167490.9 | G16: =G10-G15 -> -200501.99
B17: Operating Margin | C17: =IF(C10>0,C16/C10,0) -> -1.2719101 | D17: =IF(D10>0,D16/D10,0) -> -0.95073453 | E17: =IF(E10>0,E16/E10,0) -> -0.69335416 | F17: =IF(F10>0,F16/F10,0) -> -0.85355586 | G17: =IF(G10>0,G16/G10,0) -> -0.99276085
B19: Interest Expense | C19: 1656 | D19: 1329 | E19: 981 | F19: 613 | G19: 221
B20: Principal & Capital Outlays | C20: ='Cash Flow & DSCR'!C9-C19 -> 5304.095 | D20: ='Cash Flow & DSCR'!D9-D19 -> 5631.24 | E20: ='Cash Flow & DSCR'!E9-E19 -> 5978.5626 | F20: ='Cash Flow & DSCR'!F9-F19 -> 6347.3072 | G20: ='Cash Flow & DSCR'!G9-G19 -> 6738.7952
B22: Net Income | C22: =C16-C19-C20 -> -120159.81 | D22: =D16-D19-D20 -> -135099.81 | E22: =E16-E19-E20 -> -123705.81 | F22: =F16-F19-F20 -> -174450.71 | G22: =G16-G19-G20 -> -207461.8
B23: Net Margin | C23: =IF(C10>0,C22/C10,0) -> -1.3501102 | D23: =IF(D10>0,D22/D10,0) -> -1.0023728 | E23: =IF(E10>0,E22/E10,0) -> -0.73468845 | F23: =IF(F10>0,F22/F10,0) -> -0.88902397 | G23: =IF(G10>0,G22/G10,0) -> -1.0272215
B25: Cumulative Net Income | C25: =C22 -> -120159.81 | D25: =C25+D22 -> -255259.62 | E25: =D25+E22 -> -378965.43 | F25: =E25+F22 -> -553416.14 | G25: =F25+G22 -> -760877.94
B26: Break-even

Sheet Cash Flow & DSCR
B1: Cash Flow & Debt Service Coverage
C3: Year 1 | D3: Year 2 | E3: Year 3 | F3: Year 4 | G3: Year 5
B4: Beginning Cash | C4: =Assumptions!D57 -> 0 | D4: =C16 -> -120159.81 | E4: =D16 -> -255259.62 | F4: =E16 -> -378965.43 | G4: =F16 -> -553416.14
B5: Net Operating Income | C5: ='5-Year P&L'!C16 -> -113200 | D5: ='5-Year P&L'!D16 -> -128140 | E5: ='5-Year P&L'!E16 -> -116746 | F5: ='5-Year P&L'!F16 -> -167490.9 | G5: ='5-Year P&L'!G16 -> -200501.99
B7: Existing Debt Service | C7: =Assumptions!D58 -> 0 | D7: =Assumptions!D58 -> 0 | E7: =Assumptions!D58 -> 0 | F7: =Assumptions!D58 -> 0 | G7: =Assumptions!D58 -> 0
B8: Proposed Loan Debt Service | C8: =IF(Assumptions!D59>0,PMT(Assumptions!D60/12,Assumptions!D61*12,-Assumptions!D59)*12,0) -> 6959.8086 | D8: =IF(Assumptions!D59>0,PMT(Assumptions!D60/12,Assumptions!D61*12,-Assumptions!D59)*12,0) -> 6959.8086 | E8: =IF(Assumptions!D59>0,PMT(Assumptions!D60/12,Assumptions!D61*12,-Assumptions!D59)*12,0) -> 6959.8086 | F8: =IF(Assumptions!D59>0,PMT(Assumptions!D60/12,Assumptions!D61*12,-Assumptions!D59)*12,0) -> 6959.8086 | G8: =IF(Assumptions!D59>0,PMT(Assumptions!D60/12,Assumptions!D61*12,-Assumptions!D59)*12,0) -> 6959.8086
B9: Total Debt Service | C9: =C7+C8 -> 6959.8086 | D9: =D7+D8 -> 6959.8086 | E9: =E7+E8 -> 6959.8086 | F9: =F7+F8 -> 6959.8086 | G9: =G7+G8 -> 6959.8086
B11: DSCR (NOI ÷ Total Debt Service) | C11: =IF(C9>0,C5/C9,IF(C5>0,99.9,0)) -> -16.264815 | D11: =IF(D9>0,D5/D9,IF(D5>0,99.9,0)) -> -18.411426 | E11: =IF(E9>0,E5/E9,IF(E5>0,99.9,0)) -> -16.774312 | F11: =IF(F9>0,F5/F9,IF(F5>0,99.9,0)) -> -24.065446 | G11: =IF(G9>0,G5/G9,IF(G5>0,99.9,0)) -> -28.80855
B13: Net Income After Debt | C13: =C5-C9 -> -120159.81 | D13: =D5-D9 -> -135099.81 | E13: =E5-E9 -> -123705.81 | F13: =F5-F9 -> -174450.71 | G13: =G5-G9 -> -207461.8
B14: Net Cash Flow | C14: =C5-C9 -> -120159.81 | D14: =D5-D9 -> -135099.81 | E14: =E5-E9 -> -123705.81 | F14: =F5-F9 -> -174450.71 | G14: =G5-G9 -> -207461.8
B16: Ending Cash | C16: =C4+C14 -> -120159.81 | D16: =D4+D14 -> -255259.62 | E16: =E4+E14 -> -378965.43 | F16: =F4+F14 -> -553416.14 | G16: =G4+G14 -> -760877.94

Sheet AR & Restricted Recon
B1: AR Schedule & Restricted-vs-Unrestricted Cash Recon
B2: AR = year's collected tuition × 30-day weighted delay ÷ 365. Bad debt = contracted − collected.
C4: Year 1 | D4: Year 2 | E4: Year 3 | F4: Year 4 | G4: Year 5
B5: Accounts Receivable Schedule
B6: Contracted Tuition (gross) | C6: 0 | D6: 0 | E6: 0 | F6: 0 | G6: 0
B7: Collected Tuition (cash-basis) | C7: 0 | D7: 0 | E7: 0 | F7: 0 | G7: 0
B8: Bad Debt (contracted − collected) | C8: =C6-C7 -> 0 | D8: =D6-D7 -> 0 | E8: =E6-E7 -> 0 | F8: =F6-F7 -> 0 | G8: =G6-G7 -> 0
B9: Year-end AR Balance (30-day delay) | C9: =C7*30/365 -> 0 | D9: =D7*30/365 -> 0 | E9: =E7*30/365 -> 0 | F9: =F7*30/365 -> 0 | G9: =G7*30/365 -> 0
B11: Restricted vs Unrestricted Cash
B12: Total Cash Position (accrual) | C12: -120159.81 | D12: -255259.62 | E12: -378965.43 | F12: -553416.14 | G12: -760877.94
B13: Restricted Cash (capital/program-restricted) | C13: 0 | D13: 0 | E13: 0 | F13: 0 | G13: 0
B14: Unrestricted Cash (DSCR/runway basis) | C14: =C12-C13 -> -120159.81 | D14: =D12-D13 -> -255259.62 | E14: =E12-E13 -> -378965.43 | F14: =F12-F13 -> -553416.14 | G14: =G12-G13 -> -760877.94
B16: Note: DSCR and cash-runway covenants in this packet are computed off Unrestricted Cash (row 14). Restricted gifts cannot legally service debt and are excluded from coverage tests.

Sheet Staffing
B1: Staffing Detail
C3: Year 1 | D3: Year 2 | E3: Year 3 | F3: Year 4 | G3: Year 5
B4: Teacher FTE | C4: =Drivers!C12 -> 2 | D4: =Drivers!D12 -> 3 | E4: =Drivers!E12 -> 3 | F4: =Drivers!F12 -> 4 | G4: =Drivers!G12 -> 4
B5: Admin FTE | C5: =Assumptions!D35 -> 1 | D5: =Assumptions!D36 -> 1 | E5: =Assumptions!D37 -> 1 | F5: =Assumptions!D38 -> 1 | G5: =Assumptions!D39 -> 1
B6: Total FTE | C6: =C4+C5 -> 3 | D6: =D4+D5 -> 4 | E6: =E4+E5 -> 4 | F6: =F4+F5 -> 5 | G6: =G4+G5 -> 5

Sheet Loan Snapshot
B1: Proposed Loan Summary
B3: Loan Amount | C3: =Assumptions!D59 -> 30000
B4: Interest Rate | C4: =Assumptions!D60 -> 0.06
B5: Term (Years) | C5: =Assumptions!D61 -> 5
B6: Annual Debt Service | C6: =IF(Assumptions!D59>0,PMT(Assumptions!D60/12,Assumptions!D61*12,-Assumptions!D59)*12,0) -> 6959.8086
B8: Year 1 DSCR | C8: ='Cash Flow & DSCR'!C11 -> -16.264815

Sheet Summary
B1: Model Summary
B3: School Name | C3: =Assumptions!D5 -> Bright Horizons Microschool
B4: School Type | C4: =Assumptions!D7 -> Microschool
B5: State | C5: =Assumptions!D6 -> AZ
B6: Opening Year | C6: =Assumptions!D8 -> 2026
B8: Year 5 Enrollment | C8: =Assumptions!D16 -> 25
B9: Year 5 Revenue | C9: =Drivers!G10 -> 201964.04
B10: Year 5 NOI | C10: ='5-Year P&L'!G16 -> -200501.99
B12: KEY RATIOS
B13: Net Margin (Year 5) | C13: =IF(Drivers!G10>0,'5-Year P&L'!G21/Drivers!G10,0) -> -1.0272215
B14: Personnel % of Revenue (Year 5) | C14: =IF(Drivers!G10>0,Drivers!G16/Drivers!G10,0) -> 1.3441637
B15: Revenue per Student (Year 5) | C15: =IF(Assumptions!D16>0,Drivers!G10/Assumptions!D16,0) -> 8079
B16: Expense per Student (Year 5) | C16: =IF(Assumptions!D16>0,('5-Year P&L'!G12+'5-Year P&L'!G13)/Assumptions!D16,0) -> 16099
B17: DSCR (Year 1) | C17: ='Cash Flow & DSCR'!C11 -> -16.264815
B18: DSCR (Year 5) | C18: ='Cash Flow & DSCR'!G11 -> -28.80855
B19: Days Cash on Hand (Year 1) | C19: 0
B21: Generated by SchoolStack Budget (budget.schoolstack.ai)

Sheet Stress Tests
A1: Standard Lender Stress Tests
A2: Five fixed downside scenarios re-run on the canonical engine. Identical figures appear on the founder dashboard, consultant view, and lender packet PDF.
A4: Scenario | B4: Metric | C4: Year 1 | D4: Year 2 | E4: Year 3 | F4: Year 4 | G4: Year 5 | H4: Δ vs Base (Y1)
A5: Base Case
A6: Canonical engine output. All scenarios below are deltas vs this row.
B7: Net Income | C7: 18272.691 | D7: 131664.56 | E7: 209799.66 | F7: 273590.96 | G7: 282715.61 | H7: —
B8: DSCR | C8: 3.63 | D8: 19.92 | E8: 31.14 | F8: 40.31 | G8: 41.62 | H8: —
B9: Ending Cash | C9: 33272.691 | D9: 164937.25 | E9: 374736.91 | F9: 648327.87 | G9: 931043.48 | H9: —
B10: Break-Even Students | C10: 11 | D10: 11 | E10: 11 | F10: 11 | G10: 11 | H10: —
B11: Cash Runway (mo) | C11: 60 | H11: —
B12: Break-Even Year | C12: Year 1 | H12: —
A14: Enrollment -10%
A15: All five enrollment years scaled down by 10% — the standard lender enrollment-miss sensitivity.
B16: Net Income | C16: 3897.6914 | D16: 96136.561 | E16: 173212.86 | F16: 235912.59 | G16: 243914.91 | H16: -14375
B17: DSCR | C17: 1.56 | D17: 14.81 | E17: 25.89 | F17: 34.9 | G17: 36.05 | H17: -2.07
B18: Ending Cash | C18: 18897.691 | D18: 115034.25 | E18: 288247.11 | F18: 524159.7 | G18: 768074.61 | H18: -14375
B19: Break-Even Students | C19: 11 | D19: 11 | E19: 11 | F19: 11 | G19: 11 | H19: 0
B20: Cash Runway (mo) | C20: 60 | H20: 0
B21: Break-Even Year | C21: Year 1 | H21: 0y
A23: Enrollment -20%
A24: All five enrollment years scaled down by 20% — the stretch downside lenders use to confirm the school can survive a soft-launch.
B25: Net Income | C25: -10477.309 | D25: 60608.561 | E25: 136626.06 | F25: 179395.03 | G25: 185713.86 | H25: -28750
B26: DSCR | C26: -0.51 | D26: 9.71 | E26: 20.63 | F26: 26.78 | G26: 27.68 | H26: -4.14
B27: Ending Cash | C27: 4522.6914 | D27: 65131.253 | E27: 201757.31 | F27: 381152.34 | G27: 566866.2 | H27: -28750
B28: Break-Even Students | C28: 11 | D28: 11 | E28: 11 | F28: 11 | G28: 11 | H28: 0
B29: Cash Runway (mo) | C29: 6 | H29: -54
B30: Break-Even Year | C30: Year 2 | H30: +1y
A32: ESA / Public Funding Delayed 3 Months
A33: Year-1 ESA, school-choice, and public-funding receipts reduced by 25% (≈ 3 months delayed) to simulate a slow first disbursement.
B34: Net Income | C34: 772.69145 | D34: 131664.56 | E34: 209799.66 | F34: 273590.96 | G34: 282715.61 | H34: -17500
B35: DSCR | C35: 1.11 | D35: 19.92 | E35: 31.14 | F35: 40.31 | G35: 41.62 | H35: -2.52
B36: Ending Cash | C36: 15772.691 | D36: 147437.25 | E36: 357236.91 | F36: 630827.87 | G36: 913543.48 | H36: -17500
B37: Break-Even Students | C37: 12 | D37: 11 | E37: 11 | F37: 11 | G37: 11 | H37: 1
B38: Cash Runway (mo) | C38: 9 | H38: -51
B39: Break-Even Year | C39: Year 1 | H39: 0y
A41: Rent Shock +25%
A42: Occupancy & facility expense rows escalated by 25% — covers a lease renewal, market-rate reset, or unbudgeted CAM/utilities surprise.
B43: Net Income | C43: 10772.691 | D43: 122402.06 | E43: 200266.97 | F43: 263780.17 | G43: 272618.58 | H43: -7500
B44: DSCR | C44: 2.55 | D44: 18.59 | E44: 29.77 | F44: 38.9 | G44: 40.17 | H44: -1.08
B45: Ending Cash | C45: 25772.691 | D45: 148174.75 | E45: 348441.72 | F45: 612221.9 | G45: 884840.47 | H45: -7500
...

Sheet Decision History
B1: Decision History
B2: Track record of 5 tracked decisions (2 pursued, 1 on hold, 2 declined). Each entry shows the modeled change, the outcome the team logged, and any retrospective notes captured after the fact.
B4: Decision | C4: Type | D4: Outcome | E4: Applied to base model? | F4: Outcome logged | G4: Modeled change | H4: What happened (retrospective)
B5: Add Middle School program | C5: Add a program | D5: Pursued | E5: [APPLIED] Folded into the base model on Apr 12, 2025 | F5: Apr 10, 2025 | G5: • Program: Middle School (6-8) • Tuition $14,000/yr • Adds 72 cumulative students (5 yrs) • +2 FTE | H5: Launched in fall 2025; enrollment hit plan within 1 student.
B6: Increase retention focus | C6: Change enrollment | D6: Pursued | E6: [PENDING] Pending apply to base model | F6: Mar 5, 2025 | G6: • Enrollment +14 cumulative • Retention 92% | H6: Retention initiatives approved; planner will reflect after Q2 board review.
B7: Evaluate downtown campus | C7: Evaluate a site | D7: On hold | E7: — | F7: Mar 25, 2025 | G7: • Rent $8,500/mo • Rent escalation 4% • Sqft +1500 • Fit-out $75,000 (Y1) | H7: Landlord negotiations paused while waiting on city zoning ruling.
B8: Reduce K cohort | C8: Change enrollment | D8: Declined | E8: — | F8: Mar 15, 2025 | G8: • Enrollment -8 cumulative • Tuition -$500/student | H8: Board declined; enrollment goals retained as originally modeled.
B9: Move to larger building | C9: Evaluate a site | D9: Declined | E9: — | F9: Feb 10, 2025 | G9: • Rent $12,000/mo • Sqft +4000 | H9: Costs out of reach; revisited next year after capital campaign.
B11: Generated by SchoolStack Budget (budget.schoolstack.ai)

Sheet Financial Health
B2: Bright Horizons Microschool — Financial Health Dashboard
B3: Generated May 9, 2026
B4: ● Green = healthy | D4: ◐ Yellow = monitor | F4: ○ Red = action needed
B6: Metric | C6: Year 1 | D6: Year 2 | E6: Year 3 | F6: Year 4 | G6: Year 5 | H6: Benchmark
B7: Enrollment | C7: 12 | D7: 18 | E7: 22 | F7: 25 | G7: 25
B8: Revenue | C8: 89000 | D8: 134780 | E8: 168378.6 | F8: 196227.23 | G8: 201964.04
B9: Personnel | C9: 153600 | D9: 203322 | E9: 209421.66 | F9: 263565.75 | G9: 271472.72
B10: Operating Expenses | C10: 48600 | D10: 59598 | E10: 75702.943 | F10: 100152.37 | G10: 130993.31
B11: Debt Service | C11: 6959.8086 | D11: 6959.8086 | E11: 6959.8086 | F11: 6959.8086 | G11: 6959.8086
B12: Net Income | C12: -120159.81 | D12: -135099.81 | E12: -123705.81 | F12: -174450.71 | G12: -207461.8
B13: Ending Cash | C13: -120159.81 | D13: -255259.62 | E13: -378965.43 | F13: -553416.14 | G13: -760877.94
B14: Net Margin | C14: -1.3501102 | D14: -1.0023728 | E14: -0.73468845 | F14: -0.88902397 | G14: -1.0272215
B15: Revenue per Student | C15: 7416.6667 | D15: 7487.7778 | E15: 7653.5727 | F15: 7849.089 | G15: 8078.5617 | H15: ≥ $10,000
B16: Cost per Student | C16: 17429.984 | D16: 14993.323 | E16: 13276.564 | F16: 14827.117 | G16: 16377.034
B17: Instructional / Student | C17: 500 | D17: 772.5 | E17: 1193.5125 | F17: 1843.9768 | G17: 2848.9442
B18: Facility / Student | C18: 3000 | D18: 2058.6667 | E18: 1733.7716 | F18: 1570.4735 | G18: 1616.5407 | H18: ≤ $2,000 / $2k–$3.5k / > $3,500
B19: Surplus per Student | C19: -10013.317 | D19: -7505.5449 | E19: -5622.9914 | F19: -6978.0283 | G19: -8298.4721
B20: Payroll % | C20: 1.7258427 | D20: 1.5085473 | E20: 1.2437546 | F20: 1.3431661 | G20: 1.3441637 | H20: ≤ 55%
B21: Facility % | C21: 0.40449438 | D21: 0.27493693 | E21: 0.22653102 | F21: 0.20008353 | G21: 0.20010254 | H21: ≤ 15%
B22: Operating Margin | C22: -1.2719101 | D22: -0.95073453 | E22: -0.69335416 | F22: -0.85355586 | G22: -0.99276085 | H22: ≥ 10%
B23: Revenue Sources | C23: 2 | D23: 2 | E23: 2 | F23: 2 | G23: 2 | H23: ≥ 3 sources
B24: DSCR | C24: -16.264815 | D24: -18.411426 | E24: -16.774312 | F24: -24.065446 | G24: -28.80855 | H24: ≥ 1.25x
B25: Break-even Year | C25: =IF('5-Year P&L'!C24>=0,"✓ Break-even","") -> 0 | D25: =IF(AND('5-Year P&L'!D24>=0,'5-Year P&L'!C24<0),"✓ Break-even","") -> 0 | E25: =IF(AND('5-Year P&L'!E24>=0,'5-Year P&L'!D24<0),"✓ Break-even","") -> 0 | F25: =IF(AND('5-Year P&L'!F24>=0,'5-Year P&L'!E24<0),"✓ Break-even","") -> 0 | G25: =IF(AND('5-Year P&L'!G24>=0,'5-Year P&L'!F24<0),"✓ Break-even","") -> 0 | H25: Year 1
B26: Cash Runway (Months) | C26: -7 | D26: -11 | E26: -16 | F26: -18 | G26: -22 | H26: ≥ 24 months
B27: Days Cash on Hand | C27: 0 | D27: 0 | E27: 0 | F27: 0 | G27: 0 | H27: ≥ 90 days
B29: FINANCIAL HEALTH SIGNALS | C29: Status | D29: Assessment | F29: Watch Item
B30: Viability | C30: ○ Needs attention | D30: The model does not reach break-even within 5 years. This needs to be addressed before approaching lenders. | F30: Revisit revenue assumptions and cost structure to build a clear path to break-even.
B31: Liquidity | C31: ○ Needs attention | D31: Cash goes negative in month 1. The school will need outside funding to continue operating. | F31: Secure a line of credit or bridge funding before operations begin.
B32: Staffing Burden | C32: ○ Needs attention | D32: Staffing at 134% of revenue is above the sustainable range. There's too little left for everything else. | F32: Review staffing plan for phased hiring, shared roles, or adjusted ratios.
B33: Facility Burden | C33: ◐ Watch closely | D33: Facility costs at 20% of revenue are moderate but could become a constraint as other costs grow. | F33: Ensure enrollment growth keeps pace with any rent increases.
B34: Debt Affordability | C34: ○ Needs attention | D34: DSCR of -28.81x is below the 1.15x amber threshold. Any shortfall in revenue makes debt unaffordable. | F34: Reduce loan amounts, extend terms, or increase revenue before committing to this debt.
B35: Revenue Concentration | C35: ● Healthy | D35: Revenue is anchored to enrollment-driven income — the strongest foundation for a school model. A focused revenue stream is a strength when backed by dependable demand. | F35: Continue to pressure-test enrollment assumptions: recruitment pipeline, waitlist depth, retention rates, and collection reliability.
B36: Reserve Strength | C36: ○ Needs attention | D36: Less than 1 month of reserves by Year 5. The school has no financial cushion. | F36: Prioritize building reserves — even a small surplus each year compounds into meaningful protection.
B38: Summary | C38: 1 Healthy | 1 Watch | 5 Needs Attention
B40: Built by SchoolStack Budget • budget.schoolstack.ai
