Workbook

Sheet Instructions
B2: How to Use This Workbook
B3: Heritage Academy
B4: Generated April 29, 2026 · nonprofit_501c3
B6: Cell Color Legend
B7: Blue cells are editable inputs — change these to update your model.
B8: White cells contain formulas — do not edit (they recalculate automatically).
B9: Green cells are key outputs and summary metrics.
B11: Navigation
B12: The Assumptions tab is the central control panel — all other tabs reference it.
B14: Structure
B15: Assumptions & Drivers: Model inputs and calculations
B16: 5-Year P&L & Cash Flow: Financial projections
... B37: user-provided assumptions and should be independently verified.

Sheet Cover
B3: SCHOOLSTACK BUDGET
B4: Lender-Ready Pro Forma
B6: Heritage Academy
B8: TABLE OF CONTENTS
B9: Assumptions
B10: Drivers
B11: 5-Year P&L
B12: Cash Flow & DSCR
B13: Staffing
B14: Loan Snapshot
B15: Summary
B18: Generated April 29, 2026
B19: Generated by SchoolStack Budget • budget.schoolstack.ai

Sheet Assumptions
B1: SchoolStack Budget - Lender Pro Forma Assumptions
C2: Editable assumption — change this value | E2: Calculated — driven by formula
B3: SCHOOL PROFILE
C5: School Name | D5: Heritage Academy
C6: State | D6: FL
C7: School Type | D7: Private School
C8: First Operating Year | D8: 2023
B10: ENROLLMENT FORECAST
C12: Year 1 Enrollment | D12: 100
C13: Year 2 Enrollment | D13: 130
C14: Year 3 Enrollment | D14: 160
C15: Year 4 Enrollment | D15: 185
C16: Year 5 Enrollment | D16: 200
B18: REVENUE ASSUMPTIONS
C20: Tuition per Student (Year 1) | D20: 0
C21: Tuition Annual Growth % | D21: 0.03
C22: ESA per Student (Year 1) | D22: 8700
C23: ESA Annual Growth % | D23: 0.03
C24: Other Per-Student Revenue (Year 1) | D24: 500
C25: Other Revenue Growth % | D25: 0.03
C26: Collection Rate % | D26: 0.95
C27: Grants & Contributions (Year 1) | D27: 75000
C28: Grants Growth % | D28: 0
B30: STAFFING ASSUMPTIONS
C32: Students per Teacher | D32: 11
C33: Avg Teacher Salary (Year 1) | D33: 40000
C34: Teacher Salary Growth % | D34: 0.03
C35: Admin FTE - Year 1 | D35: 4
C36: Admin FTE - Year 2 | D36: 4
C37: Admin FTE - Year 3 | D37: 4
C38: Admin FTE - Year 4 | D38: 4
C39: Admin FTE - Year 5 | D39: 4
C40: Avg Admin Salary (Year 1) | D40: 66000
C41: Admin Salary Growth % | D41: 0.03
C42: Benefits Burden % | D42: 0.24166667
B44: OPERATING EXPENSE ASSUMPTIONS
C46: Annual Rent (Year 1) | D46: 102000
C47: Rent Growth % | D47: 0.03
C48: Other Facility Cost (Year 1) | D48: 34400
C49: Other Facility Growth % | D49: 0.03
...

Sheet Drivers
B1: Revenue & Expense Drivers
C3: Year 1 | D3: Year 2 | E3: Year 3 | F3: Year 4 | G3: Year 5
B4: Enrollment | C4: =Assumptions!D12 -> 100 | D4: =Assumptions!D13 -> 130 | E4: =Assumptions!D14 -> 160 | F4: =Assumptions!D15 -> 185 | G4: =Assumptions!D16 -> 200
B5: Tuition Revenue (Net) | C5: =Assumptions!D12*Assumptions!D20 -> 0 | D5: =Assumptions!D13*Assumptions!D20*(1+Assumptions!D21)^1 -> 0 | E5: =Assumptions!D14*Assumptions!D20*(1+Assumptions!D21)^2 -> 0 | F5: =Assumptions!D15*Assumptions!D20*(1+Assumptions!D21)^3 -> 0 | G5: =Assumptions!D16*Assumptions!D20*(1+Assumptions!D21)^4 -> 0
B6: × Collection Rate Applied | C6: =C5*Assumptions!D26 -> 0 | D6: =D5*Assumptions!D26 -> 0 | E6: =E5*Assumptions!D26 -> 0 | F6: =F5*Assumptions!D26 -> 0 | G6: =G5*Assumptions!D26 -> 0
B7: ESA / School Choice Revenue | C7: =Assumptions!D12*Assumptions!D22 -> 870000 | D7: =Assumptions!D13*Assumptions!D22*(1+Assumptions!D23)^1 -> 1164930 | E7: =Assumptions!D14*Assumptions!D22*(1+Assumptions!D23)^2 -> 1476772.8 | F7: =Assumptions!D15*Assumptions!D22*(1+Assumptions!D23)^3 -> 1758744.1 | G7: =Assumptions!D16*Assumptions!D22*(1+Assumptions!D23)^4 -> 1958385.3
B8: Other Earned Revenue | C8: =Assumptions!D12*Assumptions!D24 -> 50000 | D8: =Assumptions!D13*Assumptions!D24*(1+Assumptions!D25)^1 -> 66950 | E8: =Assumptions!D14*Assumptions!D24*(1+Assumptions!D25)^2 -> 84872 | F8: =Assumptions!D15*Assumptions!D24*(1+Assumptions!D25)^3 -> 101077.25 | G8: =Assumptions!D16*Assumptions!D24*(1+Assumptions!D25)^4 -> 112550.88
B9: Grants & Contributions | C9: =Assumptions!D27 -> 75000 | D9: =Assumptions!D27*(1+Assumptions!D28)^1 -> 75000 | E9: =Assumptions!D27*(1+Assumptions!D28)^2 -> 75000 | F9: =Assumptions!D27*(1+Assumptions!D28)^3 -> 75000 | G9: =Assumptions!D27*(1+Assumptions!D28)^4 -> 75000
B10: Total Revenue | C10: =C6+C7+C8+C9 -> 995000 | D10: =D6+D7+D8+D9 -> 1306880 | E10: =E6+E7+E8+E9 -> 1636644.8 | F10: =F6+F7+F8+F9 -> 1934821.4 | G10: =G6+G7+G8+G9 -> 2145936.2
B12: Teacher FTE (Enrollment ÷ Ratio) | C12: =CEILING(Assumptions!D12/Assumptions!D32,1) -> 10 | D12: =CEILING(Assumptions!D13/Assumptions!D32,1) -> 12 | E12: =CEILING(Assumptions!D14/Assumptions!D32,1) -> 15 | F12: =CEILING(Assumptions!D15/Assumptions!D32,1) -> 17 | G12: =CEILING(Assumptions!D16/Assumptions!D32,1) -> 19
B13: Teacher Salaries | C13: =C12*Assumptions!D33 -> 400000 | D13: =D12*Assumptions!D33*(1+Assumptions!D34)^1 -> 494400 | E13: =E12*Assumptions!D33*(1+Assumptions!D34)^2 -> 636540 | F13: =F12*Assumptions!D33*(1+Assumptions!D34)^3 -> 743054.36 | G13: =G12*Assumptions!D33*(1+Assumptions!D34)^4 -> 855386.7
B14: Admin Salaries | C14: =Assumptions!D35*Assumptions!D40 -> 264000 | D14: =Assumptions!D36*Assumptions!D40*(1+Assumptions!D41)^1 -> 271920 | E14: =Assumptions!D37*Assumptions!D40*(1+Assumptions!D41)^2 -> 280077.6 | F14: =Assumptions!D38*Assumptions!D40*(1+Assumptions!D41)^3 -> 288479.93 | G14: =Assumptions!D39*Assumptions!D40*(1+Assumptions!D41)^4 -> 297134.33
B15: Benefits & Payroll Taxes | C15: =(C13+C14)*Assumptions!D42 -> 160466.67 | D15: =(D13+D14)*Assumptions!D42 -> 185194 | E15: =(E13+E14)*Assumptions!D42 -> 221515.92 | F15: =(F13+F14)*Assumptions!D42 -> 249287.45 | G15: =(G13+G14)*Assumptions!D42 -> 278525.91
B16: Total Staffing Cost | C16: =C13+C14+C15 -> 824466.67 | D16: =D13+D14+D15 -> 951514 | E16: =E13+E14+E15 -> 1138133.5 | F16: =F13+F14+F15 -> 1280821.7 | G16: =G13+G14+G15 -> 1431046.9
B18: Rent / Lease | C18: =Assumptions!D46 -> 102000 | D18: =Assumptions!D46*(1+Assumptions!D47)^1 -> 105060 | E18: =Assumptions!D46*(1+Assumptions!D47)^2 -> 108211.8 | F18: =Assumptions!D46*(1+Assumptions!D47)^3 -> 111458.15 | G18: =Assumptions!D46*(1+Assumptions!D47)^4 -> 114801.9
B19: Other Facility Costs | C19: =Assumptions!D48 -> 34400 | D19: =Assumptions!D48*(1+Assumptions!D49)^1 -> 35432 | E19: =Assumptions!D48*(1+Assumptions!D49)^2 -> 36494.96 | F19: =Assumptions!D48*(1+Assumptions!D49)^3 -> 37589.809 | G19: =Assumptions!D48*(1+Assumptions!D49)^4 -> 38717.503
B20: Program / Curriculum | C20: =Assumptions!D12*Assumptions!D50 -> 60000 | D20: =Assumptions!D13*Assumptions!D50*(1+Assumptions!D51)^1 -> 104442 | E20: =Assumptions!D14*Assumptions!D50*(1+Assumptions!D51)^2 -> 172120.42 | F20: =Assumptions!D15*Assumptions!D50*(1+Assumptions!D51)^3 -> 266480.06 | G20: =Assumptions!D16*Assumptions!D50*(1+Assumptions!D51)^4 -> 385747.89
B21: G&A / Technology | C21: =Assumptions!D52 -> 75000 | D21: =Assumptions!D52*(1+Assumptions!D53)^1 -> 89610 | E21: =Assumptions!D52*(1+Assumptions!D53)^2 -> 107066.03 | F21: =Assumptions!D52*(1+Assumptions!D53)^3 -> 127922.49 | G21: =Assumptions!D52*(1+Assumptions!D53)^4 -> 152841.79
B22: Total Operating Expenses | C22: =C18+C19+C20+C21 -> 271400 | D22: =D18+D19+D20+D21 -> 334544 | E22: =E18+E19+E20+E21 -> 423893.2 | F22: =F18+F19+F20+F21 -> 543450.51 | G22: =G18+G19+G20+G21 -> 692109.08

Sheet 5-Year P&L
B1: 5-Year Pro Forma Profit & Loss
C3: Year 1 | D3: Year 2 | E3: Year 3 | F3: Year 4 | G3: Year 5
B5: Enrollment | C5: =Drivers!C4 -> 100 | D5: =Drivers!D4 -> 130 | E5: =Drivers!E4 -> 160 | F5: =Drivers!F4 -> 185 | G5: =Drivers!G4 -> 200
B6: Tuition Revenue (Net) | C6: =Drivers!C6 -> 0 | D6: =Drivers!D6 -> 0 | E6: =Drivers!E6 -> 0 | F6: =Drivers!F6 -> 0 | G6: =Drivers!G6 -> 0
B7: ESA / School Choice | C7: =Drivers!C7 -> 870000 | D7: =Drivers!D7 -> 1164930 | E7: =Drivers!E7 -> 1476772.8 | F7: =Drivers!F7 -> 1758744.1 | G7: =Drivers!G7 -> 1958385.3
B8: Other Revenue | C8: =Drivers!C8 -> 50000 | D8: =Drivers!D8 -> 66950 | E8: =Drivers!E8 -> 84872 | F8: =Drivers!F8 -> 101077.25 | G8: =Drivers!G8 -> 112550.88
B9: Grants & Contributions | C9: =Drivers!C9 -> 75000 | D9: =Drivers!D9 -> 75000 | E9: =Drivers!E9 -> 75000 | F9: =Drivers!F9 -> 75000 | G9: =Drivers!G9 -> 75000
B10: Total Revenue | C10: =Drivers!C10 -> 995000 | D10: =Drivers!D10 -> 1306880 | E10: =Drivers!E10 -> 1636644.8 | F10: =Drivers!F10 -> 1934821.4 | G10: =Drivers!G10 -> 2145936.2
B12: Total Staffing | C12: =Drivers!C16 -> 824466.67 | D12: =Drivers!D16 -> 951514 | E12: =Drivers!E16 -> 1138133.5 | F12: =Drivers!F16 -> 1280821.7 | G12: =Drivers!G16 -> 1431046.9
B13: Total Operating Expenses | C13: =Drivers!C22 -> 271400 | D13: =Drivers!D22 -> 334544 | E13: =Drivers!E22 -> 423893.2 | F13: =Drivers!F22 -> 543450.51 | G13: =Drivers!G22 -> 692109.08
B15: Total Expenses | C15: =C12+C13 -> 1095866.7 | D15: =D12+D13 -> 1286058 | E15: =E12+E13 -> 1562026.7 | F15: =F12+F13 -> 1824272.2 | G15: =G12+G13 -> 2123156
B16: Net Operating Income (NOI) | C16: =C10-C15 -> -100866.67 | D16: =D10-D15 -> 20822 | E16: =E10-E15 -> 74618.076 | F16: =F10-F15 -> 110549.1 | G16: =G10-G15 -> 22780.197
B17: Operating Margin | C17: =IF(C10>0,C16/C10,0) -> -0.10137353 | D17: =IF(D10>0,D16/D10,0) -> 0.0159326 | E17: =IF(E10>0,E16/E10,0) -> 0.0455921 | F17: =IF(F10>0,F16/F10,0) -> 0.0571366 | G17: =IF(G10>0,G16/G10,0) -> 0.01061551
B19: Capital & Debt Service | C19: ='Cash Flow & DSCR'!C9 -> 59064.393 | D19: ='Cash Flow & DSCR'!D9 -> 59064.393 | E19: ='Cash Flow & DSCR'!E9 -> 59064.393 | F19: ='Cash Flow & DSCR'!F9 -> 59064.393 | G19: ='Cash Flow & DSCR'!G9 -> 59064.393
B21: Net Income | C21: =C16-C19 -> -159931.06 | D21: =D16-D19 -> -38242.393 | E21: =E16-E19 -> 15553.683 | F21: =F16-F19 -> 51484.712 | G21: =G16-G19 -> -36284.196
B22: Net Margin | C22: =IF(C10>0,C21/C10,0) -> -0.16073473 | D22: =IF(D10>0,D21/D10,0) -> -0.02926236 | E22: =IF(E10>0,E21/E10,0) -> 0.0095034 | F22: =IF(F10>0,F21/F10,0) -> 0.02660954 | G22: =IF(G10>0,G21/G10,0) -> -0.01690833
B24: Cumulative Net Income | C24: =C21 -> -159931.06 | D24: =C24+D21 -> -198173.45 | E24: =D24+E21 -> -182619.77 | F24: =E24+F21 -> -131135.06 | G24: =F24+G21 -> -167419.25
B25: Break-even

Sheet Cash Flow & DSCR
B1: Cash Flow & Debt Service Coverage
C3: Year 1 | D3: Year 2 | E3: Year 3 | F3: Year 4 | G3: Year 5
B4: Beginning Cash | C4: =Assumptions!D57 -> 75000 | D4: =C16 -> -84931.06 | E4: =D16 -> -123173.45 | F4: =E16 -> -107619.77 | G4: =F16 -> -56135.059
B5: Net Operating Income | C5: ='5-Year P&L'!C16 -> -100866.67 | D5: ='5-Year P&L'!D16 -> 20822 | E5: ='5-Year P&L'!E16 -> 74618.076 | F5: ='5-Year P&L'!F16 -> 110549.1 | G5: ='5-Year P&L'!G16 -> 22780.197
B7: Existing Debt Service | C7: =Assumptions!D58 -> 25000 | D7: =Assumptions!D58 -> 25000 | E7: =Assumptions!D58 -> 25000 | F7: =Assumptions!D58 -> 25000 | G7: =Assumptions!D58 -> 25000
B8: Proposed Loan Debt Service | C8: =IF(Assumptions!D59>0,PMT(Assumptions!D60/12,Assumptions!D61*12,-Assumptions!D59)*12,0) -> 34064.393 | D8: =IF(Assumptions!D59>0,PMT(Assumptions!D60/12,Assumptions!D61*12,-Assumptions!D59)*12,0) -> 34064.393 | E8: =IF(Assumptions!D59>0,PMT(Assumptions!D60/12,Assumptions!D61*12,-Assumptions!D59)*12,0) -> 34064.393 | F8: =IF(Assumptions!D59>0,PMT(Assumptions!D60/12,Assumptions!D61*12,-Assumptions!D59)*12,0) -> 34064.393 | G8: =IF(Assumptions!D59>0,PMT(Assumptions!D60/12,Assumptions!D61*12,-Assumptions!D59)*12,0) -> 34064.393
B9: Total Debt Service | C9: =C7+C8 -> 59064.393 | D9: =D7+D8 -> 59064.393 | E9: =E7+E8 -> 59064.393 | F9: =F7+F8 -> 59064.393 | G9: =G7+G8 -> 59064.393
B11: DSCR (NOI ÷ Total Debt Service) | C11: =IF(C9>0,C5/C9,IF(C5>0,99.9,0)) -> -1.7077407 | D11: =IF(D9>0,D5/D9,IF(D5>0,99.9,0)) -> 0.3525305 | E11: =IF(E9>0,E5/E9,IF(E5>0,99.9,0)) -> 1.2633343 | F11: =IF(F9>0,F5/F9,IF(F5>0,99.9,0)) -> 1.8716709 | G11: =IF(G9>0,G5/G9,IF(G5>0,99.9,0)) -> 0.38568409
B13: Net Income After Debt | C13: =C5-C9 -> -159931.06 | D13: =D5-D9 -> -38242.393 | E13: =E5-E9 -> 15553.683 | F13: =F5-F9 -> 51484.712 | G13: =G5-G9 -> -36284.196
B14: Net Cash Flow | C14: =C5-C9 -> -159931.06 | D14: =D5-D9 -> -38242.393 | E14: =E5-E9 -> 15553.683 | F14: =F5-F9 -> 51484.712 | G14: =G5-G9 -> -36284.196
B16: Ending Cash | C16: =C4+C14 -> -84931.06 | D16: =D4+D14 -> -123173.45 | E16: =E4+E14 -> -107619.77 | F16: =F4+F14 -> -56135.059 | G16: =G4+G14 -> -92419.255

Sheet Staffing
B1: Staffing Detail
C3: Year 1 | D3: Year 2 | E3: Year 3 | F3: Year 4 | G3: Year 5
B4: Teacher FTE | C4: =Drivers!C12 -> 10 | D4: =Drivers!D12 -> 12 | E4: =Drivers!E12 -> 15 | F4: =Drivers!F12 -> 17 | G4: =Drivers!G12 -> 19
B5: Admin FTE | C5: =Assumptions!D35 -> 4 | D5: =Assumptions!D36 -> 4 | E5: =Assumptions!D37 -> 4 | F5: =Assumptions!D38 -> 4 | G5: =Assumptions!D39 -> 4
B6: Total FTE | C6: =C4+C5 -> 14 | D6: =D4+D5 -> 16 | E6: =E4+E5 -> 19 | F6: =F4+F5 -> 21 | G6: =G4+G5 -> 23

Sheet Loan Snapshot
B1: Proposed Loan Summary
B3: Loan Amount | C3: =Assumptions!D59 -> 250000
B4: Interest Rate | C4: =Assumptions!D60 -> 0.065
B5: Term (Years) | C5: =Assumptions!D61 -> 10
B6: Annual Debt Service | C6: =IF(Assumptions!D59>0,PMT(Assumptions!D60/12,Assumptions!D61*12,-Assumptions!D59)*12,0) -> 34064.393
B8: Year 1 DSCR | C8: ='Cash Flow & DSCR'!C11 -> -1.7077407

Sheet Summary
B1: Model Summary
B3: School Name | C3: =Assumptions!D5 -> Heritage Academy
B4: School Type | C4: =Assumptions!D7 -> Private School
B5: State | C5: =Assumptions!D6 -> FL
B6: Opening Year | C6: =Assumptions!D8 -> 2023
B8: Year 5 Enrollment | C8: =Assumptions!D16 -> 200
B9: Year 5 Revenue | C9: =Drivers!G10 -> 2145936.2
B10: Year 5 NOI | C10: ='5-Year P&L'!G16 -> 22780.197
B12: KEY RATIOS
B13: Net Margin (Year 5) | C13: =IF(Drivers!G10>0,'5-Year P&L'!G21/Drivers!G10,0) -> -0.01690833
B14: Personnel % of Revenue (Year 5) | C14: =IF(Drivers!G10>0,Drivers!G16/Drivers!G10,0) -> 0.66686369
B15: Revenue per Student (Year 5) | C15: =IF(Assumptions!D16>0,Drivers!G10/Assumptions!D16,0) -> 10730
B16: Expense per Student (Year 5) | C16: =IF(Assumptions!D16>0,('5-Year P&L'!G12+'5-Year P&L'!G13)/Assumptions!D16,0) -> 10616
B17: DSCR (Year 1) | C17: ='Cash Flow & DSCR'!C11 -> -1.7077407
B18: DSCR (Year 5) | C18: ='Cash Flow & DSCR'!G11 -> 0.38568409
B19: Days Cash on Hand (Year 1) | C19: 0
B21: Generated by SchoolStack Budget (budget.schoolstack.ai)

Sheet Decision History
B1: Decision History
B2: No decisions have been tracked with an outcome yet. As the team marks saved scenarios as Pursued, Declined, or On hold, those outcomes (and any retrospective notes) will appear here so reviewers can see what actually happened versus what was modeled.
B4: Once decisions are saved with a Pursued / Declined / On hold outcome inside the planner, they will be summarized here.

Sheet Financial Health
B2: Heritage Academy — Financial Health Dashboard
B3: Generated April 29, 2026
B4: ● Green = healthy | D4: ◐ Yellow = monitor | F4: ○ Red = action needed
B6: Metric | C6: Year 1 | D6: Year 2 | E6: Year 3 | F6: Year 4 | G6: Year 5 | H6: Benchmark
B7: Enrollment | C7: 100 | D7: 130 | E7: 160 | F7: 185 | G7: 200
B8: Revenue | C8: 995000 | D8: 1306880 | E8: 1636644.8 | F8: 1934821.4 | G8: 2145936.2
B9: Personnel | C9: 824466.67 | D9: 951514 | E9: 1138133.5 | F9: 1280821.7 | G9: 1431046.9
B10: Operating Expenses | C10: 271400 | D10: 334544 | E10: 423893.2 | F10: 543450.51 | G10: 692109.08
B11: Debt Service | C11: 59064.393 | D11: 59064.393 | E11: 59064.393 | F11: 59064.393 | G11: 59064.393
B12: Net Income | C12: -159931.06 | D12: -38242.393 | E12: 15553.683 | F12: 51484.712 | G12: -36284.196
B13: Ending Cash | C13: -84931.06 | D13: -123173.45 | E13: -107619.77 | F13: -56135.059 | G13: -92419.255
B14: Net Margin | C14: -0.16073473 | D14: -0.02926236 | E14: 0.0095033955 | F14: 0.026609543 | G14: -0.016908329
B15: Revenue per Student | C15: 9950 | D15: 10052.923 | E15: 10229.03 | F15: 10458.494 | G15: 10729.681 | H15: ≥ $10,000
B16: Cost per Student | C16: 11549.311 | D16: 10347.095 | E16: 10131.819 | F16: 10180.198 | G16: 10911.102
B17: Instructional / Student | C17: 600 | D17: 803.4 | E17: 1075.7526 | F17: 1440.4327 | G17: 1928.7394
B18: Facility / Student | C18: 1364 | D18: 1080.7077 | E18: 904.41725 | F18: 805.66466 | G18: 767.59701 | H18: ≤ $2,000 / $2k–$3.5k / > $3,500
B19: Surplus per Student | C19: -1599.3106 | D19: -294.17226 | E19: 97.210518 | F19: 278.29574 | G19: -181.42098
B20: Payroll % | C20: 0.82860972 | D20: 0.72808062 | E20: 0.69540655 | F20: 0.6619845 | G20: 0.66686369 | H20: ≤ 55%
B21: Facility % | C21: 0.13708543 | D21: 0.10750184 | E21: 0.088416717 | F21: 0.077034483 | G21: 0.071539592 | H21: ≤ 15%
B22: Operating Margin | C22: -0.10137353 | D22: 0.015932603 | E22: 0.045592102 | F22: 0.057136595 | G22: 0.010615505 | H22: ≥ 10%
B23: Revenue Sources | C23: 3 | D23: 3 | E23: 3 | F23: 3 | G23: 3 | H23: ≥ 3 sources
B24: DSCR | C24: -1.7077407 | D24: 0.3525305 | E24: 1.2633343 | F24: 1.8716709 | G24: 0.38568409 | H24: ≥ 1.25x
B25: Break-even Year | C25: =IF('5-Year P&L'!C24>=0,"✓ Break-even","") -> 0 | D25: =IF(AND('5-Year P&L'!D24>=0,'5-Year P&L'!C24<0),"✓ Break-even","") -> 0 | E25: =IF(AND('5-Year P&L'!E24>=0,'5-Year P&L'!D24<0),"✓ Break-even","") -> 0 | F25: =IF(AND('5-Year P&L'!F24>=0,'5-Year P&L'!E24<0),"✓ Break-even","") -> 0 | G25: =IF(AND('5-Year P&L'!G24>=0,'5-Year P&L'!F24<0),"✓ Break-even","") -> 0 | H25: Year 1
B26: Cash Runway (Months) | C26: -1 | D26: -1 | E26: -1 | F26: 0 | G26: -1 | H26: ≥ 24 months
B27: Days Cash on Hand | C27: 0 | D27: 0 | E27: 0 | F27: 0 | G27: 0 | H27: ≥ 90 days
B29: FINANCIAL HEALTH SIGNALS | C29: Status | D29: Assessment | F29: Watch Item
B30: Viability | C30: ○ Needs attention | D30: The model does not reach break-even within 5 years. This needs to be addressed before approaching lenders. | F30: Revisit revenue assumptions and cost structure to build a clear path to break-even.
B31: Liquidity | C31: ○ Needs attention | D31: Cash goes negative in month 6. The school will need outside funding to continue operating. | F31: Secure a line of credit or bridge funding before operations begin.
B32: Staffing Burden | C32: ○ Needs attention | D32: Staffing at 67% of revenue is above the sustainable range. There's too little left for everything else. | F32: Review staffing plan for phased hiring, shared roles, or adjusted ratios.
B33: Facility Burden | C33: ● Healthy | D33: Facility costs at 7% of revenue are well-managed and leave budget for programs. | F33: Watch for rent escalation clauses that could push this higher over time.
B34: Debt Affordability | C34: ○ Needs attention | D34: DSCR of 0.39x is below the 1.15x amber threshold. Any shortfall in revenue makes debt unaffordable. | F34: Reduce loan amounts, extend terms, or increase revenue before committing to this debt.
B35: Revenue Concentration | C35: ● Healthy | D35: Revenue is anchored to enrollment-driven income — the strongest foundation for a school model. A focused revenue stream is a strength when backed by dependable demand. | F35: Continue to pressure-test enrollment assumptions: recruitment pipeline, waitlist depth, retention rates, and collection reliability.
B36: Reserve Strength | C36: ○ Needs attention | D36: Less than 1 month of reserves by Year 5. The school has no financial cushion. | F36: Prioritize building reserves — even a small surplus each year compounds into meaningful protection.
B38: Summary | C38: 2 Healthy | 0 Watch | 5 Needs Attention
B40: Built by SchoolStack Budget • budget.schoolstack.ai
