Workbook

Sheet Instructions
B2: How to Use This Workbook
B3: Liberty Learning Co-Op
B4: Generated March 27, 2026 · llc_single
B6: Cell Color Legend
B7: Blue cells are editable inputs — change these to update your model.
B8: White cells contain formulas — do not edit (they recalculate automatically).
B9: Green cells are key outputs and summary metrics.
B11: Navigation
B12: The Assumptions tab is the central control panel — all other tabs reference it.
B14: Structure
B15: Tabs 5-9: Drivers & inputs
B16: Tabs 10-13: Forecasts & budgets
... B37: user-provided assumptions and should be independently verified.

Sheet Cover
B3: SchoolStack Budget
B5: 5-Year Financial Model & Underwriting Workbook
B8: School Name | C8: Liberty Learning Co-Op
B9: School Type | C9: Homeschool Co-Op
B10: Entity Type | C10: LLC (Single Member)
B11: State | C11: AZ
B12: Fiscal Year Start | C12: Month 7
B13: Model Date | C13: March 27, 2026
B14: Stage | C14: Startup / Pre-Opening
B15: Funding Profile | C15: Hybrid / Mixed
B18: Table of Contents
B19: 1. | C19: Instructions
B20: 2. | C20: Cover
B21: 3. | C21: Assumptions
B22: 4. | C22: Program Profile
B23: 5. | C23: Enrollment Drivers
B24: 6. | C24: Tuition & Funding
B25: 7. | C25: Staffing Drivers
B26: 8. | C26: OpEx Drivers
B27: 9. | C27: Capital Stack
B28: 10. | C28: Enrollment Tuition Fcst
B29: 11. | C29: Staffing Costs Fcst
B30: 12. | C30: Budget Detail
... B40: 22. | C40: Financial Health
B43: CONFIDENTIAL - Prepared by SchoolStack Budget (budget.schoolstack.ai)

Sheet Assumptions
A1: Liberty Learning Co-Op - Assumptions
B2: Editable assumption — change this value | E2: Calculated — driven by formula
A4: SCHOOL PROFILE
A5: School Name | B5: Liberty Learning Co-Op
A6: School Type | B6: Homeschool Co-Op
A7: Entity Type | B7: LLC (Single Member)
A8: State | B8: AZ
A9: EIN | B9: 86-5551234
A10: Stage | B10: Startup / Pre-Opening
A11: Funding Profile | B11: Hybrid / Mixed
A12: Fiscal Year Start Month | B12: 7
A13: Max Capacity | B13: 40
A15: ENROLLMENT
B16: 2026-27 | C16: 2027-28 | D16: 2028-29 | E16: 2029-30 | F16: 2030-31
A17: Total Students | B17: 15 | C17: 22 | D17: 30 | E17: 36 | F17: 40
A19: REVENUE DRIVERS
A20: Line Item | B20: Category | C20: Driver | D20: Amount | E20: Escalation %
A21: Co-Op Tuition | B21: Tuition & Fees | C21: Per Student | D21: 6000 | E21: 0
A22: Materials Fee | B22: Tuition & Fees | C22: Per Student | D22: 200 | E22: 0
A23: ESA Revenue | B23: School Choice | C23: Per Student | D23: 7000 | E23: 0
A24: Annual Fundraising | B24: Philanthropy | C24: Annual Fixed | D24: 3000 | E24: 0
A26: STAFFING
A27: Role | B27: Category | C27: Type | D27: FTE | E27: Rate | F27: Benefits % | G27: Tax %
A28: Director / Lead Educator | B28: School Leadership | C28: full_time | D28: 1 | E28: 48000 | F28: 0.2 | G28: 0.0765
A29: Assistant Educator | B29: Instructional | C29: part_time | D29: 0.5 | E29: 30000 | F29: 0 | G29: 0.0765
A31: OPERATING EXPENSES
A32: Line Item | B32: Category | C32: Driver | D32: Amount | E32: Escalation %
A33: Rent | B33: Occupancy / Facility | C33: Monthly | D33: 1800 | E33: 0.03
A34: Utilities | B34: Occupancy / Facility | C34: Monthly | D34: 200 | E34: 0
A35: Insurance | B35: Occupancy / Facility | C35: Annual Fixed | D35: 1800 | E35: 0
A36: Curriculum & Materials | B36: Instructional / Program | C36: Per Student | D36: 400 | E36: 0
A37: Technology | B37: Technology | C37: Per Student | D37: 250 | E37: 0
A39: CAPITAL & DEBT
A40: Instrument | B40: Type | C40: Principal | D40: Rate | E40: Term (Yrs)
A42: GROWTH & TIMING
A43: Salary Escalation Rate | B43: 0.03 | C43: Salary input or tuition escalation fallback
A44: Cost Inflation Rate | B44: 0.03 | C44: Cost inflation input or tuition escalation fallback
A45: Year 1 Proration Factor | B45: 0.83333333
A46: Starting Cash | B46: 0
A47: Debt Included | B47: No
...

Sheet Program Profile
A1: Program Profile
A3: School Model | B3: microschool
A4: School Type | B4: Homeschool Co-Op
A5: Entity Type | B5: LLC (Single Member)
A6: Financial Label Convention | B6: For-Profit (Profit & Loss / Equity)
A7: Stage | B7: Startup / Pre-Opening
A8: Funding Mix | B8: Hybrid / Mixed
A9: Fiscal Year Start Month | B9: 7
A10: Year 1 Operating Months | B10: 10
A11: Proration Factor | B11: 83.3%
A12: Debt Included | B12: No
A13: Max Capacity | B13: 40
A14: Accredited | B14: No
... A16: Facility | B16: Leased

Sheet Enrollment Drivers
A1: Enrollment Drivers
B3: 2026-27 | C3: 2027-28 | D3: 2028-29 | E3: 2029-30 | F3: 2030-31
A5: TOTAL ENROLLMENT
A6: Total Students | B6: 15 | C6: 22 | D6: 30 | E6: 36 | F6: 40
A7: Max Capacity | B7: 40
A8: Capacity Utilization | B8: =B6/$B$7 -> 0.375 | C8: =C6/$B$7 -> 0.55 | D8: =D6/$B$7 -> 0.75 | E8: =E6/$B$7 -> 0.9 | F8: =F6/$B$7 -> 1
A10: Enrollment Growth Rate | B10: - | C10: =IF(B6=0,0,(C6-B6)/B6) -> 0.46666667 | D10: =IF(C6=0,0,(D6-C6)/C6) -> 0.36363636 | E10: =IF(D6=0,0,(E6-D6)/D6) -> 0.2 | F10: =IF(E6=0,0,(F6-E6)/E6) -> 0.11111111
A12: WEIGHTED ENROLLMENT POPULATIONS
A14: Special Education (SPED) | B14: =Assumptions!B51 -> 3 | C14: =Assumptions!C51 -> 4 | D14: =Assumptions!D51 -> 5 | E14: =Assumptions!E51 -> 6 | F14: =Assumptions!F51 -> 6
A15: English Language Learners (ELL) | B15: =Assumptions!B52 -> 2 | C15: =Assumptions!C52 -> 3 | D15: =Assumptions!D52 -> 4 | E15: =Assumptions!E52 -> 5 | F15: =Assumptions!F52 -> 5
A16: Economically Disadvantaged | B16: =Assumptions!B53 -> 5 | C16: =Assumptions!C53 -> 7 | D16: =Assumptions!D53 -> 9 | E16: =Assumptions!E53 -> 10 | F16: =Assumptions!F53 -> 12
A17: Total Weighted Population | B17: =B14+B15+B16 -> 10 | C17: =C14+C15+C16 -> 14 | D17: =D14+D15+D16 -> 18 | E17: =E14+E15+E16 -> 21 | F17: =F14+F15+F16 -> 23
A18: Weighted % of Total | B18: =IF(B6=0,0,B17/B6) -> 0.66666667 | C18: =IF(C6=0,0,C17/C6) -> 0.63636364 | D18: =IF(D6=0,0,D17/D6) -> 0.6 | E18: =IF(E6=0,0,E17/E6) -> 0.58333333 | F18: =IF(F6=0,0,F17/F6) -> 0.575

Sheet Tuition & Funding
A1: Tuition & Funding Drivers
B3: 2026-27 | C3: 2027-28 | D3: 2028-29 | E3: 2029-30 | F3: 2030-31
A4: TUITION & FEES
A5: Co-Op Tuition | B5: 90000 | C5: 135960 | D5: 190962 | E5: 236029 | F5: 270122
A6: Materials Fee | B6: 3000 | C6: 4532 | D6: 6365 | E6: 7868 | F6: 9004
A7: Total Tuition & Fees | B7: =SUM(B5,B6) -> 93000 | C7: =SUM(C5,C6) -> 140492 | D7: =SUM(D5,D6) -> 197327 | E7: =SUM(E5,E6) -> 243897 | F7: =SUM(F5,F6) -> 279126
A8: SCHOOL CHOICE
A9: ESA Revenue | B9: 105000 | C9: 158620 | D9: 222789 | E9: 275367 | F9: 315142
A10: Total School Choice | B10: =SUM(B9) -> 105000 | C10: =SUM(C9) -> 158620 | D10: =SUM(D9) -> 222789 | E10: =SUM(E9) -> 275367 | F10: =SUM(F9) -> 315142
A11: PHILANTHROPY
A12: Annual Fundraising | B12: 3000 | C12: 3090 | D12: 3183 | E12: 3278 | F12: 3377
A13: Total Philanthropy | B13: =SUM(B12) -> 3000 | C13: =SUM(C12) -> 3090 | D13: =SUM(D12) -> 3183 | E13: =SUM(E12) -> 3278 | F13: =SUM(F12) -> 3377
A15: GRAND TOTAL REVENUE | B15: =SUM(B7,B10,B13) -> 201000 | C15: =SUM(C7,C10,C13) -> 302202 | D15: =SUM(D7,D10,D13) -> 423299 | E15: =SUM(E7,E10,E13) -> 522542 | F15: =SUM(F7,F10,F13) -> 597645

Sheet Staffing Drivers
A1: Staffing Drivers
A3: Role | B3: Category | C3: FTE | D3: Base Rate | E3: Benefits % | F3: Tax % | G3: Loaded Cost
A4: Director / Lead Educator | B4: School Leadership | C4: 1 | D4: 48000 | E4: 0.2 | F4: 0.0765 | G4: 61272
A5: Assistant Educator | B5: Instructional | C5: 0.5 | D5: 30000 | E5: 0 | F5: 0.0765 | G5: 16148
A7: 5-YEAR TOTAL PERSONNEL COST
B8: 2026-27 | C8: 2027-28 | D8: 2028-29 | E8: 2029-30 | F8: 2030-31
A9: Total Personnel | B9: 64516 | C9: 79742 | D9: 82134 | E9: 84598 | F9: 87136
A10: Personnel as % of Revenue | B10: 0.32097637 | C10: 0.26387014 | D10: 0.19403383 | E10: 0.16189774 | F10: 0.14579944
A11: Students per FTE | B11: 10 | C11: 14.7 | D11: 20 | E11: 24 | F11: 26.7

Sheet OpEx Drivers
A1: Operating Expense Drivers
B3: 2026-27 | C3: 2027-28 | D3: 2028-29 | E3: 2029-30 | F3: 2030-31
A4: Instructional / Program
A5: Curriculum & Materials | B5: 6000 | C5: 9064 | D5: 12731 | E5: 15735 | F5: 18008
A6: Total Instructional / Program | B6: =SUM(B5:B5) -> 6000 | C6: =SUM(C5:C5) -> 9064 | D6: =SUM(D5:D5) -> 12731 | E6: =SUM(E5:E5) -> 15735 | F6: =SUM(F5:F5) -> 18008
A7: Technology
A8: Technology | B8: 3750 | C8: 5665 | D8: 7957 | E8: 9835 | F8: 11255
A9: Total Technology | B9: =SUM(B8:B8) -> 3750 | C9: =SUM(C8:C8) -> 5665 | D9: =SUM(D8:D8) -> 7957 | E9: =SUM(E8:E8) -> 9835 | F9: =SUM(F8:F8) -> 11255
A10: Occupancy / Facility
A11: Rent | B11: 21600 | C11: 22248 | D11: 22915 | E11: 23603 | F11: 24311
A12: Utilities | B12: 2400 | C12: 2472 | D12: 2546 | E12: 2623 | F12: 2701
A13: Insurance | B13: 1800 | C13: 1854 | D13: 1910 | E13: 1967 | F13: 2026
A14: Total Occupancy / Facility | B14: =SUM(B11:B13) -> 25800 | C14: =SUM(C11:C13) -> 26574 | D14: =SUM(D11:D13) -> 27371 | E14: =SUM(E11:E13) -> 28192 | F14: =SUM(F11:F13) -> 29038
A16: TOTAL OPERATING EXPENSES | B16: =B6+B9+B14 -> 35550 | C16: =C6+C9+C14 -> 41303 | D16: =D6+D9+D14 -> 48059 | E16: =E6+E9+E14 -> 53762 | F16: =F6+F9+F14 -> 58301

Sheet Capital Stack
A1: Capital Stack & Loan Terms
A3: Instrument | B3: Type | C3: Principal | D3: Rate | E3: Term (Yrs) | F3: Annual Payment
A5: Total Annual Debt Service | F5: 0
A6: Total Loan Principal | F6: 0

Sheet Enrollment Tuition Fcst
A1: Enrollment & Tuition Forecast
B3: 2026-27 | C3: 2027-28 | D3: 2028-29 | E3: 2029-30 | F3: 2030-31
A4: Total Students | B4: 15 | C4: 22 | D4: 30 | E4: 36 | F4: 40
A6: REVENUE FORECAST
A7: Co-Op Tuition | B7: 90000 | C7: 135960 | D7: 190962 | E7: 236029 | F7: 270122
A8: Materials Fee | B8: 3000 | C8: 4532 | D8: 6365 | E8: 7868 | F8: 9004
A9: ESA Revenue | B9: 105000 | C9: 158620 | D9: 222789 | E9: 275367 | F9: 315142
A10: Annual Fundraising | B10: 3000 | C10: 3090 | D10: 3183 | E10: 3278 | F10: 3377
A11: TOTAL REVENUE | B11: =SUM(B7:B10) -> 201000 | C11: =SUM(C7:C10) -> 302202 | D11: =SUM(D7:D10) -> 423299 | E11: =SUM(E7:E10) -> 522542 | F11: =SUM(F7:F10) -> 597645
A13: Revenue per Student | B13: 13400 | C13: 13736 | D13: 14110 | E13: 14515 | F13: 14941

Sheet Staffing Costs Fcst
A1: Staffing Costs Forecast
B3: 2026-27 | C3: 2027-28 | D3: 2028-29 | E3: 2029-30 | F3: 2030-31
A4: Instructional
A5: Assistant Educator | B5: 13456 | C5: 16632 | D5: 17131 | E5: 17645 | F5: 18174
A6: Total Instructional | B6: =SUM(B5:B5) -> 13456 | C6: =SUM(C5:C5) -> 16632 | D6: =SUM(D5:D5) -> 17131 | E6: =SUM(E5:E5) -> 17645 | F6: =SUM(F5:F5) -> 18174
A7: School Leadership
A8: Director / Lead Educator | B8: 51060 | C8: 63110 | D8: 65003 | E8: 66954 | F8: 68962
A9: Total School Leadership | B9: =SUM(B8:B8) -> 51060 | C9: =SUM(C8:C8) -> 63110 | D9: =SUM(D8:D8) -> 65003 | E9: =SUM(E8:E8) -> 66954 | F9: =SUM(F8:F8) -> 68962
A11: TOTAL PERSONNEL | B11: =B6+B9 -> 64516 | C11: =C6+C9 -> 79742 | D11: =D6+D9 -> 82134 | E11: =E6+E9 -> 84598 | F11: =F6+F9 -> 87136

Sheet Budget Detail
A1: Liberty Learning Co-Op - Budget Detail
B3: 2026-27 | C3: 2027-28 | D3: 2028-29 | E3: 2029-30 | F3: 2030-31
A4: REVENUE
A5: Co-Op Tuition | B5: 75000 | C5: 135960 | D5: 190962 | E5: 236029 | F5: 270122
A6: Materials Fee | B6: 2500 | C6: 4532 | D6: 6365 | E6: 7868 | F6: 9004
A7: ESA Revenue | B7: 87500 | C7: 158620 | D7: 222789 | E7: 275367 | F7: 315142
A8: Annual Fundraising | B8: 2500 | C8: 3090 | D8: 3183 | E8: 3278 | F8: 3377
A9: Total Revenue | B9: =SUM(B5:B8) -> 167500 | C9: =SUM(C5:C8) -> 302202 | D9: =SUM(D5:D8) -> 423299 | E9: =SUM(E5:E8) -> 522542 | F9: =SUM(F5:F8) -> 597645
A11: PERSONNEL
A12: Director / Lead Educator | B12: 51060 | C12: 63110 | D12: 65003 | E12: 66954 | F12: 68962
A13: Assistant Educator | B13: 13456 | C13: 16632 | D13: 17131 | E13: 17645 | F13: 18174
A14: Total Personnel | B14: =SUM(B12:B13) -> 64516 | C14: =SUM(C12:C13) -> 79742 | D14: =SUM(D12:D13) -> 82134 | E14: =SUM(E12:E13) -> 84598 | F14: =SUM(F12:F13) -> 87136
A16: OPERATING EXPENSES
A17: Instructional / Program
A18: Curriculum & Materials | B18: 5000 | C18: 9064 | D18: 12731 | E18: 15735 | F18: 18008
A19: Technology
A20: Technology | B20: 3125 | C20: 5665 | D20: 7957 | E20: 9835 | F20: 11255
A21: Occupancy / Facility
A22: Rent | B22: 18000 | C22: 22248 | D22: 22915 | E22: 23603 | F22: 24311
A23: Utilities | B23: 2000 | C23: 2472 | D23: 2546 | E23: 2623 | F23: 2701
A24: Insurance | B24: 1500 | C24: 1854 | D24: 1910 | E24: 1967 | F24: 2026
A25: Total Occupancy / Facility | B25: =SUM(B22:B24) -> 21500 | C25: =SUM(C22:C24) -> 26574 | D25: =SUM(D22:D24) -> 27371 | E25: =SUM(E22:E24) -> 28192 | F25: =SUM(F22:F24) -> 29038
A26: Total Operating Expenses | B26: =B18+B20+B25 -> 29625 | C26: =C18+C20+C25 -> 41303 | D26: =D18+D20+D25 -> 48059 | E26: =E18+E20+E25 -> 53762 | F26: =F18+F20+F25 -> 58301
A28: CAPITAL & DEBT SERVICE
A29: Total Capital & Debt | B29: =SUM(B29:B28) -> 0 | C29: =SUM(C29:C28) -> 0 | D29: =SUM(D29:D28) -> 0 | E29: =SUM(E29:E28) -> 0 | F29: =SUM(F29:F28) -> 0

Sheet Budget Summary
A1: Liberty Learning Co-Op - Budget Summary
B3: 2026-27 | C3: 2027-28 | D3: 2028-29 | E3: 2029-30 | F3: 2030-31
A4: Total Revenue | B4: ='Budget Detail'!B9 -> 167500 | C4: ='Budget Detail'!C9 -> 302202 | D4: ='Budget Detail'!D9 -> 423299 | E4: ='Budget Detail'!E9 -> 522542 | F4: ='Budget Detail'!F9 -> 597645
A5: Total Personnel | B5: ='Budget Detail'!B14 -> 64516 | C5: ='Budget Detail'!C14 -> 79742 | D5: ='Budget Detail'!D14 -> 82134 | E5: ='Budget Detail'!E14 -> 84598 | F5: ='Budget Detail'!F14 -> 87136
A6: Total Operating Expenses | B6: ='Budget Detail'!B26 -> 29625 | C6: ='Budget Detail'!C26 -> 41303 | D6: ='Budget Detail'!D26 -> 48059 | E6: ='Budget Detail'!E26 -> 53762 | F6: ='Budget Detail'!F26 -> 58301
A7: Total Capital & Debt Service | B7: ='Budget Detail'!B29 -> 0 | C7: ='Budget Detail'!C29 -> 0 | D7: ='Budget Detail'!D29 -> 0 | E7: ='Budget Detail'!E29 -> 0 | F7: ='Budget Detail'!F29 -> 0
A8: Total Expenses | B8: =SUM(B5:B7) -> 94141 | C8: =SUM(C5:C7) -> 121045 | D8: =SUM(D5:D7) -> 130193 | E8: =SUM(E5:E7) -> 138361 | F8: =SUM(F5:F7) -> 145438
A10: KEY METRICS
A11: Net Income | B11: =B4-B8 -> 73359 | C11: =C4-C8 -> 181157 | D11: =D4-D8 -> 293106 | E11: =E4-E8 -> 384182 | F11: =F4-F8 -> 452207
A12: Net Margin % | B12: =IF(B4=0,0,B11/B4) -> 0.43796269 | C12: =IF(C4=0,0,C11/C4) -> 0.59945637 | D12: =IF(D4=0,0,D11/D4) -> 0.69243233 | E12: =IF(E4=0,0,E11/E4) -> 0.73521644 | F12: =IF(F4=0,0,F11/F4) -> 0.75664878
A13: Cumulative Net Income | B13: 73359 | C13: 254516 | D13: 547622 | E13: 931803 | F13: 1384011
A14: Revenue per Student | B14: 11167 | C14: 13736 | D14: 14110 | E14: 14515 | F14: 14941
A15: Cost per Student | B15: 6276 | C15: 5502 | D15: 4340 | E15: 3843 | F15: 3636

Sheet Monthly Cash Flow Y1
A1: Liberty Learning Co-Op - Year 1 Monthly Cash Flow
B2: July | C2: August | D2: September | E2: October | F2: November | G2: December | H2: January | I2: February | J2: March | K2: April | L2: May | M2: June | N2: Annual Total
A3: REVENUE
A4: Total Revenue | B4: 11050 | C4: 20050 | D4: 20050 | E4: 20050 | F4: 20050 | G4: 20050 | H4: 20050 | I4: 20050 | J4: 20050 | K4: 20050 | L4: 9250 | M4: 250 | N4: =SUM(B4:M4) -> 201000
A6: EXPENSES
A7: Personnel | B7: 6452 | C7: 6452 | D7: 6452 | E7: 6452 | F7: 6452 | G7: 6452 | H7: 6452 | I7: 6452 | J7: 6452 | K7: 6452 | L7: 0 | M7: 0 | N7: =SUM(B7:M7) -> 64516
A8: Operating Expenses | B8: 2963 | C8: 2963 | D8: 2963 | E8: 2963 | F8: 2963 | G8: 2963 | H8: 2963 | I8: 2963 | J8: 2963 | K8: 2963 | L8: 0 | M8: 0 | N8: =SUM(B8:M8) -> 29625
A9: Debt Service | B9: 0 | C9: 0 | D9: 0 | E9: 0 | F9: 0 | G9: 0 | H9: 0 | I9: 0 | J9: 0 | K9: 0 | L9: 0 | M9: 0 | N9: =SUM(B9:M9) -> 0
A11: CASH FLOW
A12: Total Expenses | B12: =B7+B8+B9 -> 9415 | C12: =C7+C8+C9 -> 9415 | D12: =D7+D8+D9 -> 9415 | E12: =E7+E8+E9 -> 9415 | F12: =F7+F8+F9 -> 9415 | G12: =G7+G8+G9 -> 9415 | H12: =H7+H8+H9 -> 9415 | I12: =I7+I8+I9 -> 9415 | ... M12: =M7+M8+M9 -> 0 | N12: =SUM(B12:M12) -> 94150
A13: Net Cash Flow | B13: =B4-B12 -> 1635 | C13: =C4-C12 -> 10635 | D13: =D4-D12 -> 10635 | E13: =E4-E12 -> 10635 | F13: =F4-F12 -> 10635 | G13: =G4-G12 -> 10635 | H13: =H4-H12 -> 10635 | I13: =I4-I12 -> 10635 | ... M13: =M4-M12 -> 250 | N13: =SUM(B13:M13) -> 106850
A14: Cumulative Cash | B14: =B17+B13 -> 1635 | C14: =B14+C13 -> 12270 | D14: =C14+D13 -> 22905 | E14: =D14+E13 -> 33540 | F14: =E14+F13 -> 44175 | G14: =F14+G13 -> 54810 | H14: =G14+H13 -> 65445 | I14: =H14+I13 -> 76080 | J14: =I14+J13 -> 86715 | ... M14: =L14+M13 -> 106850 | N14: =M14 -> 106850
A16: CASH FLOW METRICS
A17: Starting Cash | B17: 0
A18: Ending Cash (Month 12) | B18: =M14 -> 106850
A19: Minimum Cash Month | B19: =MIN(B14:M14) -> 1635

Sheet 5-Year Operating Stmt
A1: Liberty Learning Co-Op - 5-Year Operating Statement
B3: 2026-27 | C3: 2027-28 | D3: 2028-29 | E3: 2029-30 | F3: 2030-31
A4: REVENUE
A5: Total Revenue | B5: 167500 | C5: 302202 | D5: 423299 | E5: 522542 | F5: 597645
A7: EXPENSES
A8: Personnel | B8: 64516 | C8: 79742 | D8: 82134 | E8: 84598 | F8: 87136
A9: Operating Expenses | B9: 29625 | C9: 41303 | D9: 48059 | E9: 53762 | F9: 58301
A10: Capital & Debt Service | B10: 0 | C10: 0 | D10: 0 | E10: 0 | F10: 0
A11: Total Expenses | B11: =SUM(B8:B10) -> 94141 | C11: =SUM(C8:C10) -> 121045 | D11: =SUM(D8:D10) -> 130193 | E11: =SUM(E8:E10) -> 138361 | F11: =SUM(F8:F10) -> 145438
A13: BOTTOM LINE
A14: Net Income | B14: =B5-B11 -> 73359 | C14: =C5-C11 -> 181157 | D14: =D5-D11 -> 293106 | E14: =E5-E11 -> 384182 | F14: =F5-F11 -> 452207
A15: Net Margin % | B15: =IF(B5=0,0,B14/B5) -> 0.43796269 | C15: =IF(C5=0,0,C14/C5) -> 0.59945637 | D15: =IF(D5=0,0,D14/D5) -> 0.69243233 | E15: =IF(E5=0,0,E14/E5) -> 0.73521644 | F15: =IF(F5=0,0,F14/F5) -> 0.75664878
A16: Cumulative Net Income | B16: =B14 -> 73359 | C16: =B16+C14 -> 254516 | D16: =C16+D14 -> 547622 | E16: =D16+E14 -> 931803 | F16: =E16+F14 -> 1384011
A17: Break-even | B17: ✓ Break-even

Sheet Debt Schedule
A1: Debt Schedule
B3: 2026-27 | C3: 2027-28 | D3: 2028-29 | E3: 2029-30 | F3: 2030-31
A4: LOAN TERMS
A5: Loan Name | B5: Principal | C5: Annual Rate | D5: Term (Years) | E5: Annual Payment

Sheet Balance Sheet
A1: Liberty Learning Co-Op - Balance Sheet
B3: 2026-27 | C3: 2027-28 | D3: 2028-29 | E3: 2029-30 | F3: 2030-31
A4: ASSETS
A5: Cash & Equivalents | B5: ='Monthly Cash Flow Y1'!M14 -> 106850 | C5: =B5+'5-Year Operating Stmt'!C14 -> 288007 | D5: =B5+'5-Year Operating Stmt'!C14+'5-Year Operating Stmt'!D14 -> 581113 | E5: =B5+'5-Year Operating Stmt'!C14+'5-Year Operating Stmt'!D14+'5-Year Operating Stmt'!E14 -> 965294 | F5: =B5+'5-Year Operating Stmt'!C14+'5-Year Operating Stmt'!D14+'5-Year Operating Stmt'!E14+'5-Year Operating Stmt'!F14 -> 1417502
A6: Accounts Receivable | B6: 0 | C6: 0 | D6: 0 | E6: 0 | F6: 0
A7: Fixed Assets | B7: 2000 | C7: 2000 | D7: 2000 | E7: 2000 | F7: 2000
A8: Other Assets | B8: 0 | C8: 0 | D8: 0 | E8: 0 | F8: 0
A9: Total Assets | B9: =SUM(B5:B8) -> 108850 | C9: =SUM(C5:C8) -> 290007 | D9: =SUM(D5:D8) -> 583113 | E9: =SUM(E5:E8) -> 967294 | F9: =SUM(F5:F8) -> 1419502
A11: LIABILITIES
A12: Accounts Payable | B12: 0 | C12: 0 | D12: 0 | E12: 0 | F12: 0
A13: Long-Term Debt | B13: 0 | C13: 0 | D13: 0 | E13: 0 | F13: 0
A14: Total Liabilities | B14: =SUM(B12:B13) -> 0 | C14: =SUM(C12:C13) -> 0 | D14: =SUM(D12:D13) -> 0 | E14: =SUM(E12:E13) -> 0 | F14: =SUM(F12:F13) -> 0
A16: EQUITY
A17: Equity | B17: =B9-B14 -> 108850 | C17: =C9-C14 -> 290007 | D17: =D9-D14 -> 583113 | E17: =E9-E14 -> 967294 | F17: =F9-F14 -> 1419502
A19: Balance Check (should = 0) | B19: =B9-B14-B17 -> 0 | C19: =C9-C14-C17 -> 0 | D19: =D9-D14-D17 -> 0 | E19: =E9-E14-E17 -> 0 | F19: =F9-F14-F17 -> 0

Sheet DSCR & Covenants
A1: DSCR & Covenant Checks
B3: 2026-27 | C3: 2027-28 | D3: 2028-29 | E3: 2029-30 | F3: 2030-31
A4: CASH FLOW & DEBT
A5: Revenue | B5: 167500 | C5: 302202 | D5: 423299 | E5: 522542 | F5: 597645
A6: Personnel | B6: 64516 | C6: 79742 | D6: 82134 | E6: 84598 | F6: 87136
A7: Operating Expenses | B7: 29625 | C7: 41303 | D7: 48059 | E7: 53762 | F7: 58301
A8: CFADS (Rev - Pers - OpEx) | B8: =B5-B6-B7 -> 73359 | C8: =C5-C6-C7 -> 181157 | D8: =D5-D6-D7 -> 293106 | E8: =E5-E6-E7 -> 384182 | F8: =F5-F6-F7 -> 452207
A9: Debt Service | B9: 0 | C9: 0 | D9: 0 | E9: 0 | F9: 0
A10: DSCR | B10: N/A | C10: N/A | D10: N/A | E10: N/A | F10: N/A
A12: LIQUIDITY METRICS
A13: Ending Cash | B13: 106850 | C13: 288007 | D13: 581113 | E13: 965294 | F13: 1417502
A14: Days Cash on Hand | B14: =IF((B6+B7+B9)=0,0,(B13/(B6+B7+B9))*365) -> 414 | C14: =IF((C6+C7+C9)=0,0,(C13/(C6+C7+C9))*365) -> 868 | D14: =IF((D6+D7+D9)=0,0,(D13/(D6+D7+D9))*365) -> 1629 | E14: =IF((E6+E7+E9)=0,0,(E13/(E6+E7+E9))*365) -> 2546 | F14: =IF((F6+F7+F9)=0,0,(F13/(F6+F7+F9))*365) -> 3557
A15: Months of Runway | B15: =IF((B6+B7+B9)=0,0,B13/((B6+B7+B9)/12)) -> 13.6 | C15: =IF((C6+C7+C9)=0,0,C13/((C6+C7+C9)/12)) -> 28.6 | D15: =IF((D6+D7+D9)=0,0,D13/((D6+D7+D9)/12)) -> 53.6 | E15: =IF((E6+E7+E9)=0,0,E13/((E6+E7+E9)/12)) -> 83.7 | F15: =IF((F6+F7+F9)=0,0,F13/((F6+F7+F9)/12)) -> 117
A16: Capacity Utilization | B16: 0.375 | C16: 0.55 | D16: 0.75 | E16: 0.9 | F16: 1
A18: BREAK-EVEN ANALYSIS
A19: Revenue per Student | B19: 11167 | C19: 13736 | D19: 14110 | E19: 14515 | F19: 14941
A20: Fixed Costs (Pers + Debt) | B20: 64516 | C20: 79742 | D20: 82134 | E20: 84598 | F20: 87136
A21: Variable Cost per Student (OpEx) | B21: 1975 | C21: 1877 | D21: 1602 | E21: 1493 | F21: 1458
A22: Break-Even Enrollment | B22: 8 | C22: 7 | D22: 7 | E22: 7 | F22: 7
A24: COVENANT CHECKS
A25: DSCR ≥ 1x | B25: N/A | C25: N/A | D25: N/A | E25: N/A | F25: N/A
A26: Positive Net Income | B26: PASS | C26: PASS | D26: PASS | E26: PASS | F26: PASS
A27: Capacity ≥ 70% | B27: FAIL | C27: FAIL | D27: PASS | E27: PASS | F27: PASS
A28: Cash Reserve ≥ 2 months | B28: PASS | C28: PASS | D28: PASS | E28: PASS | F28: PASS
A29: Days Cash ≥ 30 | B29: PASS | C29: PASS | D29: PASS | E29: PASS | F29: PASS

Sheet Sources & Uses
A1: Sources & Uses
A3: SOURCES | B3: Amount | D3: USES | E3: Amount
A4: Owner Savings | B4: 12000 | D4: Startup Costs | E4: 12000
A6: Total Sources | B6: 12000 | D6: Total Uses | E6: 12000
A7: Sources - Uses (should = 0) | B7: 0

Sheet Scenarios
A1: Scenario Analysis
A3: BASE CASE
A4: Enrollment: +0% | Revenue: +0% | Staffing: +0% | Facility: +0% | Expenses: +0%
B5: 2026-27 | C5: 2027-28 | D5: 2028-29 | E5: 2029-30 | F5: 2030-31
A6: Revenue | B6: 167500 | C6: 302202 | D6: 423299 | E6: 522542 | F6: 597645
A7: Total Expenses | B7: 94141 | C7: 121045 | D7: 130193 | E7: 138361 | F7: 145438
A8: Net Income | B8: 73359 | C8: 181157 | D8: 293106 | E8: 384182 | F8: 452207
A9: Net Margin % | B9: 0.43796269 | C9: 0.59945637 | D9: 0.69243233 | E9: 0.73521644 | F9: 0.75664878
A10: DSCR | B10: N/A | C10: N/A | D10: N/A | E10: N/A | F10: N/A
A11: Break-Even Enrollment | B11: 8 | C11: 7 | D11: 7 | E11: 7 | F11: 7
A13: LOW ESA UTILIZATION
A14: Enrollment: -25% | Revenue: +0% | Staffing: +0% | Facility: +0% | Expenses: +0%
B15: 2026-27 | C15: 2027-28 | D15: 2028-29 | E15: 2029-30 | F15: 2030-31
A16: Revenue | B16: 125625 | C16: 226652 | D16: 317474 | E16: 391907 | F16: 448234
A17: Total Expenses | B17: 94141 | C17: 121045 | D17: 130193 | E17: 138361 | F17: 145438
A18: Net Income | B18: 31484 | C18: 105606 | D18: 187281 | E18: 253546 | F18: 302796
A19: Net Margin % | B19: 0.25061692 | C19: 0.46594183 | D19: 0.58990977 | E19: 0.64695525 | F19: 0.6755317
A20: DSCR | B20: N/A | C20: N/A | D20: N/A | E20: N/A | F20: N/A
A21: Break-Even Enrollment | B21: 8 | C21: 8 | D21: 8 | E21: 7 | F21: 7

Sheet Underwriting Snapshot
A1: Underwriting Snapshot - Loan Committee Summary
A3: SCHOOL PROFILE
A4: School Name | B4: Liberty Learning Co-Op
A5: Type | B5: Homeschool Co-Op
A6: Entity | B6: LLC (Single Member)
A7: Stage | B7: Startup / Pre-Opening
A8: State | B8: AZ
A9: Funding | B9: Hybrid / Mixed
A11: 5-YEAR FINANCIAL TREND
D12: 2026-27 | E12: 2027-28 | F12: 2028-29 | G12: 2029-30 | H12: 2030-31
A13: Revenue | D13: 167500 | E13: 302202 | F13: 423299 | G13: 522542 | H13: 597645
A14: Total Expenses | D14: 94141 | E14: 121045 | F14: 130193 | G14: 138361 | H14: 145438
A15: Net Income | D15: 73359 | E15: 181157 | F15: 293106 | G15: 384182 | H15: 452207
A16: Cash Position | D16: 106850 | E16: 288007 | F16: 581113 | G16: 965294 | H16: 1417502
A17: Outstanding Debt | D17: 0 | E17: 0 | F17: 0 | G17: 0 | H17: 0
A19: KEY RATIOS
D20: 2026-27 | E20: 2027-28 | F20: 2028-29 | G20: 2029-30 | H20: 2030-31
A21: Net Margin | D21: 0.43796269 | E21: 0.59945637 | F21: 0.69243233 | G21: 0.73521644 | H21: 0.75664878
A22: DSCR | D22: N/A | E22: N/A | F22: N/A | G22: N/A | H22: N/A
A23: Capacity Utilization | D23: 0.375 | E23: 0.55 | F23: 0.75 | G23: 0.9 | H23: 1
A24: Enrollment | D24: 15 | E24: 22 | F24: 30 | G24: 36 | H24: 40
A26: Prepared by SchoolStack Budget - budget.schoolstack.ai

Sheet Financial Health
B2: Liberty Learning Co-Op — Financial Health Dashboard
B3: Generated March 27, 2026
B4: ● Green = healthy | D4: ◐ Yellow = monitor | F4: ○ Red = action needed
B6: Metric | C6: Year 1 | D6: Year 2 | E6: Year 3 | F6: Year 4 | G6: Year 5 | H6: Benchmark
B7: Enrollment | C7: 15 | D7: 22 | E7: 30 | F7: 36 | G7: 40
B8: Revenue | C8: 167500 | D8: 302202 | E8: 423299.1 | F8: 522542.05 | G8: 597645.18
B9: Personnel | C9: 64516.25 | D9: 79742.085 | E9: 82134.348 | F9: 84598.378 | G9: 87136.329
B10: Operating Expenses | C10: 29625 | D10: 41303 | E10: 48058.77 | F10: 53762.168 | G10: 58301.356
B11: Debt Service | C11: 0 | D11: 0 | E11: 0 | F11: 0 | G11: 0
B12: Net Income | C12: 73358.75 | D12: 181156.91 | E12: 293105.98 | F12: 384181.51 | G12: 452207.49
B13: Ending Cash | C13: 106850 | D13: 288006.91 | E13: 581112.9 | F13: 965294.4 | G13: 1417501.9
B14: Net Margin | C14: 0.43796269 | D14: 0.59945637 | E14: 0.69243233 | F14: 0.73521644 | G14: 0.75664878
B15: Revenue per Student | C15: 11166.667 | D15: 13736.455 | E15: 14109.97 | F15: 14515.057 | G15: 14941.129 | H15: ≥ $10,000
B16: Payroll % | C16: 0.38517164 | D16: 0.26387014 | E16: 0.19403383 | F16: 0.16189774 | G16: 0.14579944 | H16: ≤ 55%
B17: Facility % | C17: 0.15402985 | D17: 0.08793456 | E17: 0.064661654 | F17: 0.053952321 | G17: 0.048587571 | H17: ≤ 15%
B18: Operating Margin | C18: 0.43796269 | D18: 0.59945637 | E18: 0.69243233 | F18: 0.73521644 | G18: 0.75664878 | H18: ≥ 10%
B19: Revenue Sources | C19: 3 | D19: 3 | E19: 3 | F19: 3 | G19: 3 | H19: ≥ 3 sources
B20: DSCR | C20: N/A | D20: N/A | E20: N/A | F20: N/A | G20: N/A | H20: N/A
B21: Break-even Year | C21: =IF('5-Year Operating Stmt'!B16>=0,"✓ Break-even","") -> ✓ Break-even | D21: =IF(AND('5-Year Operating Stmt'!C16>=0,'5-Year Operating Stmt'!B16<0),"✓ Break-even","") -> 0 | E21: =IF(AND('5-Year Operating Stmt'!D16>=0,'5-Year Operating Stmt'!C16<0),"✓ Break-even","") -> 0 | F21: =IF(AND('5-Year Operating Stmt'!E16>=0,'5-Year Operating Stmt'!D16<0),"✓ Break-even","") -> 0 | G21: =IF(AND('5-Year Operating Stmt'!F16>=0,'5-Year Operating Stmt'!E16<0),"✓ Break-even","") -> 0 | H21: Year 1
B22: Cash Runway (Months) | C22: 14 | D22: 29 | E22: 54 | F22: 60+ | G22: 60+ | H22: ≥ 24 months
B24: FINANCIAL HEALTH SIGNALS | C24: Status | D24: Assessment | F24: Watch Item
B25: Viability | C25: ● Healthy | D25: The model reaches profit early and sustains strong margins through Year 5. | F25: Monitor enrollment actuals vs. projections in Year 1.
B26: Liquidity | C26: ● Healthy | D26: Cash stays positive throughout the projection and reserves exceed 3 months of expenses. | F26: Maintain reserves as a buffer against seasonal revenue dips.
B27: Staffing Burden | C27: ● Healthy | D27: Staffing at 15% of revenue leaves room for facilities, programs, and reserves. | F27: As you add staff, ensure staffing stays below 60% of revenue.
B28: Facility Burden | C28: ● Healthy | D28: Facility costs at 5% of revenue are well-managed and leave budget for programs. | F28: Watch for rent escalation clauses that could push this higher over time.
B29: Revenue Concentration | C29: ● Healthy | D29: Revenue is anchored to enrollment-driven income — the strongest foundation for a school model. A focused revenue stream is a strength when backed by dependable demand. | F29: Continue to pressure-test enrollment assumptions: recruitment pipeline, waitlist depth, retention rates, and collection reliability.
B30: Reserve Strength | C30: ● Healthy | D30: 117.0 months of reserves by Year 5 — a strong buffer for unexpected costs. | F30: Continue growing reserves toward 6 months for best-in-class financial health.
B32: Summary | C32: 6 Healthy | 0 Watch | 0 Needs Attention
B34: Built by SchoolStack Budget • budget.schoolstack.ai
