Workbook

Sheet Cover
B3: SchoolStack Budget
B5: 5-Year Financial Model & Underwriting Workbook
B8: School Name | C8: Heritage Academy
B9: School Type | C9: Private School
B10: Entity Type | C10: 501(c)(3) Nonprofit
B11: State | C11: FL
B12: Fiscal Year Start | C12: Month 7
B13: Model Date | C13: March 17, 2026
B14: Stage | C14: Operating
B15: Funding Profile | C15: Hybrid / Mixed
B18: Table of Contents
B19: 1. | C19: Cover
B20: 2. | C20: Instructions
B21: 3. | C21: Assumptions
B22: 4. | C22: Program Profile
B23: 5. | C23: Enrollment Drivers
B24: 6. | C24: Tuition & Funding
B25: 7. | C25: Staffing Drivers
B26: 8. | C26: OpEx Drivers
B27: 9. | C27: Capital Stack
B28: 10. | C28: Enrollment Tuition Fcst
B29: 11. | C29: Staffing Costs Fcst
B30: 12. | C30: Budget Detail
... B39: 21. | C39: Underwriting Snapshot
B42: CONFIDENTIAL - Prepared by SchoolStack Budget (budget.schoolstack.ai)

Sheet Instructions
B2: How to Use This Workbook
B4: Color Legend
B5: Yellow cells are editable inputs - change these to update your model.
B6: Gray cells contain formulas - do not edit.
B7: Green cells are key outputs and summary metrics.
B9: Navigation
B10: The Assumptions tab is the central control panel - all other tabs reference it.
B12: Structure
B13: Tabs 5-9: Drivers & inputs
B14: Tabs 10-13: Forecasts & budgets
B15: Tabs 14-17: Financial statements
B16: Tabs 18-21: Analysis & underwriting
... B25: user-provided assumptions and should be independently verified.

Sheet Assumptions
A1: Heritage Academy - Assumptions
A2: Yellow cells are editable inputs. All other cells are formulas.
A4: SCHOOL PROFILE
A5: School Name | B5: Heritage Academy
A6: School Type | B6: Private School
A7: Entity Type | B7: 501(c)(3) Nonprofit
A8: State | B8: FL
A9: EIN | B9: 59-9876543
A10: Stage | B10: Operating
A11: Funding Profile | B11: Hybrid / Mixed
A12: Fiscal Year Start Month | B12: 7
A13: Max Capacity | B13: 200
A15: ENROLLMENT
B16: 2023-24 | C16: 2024-25 | D16: 2025-26 | E16: 2026-27 | F16: 2027-28
A17: Total Students | B17: 100 | C17: 130 | D17: 160 | E17: 185 | F17: 200
A19: REVENUE DRIVERS
A20: Line Item | B20: Category | C20: Driver | D20: Amount | E20: Escalation %
A21: Tuition | B21: Tuition & Fees | C21: Per Student | D21: 10500 | E21: 0
A22: Registration Fee | B22: Tuition & Fees | C22: Per Student | D22: 350 | E22: 0
A23: Scholarship Discount | B23: Tuition Offsets | C23: Per Student | D23: -1050 | E23: 0
A24: FL FTC Scholarship | B24: School Choice | C24: Per Student | D24: 8700 | E24: 0
A25: Foundation Grant | B25: Philanthropy | C25: Annual Fixed | D25: 50000 | E25: 0
A26: Annual Fund | B26: Philanthropy | C26: Annual Fixed | D26: 25000 | E26: 0
A27: After-School Programs | B27: Other Revenue | C27: Per Student | D27: 500 | E27: 0
A29: STAFFING
A30: Role | B30: Category | C30: Type | D30: FTE | E30: Rate | F30: Benefits % | G30: Tax %
A31: Head of School | B31: School Leadership | C31: full_time | D31: 1 | E31: 95000 | F31: 0.25 | G31: 0.0765
A32: Assistant Principal | B32: School Leadership | C32: full_time | D32: 1 | E32: 75000 | F32: 0.25 | G32: 0.0765
A33: Teachers | B33: Instructional | C33: full_time | D33: 6 | E33: 48000 | F33: 0.25 | G33: 0.0765
A34: Paraprofessionals | B34: Instructional | C34: full_time | D34: 3 | E34: 32000 | F34: 0.2 | G34: 0.0765
A35: Office Manager | B35: Administrative | C35: full_time | D35: 1 | E35: 42000 | F35: 0.25 | G35: 0.0765
A36: School Counselor | B36: Student Support | C36: full_time | D36: 1 | E36: 52000 | F36: 0.25 | G36: 0.0765
A38: OPERATING EXPENSES
A39: Line Item | B39: Category | C39: Driver | D39: Amount | E39: Escalation %
A40: Rent | B40: Occupancy / Facility | C40: Monthly | D40: 8500 | E40: 0.03
A41: Utilities | B41: Occupancy / Facility | C41: Monthly | D41: 1200 | E41: 0
A42: Insurance | B42: Occupancy / Facility | C42: Annual Fixed | D42: 12000 | E42: 0
A43: Maintenance | B43: Occupancy / Facility | C43: Annual Fixed | D43: 8000 | E43: 0
A44: Curriculum | B44: Instructional / Program | C44: Per Student | D44: 600 | E44: 0
A45: Technology | B45: Technology | C45: Per Student | D45: 400 | E45: 0
...

Sheet Program Profile
A1: Program Profile
A3: School Model | B3: private
A4: School Type | B4: Private School
A5: Entity Type | B5: 501(c)(3) Nonprofit
A6: Financial Label Convention | B6: Nonprofit (Change in Net Assets / Net Assets)
A7: Stage | B7: Operating
A8: Funding Mix | B8: Hybrid / Mixed
A9: Fiscal Year Start Month | B9: 7
A10: Year 1 Operating Months | B10: 12
A11: Proration Factor | B11: 100.0%
A12: Debt Included | B12: Yes
A13: Max Capacity | B13: 200
A14: Accredited | B14: No
... A16: Facility | B16: Leased

Sheet Enrollment Drivers
A1: Enrollment Drivers
B3: Prior Year | C3: Current Year | D3: 2023-24 | E3: 2024-25 | F3: 2025-26 | G3: 2026-27 | H3: 2027-28
A5: TOTAL ENROLLMENT
A6: Total Students | B6: 85 | C6: 0 | D6: 100 | E6: 130 | F6: 160 | G6: 185 | H6: 200
A7: Max Capacity | B7: 200
A8: Capacity Utilization | D8: 0.5 | E8: 0.65 | F8: 0.8 | G8: 0.925 | H8: 1
A10: Enrollment Growth Rate | D10: - | E10: 0.3 | F10: 0.23076923 | G10: 0.15625 | H10: 0.081081081

Sheet Tuition & Funding
A1: Tuition & Funding Drivers
B3: 2023-24 | C3: 2024-25 | D3: 2025-26 | E3: 2026-27 | F3: 2027-28
A4: REVENUE BY LINE ITEM
A5: Tuition (Tuition & Fees) | B5: 1050000 | C5: 1405950 | D5: 1782312 | E5: 2122622 | F5: 2363569
A6: Registration Fee (Tuition & Fees) | B6: 35000 | C6: 46865 | D6: 59410 | E6: 70754 | F6: 78786
A7: Scholarship Discount (Tuition Offsets) | B7: 105000 | C7: 140595 | D7: 178231 | E7: 212262 | F7: 236357
A8: FL FTC Scholarship (School Choice) | B8: 870000 | C8: 1164930 | D8: 1476773 | E8: 1758744 | F8: 1958385
A9: Foundation Grant (Philanthropy) | B9: 50000 | C9: 51500 | D9: 53045 | E9: 54636 | F9: 56275
A10: Annual Fund (Philanthropy) | B10: 25000 | C10: 25750 | D10: 26523 | E10: 27318 | F10: 28138
A11: After-School Programs (Other Revenue) | B11: 50000 | C11: 66950 | D11: 84872 | E11: 101077 | F11: 112551
A12: TOTAL REVENUE | B12: =SUM(B5:B11) -> 1975000 | C12: =SUM(C5:C11) -> 2621350 | D12: =SUM(D5:D11) -> 3304704 | E12: =SUM(E5:E11) -> 3922890 | F12: =SUM(F5:F11) -> 4361347

Sheet Staffing Drivers
A1: Staffing Drivers
A3: Role | B3: Category | C3: FTE | D3: Base Rate | E3: Benefits % | F3: Tax % | G3: Loaded Cost
A4: Head of School | B4: School Leadership | C4: 1 | D4: 95000 | E4: 0.25 | F4: 0.0765 | G4: 126018
A5: Assistant Principal | B5: School Leadership | C5: 1 | D5: 75000 | E5: 0.25 | F5: 0.0765 | G5: 99488
A6: Teachers | B6: Instructional | C6: 6 | D6: 48000 | E6: 0.25 | F6: 0.0765 | G6: 382032
A7: Paraprofessionals | B7: Instructional | C7: 3 | D7: 32000 | E7: 0.2 | F7: 0.0765 | G7: 122544
A8: Office Manager | B8: Administrative | C8: 1 | D8: 42000 | E8: 0.25 | F8: 0.0765 | G8: 55713
A9: School Counselor | B9: Student Support | C9: 1 | D9: 52000 | E9: 0.25 | F9: 0.0765 | G9: 68978
A11: 5-YEAR TOTAL PERSONNEL COST
B12: 2023-24 | C12: 2024-25 | D12: 2025-26 | E12: 2026-27 | F12: 2027-28
A13: Total Personnel | B13: 854772 | C13: 880415 | D13: 906828 | E13: 934032 | F13: 962053
A14: Personnel as % of Revenue | B14: 0.43279595 | C14: 0.33586326 | D14: 0.27440514 | E14: 0.23809805 | F14: 0.22058632
A15: Students per FTE | B15: 7.7 | C15: 10 | D15: 12.3 | E15: 14.2 | F15: 15.4

Sheet OpEx Drivers
A1: Operating Expense Drivers
B3: 2023-24 | C3: 2024-25 | D3: 2025-26 | E3: 2026-27 | F3: 2027-28
A4: Instructional / Program
A5: Curriculum | B5: 60000 | C5: 80340 | D5: 101846 | E5: 121293 | F5: 135061
A6: Total Instructional / Program | B6: =SUM(B5:B5) -> 60000 | C6: =SUM(C5:C5) -> 80340 | D6: =SUM(D5:D5) -> 101846 | E6: =SUM(E5:E5) -> 121293 | F6: =SUM(F5:F5) -> 135061
A7: Technology
A8: Technology | B8: 40000 | C8: 53560 | D8: 67898 | E8: 80862 | F8: 90041
A9: Total Technology | B9: =SUM(B8:B8) -> 40000 | C9: =SUM(C8:C8) -> 53560 | D9: =SUM(D8:D8) -> 67898 | E9: =SUM(E8:E8) -> 80862 | F9: =SUM(F8:F8) -> 90041
A10: Occupancy / Facility
A11: Rent | B11: 102000 | C11: 105060 | D11: 108212 | E11: 111458 | F11: 114802
A12: Utilities | B12: 14400 | C12: 14832 | D12: 15277 | E12: 15735 | F12: 16207
A13: Insurance | B13: 12000 | C13: 12360 | D13: 12731 | E13: 13113 | F13: 13506
A14: Maintenance | B14: 8000 | C14: 8240 | D14: 8487 | E14: 8742 | F14: 9004
A15: Total Occupancy / Facility | B15: =SUM(B11:B14) -> 136400 | C15: =SUM(C11:C14) -> 140492 | D15: =SUM(D11:D14) -> 144707 | E15: =SUM(E11:E14) -> 149048 | F15: =SUM(F11:F14) -> 153519
A16: Administrative / General
A17: Marketing | B17: 15000 | C17: 15450 | D17: 15914 | E17: 16391 | F17: 16883
A18: Professional Development | B18: 8000 | C18: 8240 | D18: 8487 | E18: 8742 | F18: 9004
A19: Accounting & Legal | B19: 12000 | C19: 12360 | D19: 12731 | E19: 13113 | F19: 13506
A20: Total Administrative / General | B20: =SUM(B17:B19) -> 35000 | C20: =SUM(C17:C19) -> 36050 | D20: =SUM(D17:D19) -> 37132 | E20: =SUM(E17:E19) -> 38245 | F20: =SUM(F17:F19) -> 39393
A22: TOTAL OPERATING EXPENSES | B22: =B6+B9+B15+B20 -> 271400 | C22: =C6+C9+C15+C20 -> 310442 | D22: =D6+D9+D15+D20 -> 351582 | E22: =E6+E9+E15+E20 -> 389448 | F22: =F6+F9+F15+F20 -> 418014

Sheet Capital Stack
A1: Capital Stack & Loan Terms
A3: Instrument | B3: Type | C3: Principal | D3: Rate | E3: Term (Yrs) | F3: Annual Payment
A4: Facility Buildout Loan | B4: Loan | C4: 250000 | D4: 0.065 | E4: 10 | F4: 34064
A5: Furniture & Equipment | B5: Capital Expense | C5: 25000 | D5: 0 | E5: 0 | F5: 25000
A7: Total Annual Debt Service | F7: 34064
A8: Total Loan Principal | F8: 250000

Sheet Enrollment Tuition Fcst
A1: Enrollment & Tuition Forecast
B3: 2023-24 | C3: 2024-25 | D3: 2025-26 | E3: 2026-27 | F3: 2027-28
A4: Total Students | B4: 100 | C4: 130 | D4: 160 | E4: 185 | F4: 200
A6: REVENUE FORECAST
A7: Tuition | B7: 1050000 | C7: 1405950 | D7: 1782312 | E7: 2122622 | F7: 2363569
A8: Registration Fee | B8: 35000 | C8: 46865 | D8: 59410 | E8: 70754 | F8: 78786
A9: Scholarship Discount | B9: 105000 | C9: 140595 | D9: 178231 | E9: 212262 | F9: 236357
A10: FL FTC Scholarship | B10: 870000 | C10: 1164930 | D10: 1476773 | E10: 1758744 | F10: 1958385
A11: Foundation Grant | B11: 50000 | C11: 51500 | D11: 53045 | E11: 54636 | F11: 56275
A12: Annual Fund | B12: 25000 | C12: 25750 | D12: 26523 | E12: 27318 | F12: 28138
A13: After-School Programs | B13: 50000 | C13: 66950 | D13: 84872 | E13: 101077 | F13: 112551
A14: TOTAL REVENUE | B14: =SUM(B7:B13) -> 1975000 | C14: =SUM(C7:C13) -> 2621350 | D14: =SUM(D7:D13) -> 3304704 | E14: =SUM(E7:E13) -> 3922890 | F14: =SUM(F7:F13) -> 4361347
A16: Revenue per Student | B16: 19750 | C16: 20164 | D16: 20654 | E16: 21205 | F16: 21807

Sheet Staffing Costs Fcst
A1: Staffing Costs Forecast
B3: 2023-24 | C3: 2024-25 | D3: 2025-26 | E3: 2026-27 | F3: 2027-28
A4: Instructional
A5: Teachers | B5: 382032 | C5: 393493 | D5: 405298 | E5: 417457 | F5: 429980
A6: Paraprofessionals | B6: 122544 | C6: 126220 | D6: 130007 | E6: 133907 | F6: 137924
A7: Total Instructional | B7: =SUM(B5:B6) -> 504576 | C7: =SUM(C5:C6) -> 519713 | D7: =SUM(D5:D6) -> 535305 | E7: =SUM(E5:E6) -> 551364 | F7: =SUM(F5:F6) -> 567905
A8: School Leadership
A9: Head of School | B9: 126018 | C9: 129798 | D9: 133692 | E9: 137703 | F9: 141834
A10: Assistant Principal | B10: 99488 | C10: 102472 | D10: 105546 | E10: 108713 | F10: 111974
A11: Total School Leadership | B11: =SUM(B9:B10) -> 225505 | C11: =SUM(C9:C10) -> 232270 | D11: =SUM(D9:D10) -> 239238 | E11: =SUM(E9:E10) -> 246415 | F11: =SUM(F9:F10) -> 253808
A12: Student Support
A13: School Counselor | B13: 68978 | C13: 71047 | D13: 73179 | E13: 75374 | F13: 77635
A14: Total Student Support | B14: =SUM(B13:B13) -> 68978 | C14: =SUM(C13:C13) -> 71047 | D14: =SUM(D13:D13) -> 73179 | E14: =SUM(E13:E13) -> 75374 | F14: =SUM(F13:F13) -> 77635
A15: Administrative
A16: Office Manager | B16: 55713 | C16: 57384 | D16: 59106 | E16: 60879 | F16: 62705
A17: Total Administrative | B17: =SUM(B16:B16) -> 55713 | C17: =SUM(C16:C16) -> 57384 | D17: =SUM(D16:D16) -> 59106 | E17: =SUM(E16:E16) -> 60879 | F17: =SUM(F16:F16) -> 62705
A19: TOTAL PERSONNEL | B19: =B7+B11+B14+B17 -> 854772 | C19: =C7+C11+C14+C17 -> 880415 | D19: =D7+D11+D14+D17 -> 906828 | E19: =E7+E11+E14+E17 -> 934032 | F19: =F7+F11+F14+F17 -> 962053

Sheet Budget Detail
A1: Heritage Academy - Budget Detail
B3: 2023-24 | C3: 2024-25 | D3: 2025-26 | E3: 2026-27 | F3: 2027-28
A4: REVENUE
A5: Tuition | B5: 1050000 | C5: 1405950 | D5: 1782312 | E5: 2122622 | F5: 2363569
A6: Registration Fee | B6: 35000 | C6: 46865 | D6: 59410 | E6: 70754 | F6: 78786
A7: Scholarship Discount | B7: 105000 | C7: 140595 | D7: 178231 | E7: 212262 | F7: 236357
A8: FL FTC Scholarship | B8: 870000 | C8: 1164930 | D8: 1476773 | E8: 1758744 | F8: 1958385
A9: Foundation Grant | B9: 50000 | C9: 51500 | D9: 53045 | E9: 54636 | F9: 56275
A10: Annual Fund | B10: 25000 | C10: 25750 | D10: 26523 | E10: 27318 | F10: 28138
A11: After-School Programs | B11: 50000 | C11: 66950 | D11: 84872 | E11: 101077 | F11: 112551
A12: Total Revenue | B12: =SUM(B5:B11) -> 1975000 | C12: =SUM(C5:C11) -> 2621350 | D12: =SUM(D5:D11) -> 3304704 | E12: =SUM(E5:E11) -> 3922890 | F12: =SUM(F5:F11) -> 4361347
A14: PERSONNEL
A15: Head of School | B15: 126018 | C15: 129798 | D15: 133692 | E15: 137703 | F15: 141834
A16: Assistant Principal | B16: 99488 | C16: 102472 | D16: 105546 | E16: 108713 | F16: 111974
A17: Teachers | B17: 382032 | C17: 393493 | D17: 405298 | E17: 417457 | F17: 429980
A18: Paraprofessionals | B18: 122544 | C18: 126220 | D18: 130007 | E18: 133907 | F18: 137924
A19: Office Manager | B19: 55713 | C19: 57384 | D19: 59106 | E19: 60879 | F19: 62705
A20: School Counselor | B20: 68978 | C20: 71047 | D20: 73179 | E20: 75374 | F20: 77635
A21: Total Personnel | B21: =SUM(B15:B20) -> 854772 | C21: =SUM(C15:C20) -> 880415 | D21: =SUM(D15:D20) -> 906828 | E21: =SUM(E15:E20) -> 934032 | F21: =SUM(F15:F20) -> 962053
A23: OPERATING EXPENSES
A24: Instructional / Program
A25: Curriculum | B25: 60000 | C25: 80340 | D25: 101846 | E25: 121293 | F25: 135061
A26: Technology
A27: Technology | B27: 40000 | C27: 53560 | D27: 67898 | E27: 80862 | F27: 90041
A28: Occupancy / Facility
A29: Rent | B29: 102000 | C29: 105060 | D29: 108212 | E29: 111458 | F29: 114802
A30: Utilities | B30: 14400 | C30: 14832 | D30: 15277 | E30: 15735 | F30: 16207
A31: Insurance | B31: 12000 | C31: 12360 | D31: 12731 | E31: 13113 | F31: 13506
A32: Maintenance | B32: 8000 | C32: 8240 | D32: 8487 | E32: 8742 | F32: 9004
A33: Total Occupancy / Facility | B33: =SUM(B29:B32) -> 136400 | C33: =SUM(C29:C32) -> 140492 | D33: =SUM(D29:D32) -> 144707 | E33: =SUM(E29:E32) -> 149048 | F33: =SUM(F29:F32) -> 153519
A34: Administrative / General
A35: Marketing | B35: 15000 | C35: 15450 | D35: 15914 | E35: 16391 | F35: 16883
A36: Professional Development | B36: 8000 | C36: 8240 | D36: 8487 | E36: 8742 | F36: 9004
A37: Accounting & Legal | B37: 12000 | C37: 12360 | D37: 12731 | E37: 13113 | F37: 13506
A38: Total Administrative / General | B38: =SUM(B35:B37) -> 35000 | C38: =SUM(C35:C37) -> 36050 | D38: =SUM(D35:D37) -> 37132 | E38: =SUM(E35:E37) -> 38245 | F38: =SUM(F35:F37) -> 39393
A39: Total Operating Expenses | B39: =B25+B27+B33+B38 -> 271400 | C39: =C25+C27+C33+C38 -> 310442 | D39: =D25+D27+D33+D38 -> 351582 | E39: =E25+E27+E33+E38 -> 389448 | F39: =F25+F27+F33+F38 -> 418014
A41: CAPITAL & DEBT SERVICE
A42: Facility Buildout Loan | B42: 34064 | C42: 34064 | D42: 34064 | E42: 34064 | F42: 34064
A43: Furniture & Equipment | B43: 25000 | C43: 10000 | D43: 10000 | E43: 5000 | F43: 5000
A44: Total Capital & Debt | B44: =SUM(B42:B43) -> 59064 | C44: =SUM(C42:C43) -> 44064 | D44: =SUM(D42:D43) -> 44064 | E44: =SUM(E42:E43) -> 39064 | F44: =SUM(F42:F43) -> 39064

Sheet Budget Summary
A1: Heritage Academy - Budget Summary
B3: 2023-24 | C3: 2024-25 | D3: 2025-26 | E3: 2026-27 | F3: 2027-28
A4: Total Revenue | B4: ='Budget Detail'!B12 -> 1975000 | C4: ='Budget Detail'!C12 -> 2621350 | D4: ='Budget Detail'!D12 -> 3304704 | E4: ='Budget Detail'!E12 -> 3922890 | F4: ='Budget Detail'!F12 -> 4361347
A5: Total Personnel | B5: ='Budget Detail'!B21 -> 854772 | C5: ='Budget Detail'!C21 -> 880415 | D5: ='Budget Detail'!D21 -> 906828 | E5: ='Budget Detail'!E21 -> 934032 | F5: ='Budget Detail'!F21 -> 962053
A6: Total Operating Expenses | B6: ='Budget Detail'!B39 -> 271400 | C6: ='Budget Detail'!C39 -> 310442 | D6: ='Budget Detail'!D39 -> 351582 | E6: ='Budget Detail'!E39 -> 389448 | F6: ='Budget Detail'!F39 -> 418014
A7: Total Capital & Debt Service | B7: ='Budget Detail'!B44 -> 59064 | C7: ='Budget Detail'!C44 -> 44064 | D7: ='Budget Detail'!D44 -> 44064 | E7: ='Budget Detail'!E44 -> 39064 | F7: ='Budget Detail'!F44 -> 39064
A8: Total Expenses | B8: =SUM(B5:B7) -> 1185236 | C8: =SUM(C5:C7) -> 1234922 | D8: =SUM(D5:D7) -> 1302474 | E8: =SUM(E5:E7) -> 1362545 | F8: =SUM(F5:F7) -> 1419132
A10: KEY METRICS
A11: Change in Net Assets | B11: =B4-B8 -> 789764 | C11: =C4-C8 -> 1386428 | D11: =D4-D8 -> 2002229 | E11: =E4-E8 -> 2560345 | F11: =F4-F8 -> 2942215
A12: Net Margin % | B12: =IF(B4=0,0,B11/B4) -> 0.39988031 | C12: =IF(C4=0,0,C11/C4) -> 0.52889864 | D12: =IF(D4=0,0,D11/D4) -> 0.60587258 | E12: =IF(E4=0,0,E11/E4) -> 0.65266812 | F12: =IF(F4=0,0,F11/F4) -> 0.67461156
A13: Cumulative Change in Net Assets | B13: 789764 | C13: 2176192 | D13: 4178421 | E13: 6738766 | F13: 9680981
A14: Revenue per Student | B14: 19750 | C14: 20164 | D14: 20654 | E14: 21205 | F14: 21807
A15: Cost per Student | B15: 11852 | C15: 9499 | D15: 8140 | E15: 7365 | F15: 7096

Sheet Monthly Cash Flow Y1
A1: Heritage Academy - Year 1 Monthly Cash Flow
B2: July | C2: August | D2: September | E2: October | F2: November | G2: December | H2: January | I2: February | J2: March | K2: April | L2: May | M2: June | N2: Annual Total
A3: REVENUE
A4: Total Revenue | B4: 85833 | C4: 180333 | D4: 180333 | E4: 180333 | F4: 180333 | G4: 180333 | H4: 180333 | I4: 180333 | J4: 180333 | K4: 180333 | L4: 180333 | M4: 85833 | N4: 1974996
A6: EXPENSES
A7: Personnel | B7: 71231 | C7: 71231 | D7: 71231 | E7: 71231 | F7: 71231 | G7: 71231 | H7: 71231 | I7: 71231 | J7: 71231 | K7: 71231 | L7: 71231 | M7: 71231 | N7: 854772
A8: Operating Expenses | B8: 22617 | C8: 22617 | D8: 22617 | E8: 22617 | F8: 22617 | G8: 22617 | H8: 22617 | I8: 22617 | J8: 22617 | K8: 22617 | L8: 22617 | M8: 22617 | N8: 271400
A9: Debt Service | B9: 4922 | C9: 4922 | D9: 4922 | E9: 4922 | F9: 4922 | G9: 4922 | H9: 4922 | I9: 4922 | J9: 4922 | K9: 4922 | L9: 4922 | M9: 4922 | N9: 59064
A11: CASH FLOW
A12: Total Expenses | B12: 98770 | C12: 98770 | D12: 98770 | E12: 98770 | F12: 98770 | G12: 98770 | H12: 98770 | I12: 98770 | J12: 98770 | K12: 98770 | L12: 98770 | M12: 98770 | N12: 1185240
A13: Net Cash Flow | B13: -12937 | C13: 81563 | D13: 81563 | E13: 81563 | F13: 81563 | G13: 81563 | H13: 81563 | I13: 81563 | J13: 81563 | K13: 81563 | L13: 81563 | M13: -12937 | N13: 789756
A14: Cumulative Cash | B14: 62063 | C14: 143626 | D14: 225189 | E14: 306752 | F14: 388315 | G14: 469878 | H14: 551441 | I14: 633004 | J14: 714567 | K14: 796130 | L14: 877693 | M14: 864756 | N14: 864756
A16: CASH FLOW METRICS
A17: Starting Cash | B17: 75000
A18: Ending Cash (Month 12) | B18: 864756
A19: Minimum Cash Month | B19: 62063

Sheet 5-Year Operating Stmt
A1: Heritage Academy - 5-Year Operating Statement
B3: 2023-24 | C3: 2024-25 | D3: 2025-26 | E3: 2026-27 | F3: 2027-28
A4: REVENUE
A5: Total Revenue | B5: 1975000 | C5: 2621350 | D5: 3304704 | E5: 3922890 | F5: 4361347
A7: EXPENSES
A8: Personnel | B8: 854772 | C8: 880415 | D8: 906828 | E8: 934032 | F8: 962053
A9: Operating Expenses | B9: 271400 | C9: 310442 | D9: 351582 | E9: 389448 | F9: 418014
A10: Capital & Debt Service | B10: 59064 | C10: 44064 | D10: 44064 | E10: 39064 | F10: 39064
A11: Total Expenses | B11: =SUM(B8:B10) -> 1185236 | C11: =SUM(C8:C10) -> 1234922 | D11: =SUM(D8:D10) -> 1302474 | E11: =SUM(E8:E10) -> 1362545 | F11: =SUM(F8:F10) -> 1419132
A13: BOTTOM LINE
A14: Change in Net Assets | B14: =B5-B11 -> 789764 | C14: =C5-C11 -> 1386428 | D14: =D5-D11 -> 2002229 | E14: =E5-E11 -> 2560345 | F14: =F5-F11 -> 2942215
A15: Net Margin % | B15: =IF(B5=0,0,B14/B5) -> 0.39988031 | C15: =IF(C5=0,0,C14/C5) -> 0.52889864 | D15: =IF(D5=0,0,D14/D5) -> 0.60587258 | E15: =IF(E5=0,0,E14/E5) -> 0.65266812 | F15: =IF(F5=0,0,F14/F5) -> 0.67461156

Sheet Debt Schedule
A1: Debt Schedule
B3: 2023-24 | C3: 2024-25 | D3: 2025-26 | E3: 2026-27 | F3: 2027-28
A4: Facility Buildout Loan
A5: Beginning Balance | B5: 250000 | C5: 231645 | D5: 212061 | E5: 191165 | F5: 168870
A6: Interest | B6: 15710 | C6: 14480 | D6: 13169 | E6: 11769 | F6: 10276
A7: Principal Payment | B7: 18355 | C7: 19584 | D7: 20896 | E7: 22295 | F7: 23788
A8: Total Payment | B8: 34064 | C8: 34064 | D8: 34064 | E8: 34064 | F8: 34064
A9: Ending Balance | B9: 231645 | C9: 212061 | D9: 191165 | E9: 168870 | F9: 145082

Sheet Balance Sheet
A1: Heritage Academy - Balance Sheet
B3: 2023-24 | C3: 2024-25 | D3: 2025-26 | E3: 2026-27 | F3: 2027-28
A4: ASSETS
A5: Cash & Equivalents | B5: 864756 | C5: 2251184 | D5: 4253414 | E5: 6813759 | F5: 9755974
A6: Accounts Receivable | B6: 12000 | C6: 12000 | D6: 12000 | E6: 12000 | F6: 12000
A7: Fixed Assets | B7: 180000 | C7: 180000 | D7: 180000 | E7: 180000 | F7: 180000
A8: Other Assets | B8: 5000 | C8: 5000 | D8: 5000 | E8: 5000 | F8: 5000
A9: Total Assets | B9: 1061756 | C9: 2448184 | D9: 4450414 | E9: 7010759 | F9: 9952974
A11: LIABILITIES
A12: Accounts Payable | B12: 8000 | C12: 8000 | D12: 8000 | E12: 8000 | F12: 8000
A13: Long-Term Debt | B13: 231645 | C13: 212061 | D13: 191165 | E13: 168870 | F13: 145082
A14: Total Liabilities | B14: 239645 | C14: 220061 | D14: 199165 | E14: 176870 | F14: 153082
A16: NET ASSETS
A17: Net Assets | B17: 822111 | C17: 2228123 | D17: 4251248 | E17: 6833888 | F17: 9799892
A19: Balance Check (should = 0) | B19: 0 | C19: 0 | D19: 1 | E19: 1 | F19: 0

Sheet DSCR & Covenants
A1: DSCR & Covenant Checks
B3: 2023-24 | C3: 2024-25 | D3: 2025-26 | E3: 2026-27 | F3: 2027-28
A4: CASH FLOW & DEBT
A5: Revenue | B5: 1975000 | C5: 2621350 | D5: 3304704 | E5: 3922890 | F5: 4361347
A6: Personnel | B6: 854772 | C6: 880415 | D6: 906828 | E6: 934032 | F6: 962053
A7: Operating Expenses | B7: 271400 | C7: 310442 | D7: 351582 | E7: 389448 | F7: 418014
A8: CFADS (Rev - Pers - OpEx) | B8: =B5-B6-B7 -> 848828 | C8: =C5-C6-C7 -> 1430493 | D8: =D5-D6-D7 -> 2046294 | E8: =E5-E6-E7 -> 2599410 | F8: =F5-F6-F7 -> 2981279
A9: Debt Service | B9: 34064 | C9: 34064 | D9: 34064 | E9: 34064 | F9: 34064
A10: DSCR | B10: =IF(B9=0,"N/A",B8/B9) -> 24.92 | C10: =IF(C9=0,"N/A",C8/C9) -> 41.99 | D10: =IF(D9=0,"N/A",D8/D9) -> 60.07 | E10: =IF(E9=0,"N/A",E8/E9) -> 76.31 | F10: =IF(F9=0,"N/A",F8/F9) -> 87.52
A12: LIQUIDITY METRICS
A13: Ending Cash | B13: 864756 | C13: 2251184 | D13: 4253414 | E13: 6813759 | F13: 9755974
A14: Days Cash on Hand | B14: =IF((B6+B7+B9)=0,0,(B13/(B6+B7+B9))*365) -> 272 | C14: =IF((C6+C7+C9)=0,0,(C13/(C6+C7+C9))*365) -> 671 | D14: =IF((D6+D7+D9)=0,0,(D13/(D6+D7+D9))*365) -> 1201 | E14: =IF((E6+E7+E9)=0,0,(E13/(E6+E7+E9))*365) -> 1832 | F14: =IF((F6+F7+F9)=0,0,(F13/(F6+F7+F9))*365) -> 2518
A15: Months of Runway | B15: =IF((B6+B7+B9)=0,0,B13/((B6+B7+B9)/12)) -> 8.9 | C15: =IF((C6+C7+C9)=0,0,C13/((C6+C7+C9)/12)) -> 22.1 | D15: =IF((D6+D7+D9)=0,0,D13/((D6+D7+D9)/12)) -> 39.5 | E15: =IF((E6+E7+E9)=0,0,E13/((E6+E7+E9)/12)) -> 60.2 | F15: =IF((F6+F7+F9)=0,0,F13/((F6+F7+F9)/12)) -> 82.8
A16: Capacity Utilization | B16: 0.5 | C16: 0.65 | D16: 0.8 | E16: 0.925 | F16: 1
A18: BREAK-EVEN ANALYSIS
A19: Revenue per Student | B19: 19750 | C19: 20164 | D19: 20654 | E19: 21205 | F19: 21807
A20: Fixed Costs (Pers + Debt) | B20: 888836 | C20: 914480 | D20: 940892 | E20: 968097 | F20: 996118
A21: Variable Cost per Student (OpEx) | B21: 2714 | C21: 2388 | D21: 2197 | E21: 2105 | F21: 2090
A22: Break-Even Enrollment | B22: 53 | C22: 52 | D22: 51 | E22: 51 | F22: 51
A24: COVENANT CHECKS
A25: DSCR ≥ 1.25x | B25: PASS | C25: PASS | D25: PASS | E25: PASS | F25: PASS
A26: Positive Net Income | B26: PASS | C26: PASS | D26: PASS | E26: PASS | F26: PASS
A27: Capacity ≥ 7500% | B27: FAIL | C27: FAIL | D27: FAIL | E27: FAIL | F27: FAIL
A28: Cash Reserve ≥ 3 months | B28: PASS | C28: PASS | D28: PASS | E28: PASS | F28: PASS
A29: Days Cash ≥ 60 | B29: PASS | C29: PASS | D29: PASS | E29: PASS | F29: PASS

Sheet Sources & Uses
A1: Sources & Uses
A3: SOURCES | B3: Amount | D3: USES | E3: Amount
A4: Facility Buildout Loan | B4: 250000 | D4: Facility Renovation | E4: 200000
A5: Foundation Grant | B5: 50000 | D5: Furniture & Equipment | E5: 50000
A6: Operating Cash | B6: 75000 | D6: Working Capital Reserve | E6: 75000
D7: Pre-Opening Costs | E7: 50000
A9: Total Sources | B9: 375000 | D9: Total Uses | E9: 375000
A10: Sources - Uses (should = 0) | B10: 0

Sheet Scenarios
A1: Scenario Analysis
A3: BASE CASE
A4: Enrollment: +0% | Revenue: +0% | Staffing: +0% | Facility: +0% | Expenses: +0%
B5: 2023-24 | C5: 2024-25 | D5: 2025-26 | E5: 2026-27 | F5: 2027-28
A6: Revenue | B6: 1975000 | C6: 2621350 | D6: 3304704 | E6: 3922890 | F6: 4361347
A7: Total Expenses | B7: 1160236 | C7: 1224922 | D7: 1292474 | E7: 1357545 | F7: 1414132
A8: Change in Net Assets | B8: 814764 | C8: 1396428 | D8: 2012229 | E8: 2565345 | F8: 2947215
A9: Net Margin % | B9: 0.41253854 | C9: 0.53271347 | D9: 0.60889857 | E9: 0.65394269 | F9: 0.67575799
A10: DSCR | B10: 24.92 | C10: 41.99 | D10: 60.07 | E10: 76.31 | F10: 87.52
A11: Break-Even Enrollment | B11: 53 | C11: 52 | D11: 51 | E11: 51 | F11: 51
A13: LOW ENROLLMENT
A14: Enrollment: -15% | Revenue: +0% | Staffing: +0% | Facility: +0% | Expenses: +0%
B15: 2023-24 | C15: 2024-25 | D15: 2025-26 | E15: 2026-27 | F15: 2027-28
A16: Revenue | B16: 1678750 | C16: 2228148 | D16: 2808998 | E16: 3334456 | F16: 3707145
A17: Total Expenses | B17: 1160236 | C17: 1224922 | D17: 1292474 | E17: 1357545 | F17: 1414132
A18: Change in Net Assets | B18: 518514 | C18: 1003226 | D18: 1516524 | E18: 1976912 | F18: 2293013
A19: Net Margin % | B19: 0.30886886 | C19: 0.45025114 | D19: 0.53988067 | E19: 0.59287375 | F19: 0.61853882
A20: DSCR | B20: 16.22 | C20: 30.45 | D20: 45.52 | E20: 59.03 | F20: 68.31
A21: Break-Even Enrollment | B21: 54 | C21: 53 | D21: 53 | E21: 52 | F21: 52
A23: HIGH COSTS
A24: Enrollment: +0% | Revenue: +0% | Staffing: +0% | Facility: +0% | Expenses: +10%
B25: 2023-24 | C25: 2024-25 | D25: 2025-26 | E25: 2026-27 | F25: 2027-28
A26: Revenue | B26: 1975000 | C26: 2621350 | D26: 3304704 | E26: 3922890 | F26: 4361347
A27: Total Expenses | B27: 1173736 | C27: 1241917 | D27: 1313162 | E27: 1381585 | F27: 1440581
A28: Change in Net Assets | B28: 801264 | C28: 1379433 | D28: 1991542 | E28: 2541305 | F28: 2920765
A29: Net Margin % | B29: 0.40570309 | C29: 0.52623017 | D29: 0.60263854 | E29: 0.64781456 | F29: 0.66969348
A30: DSCR | B30: 24.52 | C30: 41.49 | D30: 59.46 | E30: 75.6 | F30: 86.74
A31: Break-Even Enrollment | B31: 53 | C31: 52 | D31: 52 | E31: 52 | F31: 51

Sheet Underwriting Snapshot
A1: Underwriting Snapshot - Loan Committee Summary
A3: SCHOOL PROFILE
A4: School Name | B4: Heritage Academy
A5: Type | B5: Private School
A6: Entity | B6: 501(c)(3) Nonprofit
A7: Stage | B7: Operating
A8: State | B8: FL
A9: Funding | B9: Hybrid / Mixed
A11: 5-YEAR FINANCIAL TREND
D12: 2023-24 | E12: 2024-25 | F12: 2025-26 | G12: 2026-27 | H12: 2027-28
A13: Revenue | D13: 1975000 | E13: 2621350 | F13: 3304704 | G13: 3922890 | H13: 4361347
A14: Total Expenses | D14: 1160236 | E14: 1224922 | F14: 1292474 | G14: 1357545 | H14: 1414132
A15: Change in Net Assets | D15: 789764 | E15: 1386428 | F15: 2002229 | G15: 2560345 | H15: 2942215
A16: Cash Position | D16: 864756 | E16: 2251184 | F16: 4253414 | G16: 6813759 | H16: 9755974
A17: Outstanding Debt | D17: 231645 | E17: 212061 | F17: 191165 | G17: 168870 | H17: 145082
A19: KEY RATIOS
D20: 2023-24 | E20: 2024-25 | F20: 2025-26 | G20: 2026-27 | H20: 2027-28
A21: Net Margin | D21: 0.39988031 | E21: 0.52889864 | F21: 0.60587258 | G21: 0.65266812 | H21: 0.67461156
A22: DSCR | D22: 24.92 | E22: 41.99 | F22: 60.07 | G22: 76.31 | H22: 87.52
A23: Capacity Utilization | D23: 0.5 | E23: 0.65 | F23: 0.8 | G23: 0.925 | H23: 1
A24: Enrollment | D24: 100 | E24: 130 | F24: 160 | G24: 185 | H24: 200
A26: Prepared by SchoolStack Budget - budget.schoolstack.ai
