Workbook

Sheet Instructions
B2: How to Use This Workbook
B3: Bright Horizons Microschool
B4: Generated May 9, 2026 · llc_single
B6: Cell Color Legend
B7: Blue cells are editable inputs — change these to update your model.
B8: White cells contain formulas — do not edit (they recalculate automatically).
B9: Green cells are key outputs and summary metrics.
B11: Navigation
B12: The Assumptions tab is the central control panel — all other tabs reference it.
B14: Structure
B15: Tabs 5-9: Drivers & inputs
B16: Tabs 10-13: Forecasts & budgets
... B37: user-provided assumptions and should be independently verified.

Sheet Cover
B3: SchoolStack Budget
B5: 5-Year Financial Model — Founder Planning Workbook
B8: School Name | C8: Bright Horizons Microschool
B9: School Type | C9: Microschool
B10: Entity Type | C10: LLC (Single Member)
B11: State | C11: AZ
B12: Fiscal Year Start | C12: Month 7
B13: Model Date | C13: May 9, 2026
B14: Stage | C14: Startup / Pre-Opening
B15: Funding Profile | C15: Tuition-Based
B18: Table of Contents
B19: 1. | C19: Instructions
B20: 2. | C20: Cover
B21: 3. | C21: Assumptions
B22: 4. | C22: Program Profile
B23: 5. | C23: Enrollment Drivers
B24: 6. | C24: Tuition & Funding
B25: 7. | C25: Staffing Drivers
B26: 8. | C26: OpEx Drivers
B27: 9. | C27: Capital Stack
B28: 10. | C28: Enrollment Tuition Fcst
B29: 11. | C29: Staffing Costs Fcst
B30: 12. | C30: Budget Detail
... B42: 24. | C42: Assumptions Confidence
B45: CONFIDENTIAL - Prepared by SchoolStack Budget (budget.schoolstack.ai)

Sheet Assumptions
A1: Bright Horizons Microschool - Assumptions
B2: Editable assumption — change this value | E2: Calculated — driven by formula
A4: SCHOOL PROFILE
A5: School Name | B5: Bright Horizons Microschool
A6: School Type | B6: Microschool
A7: Entity Type | B7: LLC (Single Member)
A8: State | B8: AZ
A9: EIN | B9: 88-1234567
A10: Stage | B10: Startup / Pre-Opening
A11: Funding Profile | B11: Tuition-Based
A12: Fiscal Year Start Month | B12: 7
A13: Max Capacity | B13: 25
A15: ENROLLMENT
B16: 2026-27 | C16: 2027-28 | D16: 2028-29 | E16: 2029-30 | F16: 2030-31
A17: Total Students | B17: 12 | C17: 18 | D17: 22 | E17: 25 | F17: 25
A19: REVENUE DRIVERS
A20: Line Item | B20: Category | C20: Driver | D20: Amount | E20: Escalation % | F20: Timing
A21: Tuition | B21: Tuition & Fees | C21: Per Student | D21: 12000 | E21: 0 | F21: Default
A22: Registration Fee | B22: Tuition & Fees | C22: Per Student | D22: 250 | E22: 0 | F22: Default
A23: AZ ESA Funds | B23: School Choice | C23: Per Student | D23: 7000 | E23: 0 | F23: Default
A24: Annual Fundraising | B24: Philanthropy | C24: Annual Fixed | D24: 5000 | E24: 0 | F24: Default
A25: Scholarship Discount | B25: Tuition Offsets | C25: % of Base | D25: 10 | E25: 0 | F25: Default
A27: REVENUE QUALITY
A28: Bucket | B28: 2026-27 | C28: 2027-28 | D28: 2028-29 | E28: 2029-30 | F28: 2030-31
A29: Contracted | B29: -12000 | C29: -22248 | D29: -28007.76 | E29: -32781.81 | F29: -33765.264
A30: Projected | B30: 122500 | C30: 227115 | D30: 285912.55 | E30: 334647.64 | F30: 344687.07
A31: Donor-dependent | B31: 4166.6667 | C31: 5150 | D31: 5304.5 | E31: 5463.635 | F31: 5627.5441
A32: Policy-dependent | B32: 70000 | C32: 129780 | D32: 163378.6 | E32: 191227.23 | F32: 196964.04
A33: Contracted % | B33: -0.064981949 | C33: -0.065474386 | D33: -0.06565531 | E33: -0.065753425 | F33: -0.065753425
A34: Projected % | B34: 0.6633574 | C34: 0.66838436 | D34: 0.67023129 | E34: 0.67123288 | F34: 0.67123288
A35: Donor-dependent % | B35: 0.022563177 | C35: 0.015156108 | D35: 0.012434718 | E35: 0.010958904 | F35: 0.010958904
A36: Policy-dependent % | B36: 0.37906137 | C36: 0.38193392 | D36: 0.38298931 | E36: 0.38356164 | F36: 0.38356164
A37: Hard Rev Coverage (Contracted ÷ Fixed + Debt) | B37: -0.077452251 | C37: -0.12157202 | D37: -0.14944429 | E37: -0.17077854 | F37: -0.17171653
A39: STAFFING
A40: Role | B40: Category | C40: Type | D40: FTE | E40: Rate | F40: Benefits % | G40: Tax %
A41: Founder / Head of School | B41: School Leadership | C41: full_time | D41: 1 | E41: 55000 | F41: 0.2 | G41: 0.0765
A42: Lead Teacher | B42: Instructional | C42: full_time | D42: 1 | E42: 45000 | F42: 0.2 | G42: 0.0765
A43: Teaching Assistant | B43: Instructional | C43: part_time | D43: 0.5 | E43: 28000 | F43: 0 | G43: 0.0765
A45: OPERATING EXPENSES
A46: Line Item | B46: Category | C46: Driver | D46: Amount | E46: Escalation %
...

Sheet Program Profile
A1: Program Profile
A3: School Model | B3: microschool
A4: School Type | B4: Microschool
A5: Entity Type | B5: LLC (Single Member)
A6: Financial Label Convention | B6: For-Profit (Profit & Loss / Equity)
A7: Stage | B7: Startup / Pre-Opening
A8: Funding Mix | B8: Tuition-Based
A9: Fiscal Year Start Month | B9: 7
A10: Year 1 Operating Months | B10: 10
A11: Proration Factor | B11: 83.3%
A12: Debt Included | B12: No
A13: Max Capacity | B13: 25
A14: Accredited | B14: No
... A16: Facility | B16: Leased

Sheet Enrollment Drivers
A1: Enrollment Drivers
B3: 2026-27 | C3: 2027-28 | D3: 2028-29 | E3: 2029-30 | F3: 2030-31
A5: TOTAL ENROLLMENT
A6: Total Students | B6: 12 | C6: 18 | D6: 22 | E6: 25 | F6: 25
A7: Max Capacity | B7: 25
A8: Capacity Utilization | B8: =B6/$B$7 -> 0.48 | C8: =C6/$B$7 -> 0.72 | D8: =D6/$B$7 -> 0.88 | E8: =E6/$B$7 -> 1 | F8: =F6/$B$7 -> 1
A10: Enrollment Growth Rate | B10: - | C10: =IF(B6=0,0,(C6-B6)/B6) -> 0.5 | D10: =IF(C6=0,0,(D6-C6)/C6) -> 0.22222222 | E10: =IF(D6=0,0,(E6-D6)/D6) -> 0.13636364 | F10: =IF(E6=0,0,(F6-E6)/E6) -> 0

Sheet Tuition & Funding
A1: Tuition & Funding Drivers
B3: 2026-27 | C3: 2027-28 | D3: 2028-29 | E3: 2029-30 | F3: 2030-31
A4: TUITION & FEES
A5: Tuition | B5: 144000 | C5: 222480 | D5: 280078 | E5: 327818 | F5: 337653
A6: Registration Fee | B6: 3000 | C6: 4635 | D6: 5835 | E6: 6830 | F6: 7034
A7: Total Tuition & Fees | B7: =SUM(B5,B6) -> 147000 | C7: =SUM(C5,C6) -> 227115 | D7: =SUM(D5,D6) -> 285913 | E7: =SUM(E5,E6) -> 334648 | F7: =SUM(F5,F6) -> 344687
A8: TUITION OFFSETS
A9: Scholarship Discount | B9: -10 | C9: -10 | D9: -11 | E9: -11 | F9: -11
A10: Total Tuition Offsets | B10: =SUM(B9) -> -10 | C10: =SUM(C9) -> -10 | D10: =SUM(D9) -> -11 | E10: =SUM(E9) -> -11 | F10: =SUM(F9) -> -11
A11: SCHOOL CHOICE
A12: AZ ESA Funds | B12: 84000 | C12: 129780 | D12: 163379 | E12: 191227 | F12: 196964
A13: Total School Choice | B13: =SUM(B12) -> 84000 | C13: =SUM(C12) -> 129780 | D13: =SUM(D12) -> 163379 | E13: =SUM(E12) -> 191227 | F13: =SUM(F12) -> 196964
A14: PHILANTHROPY
A15: Annual Fundraising | B15: 5000 | C15: 5150 | D15: 5305 | E15: 5464 | F15: 5628
A16: Total Philanthropy | B16: =SUM(B15) -> 5000 | C16: =SUM(C15) -> 5150 | D16: =SUM(D15) -> 5305 | E16: =SUM(E15) -> 5464 | F16: =SUM(F15) -> 5628
A18: GRAND TOTAL REVENUE | B18: =SUM(B7,B10,B13,B16) -> 221600 | C18: =SUM(C7,C10,C13,C16) -> 339130 | D18: =SUM(D7,D10,D13,D16) -> 424882 | E18: =SUM(E7,E10,E13,E16) -> 495517 | F18: =SUM(F7,F10,F13,F16) -> 509276

Sheet Staffing Drivers
A1: Staffing Drivers
A3: Role | B3: Category | C3: FTE | D3: Base Rate | E3: Benefits % | F3: Tax % | G3: Loaded Cost | H3: Rates
A4: Founder / Head of School | B4: School Leadership | C4: 1 | D4: 55000 | E4: 0.2 | F4: 0.0765 | G4: 70208 | H4: Default
A5: Lead Teacher | B5: Instructional | C5: 1 | D5: 45000 | E5: 0.2 | F5: 0.0765 | G5: 57443 | H5: Default
A6: Teaching Assistant | B6: Instructional | C6: 0.5 | D6: 28000 | E6: 0 | F6: 0.0765 | G6: 15071 | H6: Default
A8: 5-YEAR TOTAL PERSONNEL COST
B9: 2026-27 | C9: 2027-28 | D9: 2028-29 | E9: 2029-30 | F9: 2030-31
A10: Total Personnel | B10: 118934 | C10: 147003 | D10: 151413 | E10: 155955 | F10: 160634
A11: Personnel as % of Revenue | B11: 0.53670653 | C11: 0.43347041 | D11: 0.35636396 | E11: 0.31473211 | F11: 0.31541616
A12: Students per FTE | B12: 4.8 | C12: 7.2 | D12: 8.8 | E12: 10 | F12: 10

Sheet OpEx Drivers
A1: Operating Expense Drivers
B3: 2026-27 | C3: 2027-28 | D3: 2028-29 | E3: 2029-30 | F3: 2030-31
A4: Instructional / Program
A5: Curriculum & Materials | B5: 6000 | C5: 9270 | D5: 11670 | E5: 13659 | F5: 14069
A6: Total Instructional / Program | B6: =SUM(B5:B5) -> 6000 | C6: =SUM(C5:C5) -> 9270 | D6: =SUM(D5:D5) -> 11670 | E6: =SUM(E5:E5) -> 13659 | F6: =SUM(F5:F5) -> 14069
A7: Technology
A8: Technology | B8: 3600 | C8: 5562 | D8: 7002 | E8: 8195 | F8: 8441
A9: Total Technology | B9: =SUM(B8:B8) -> 3600 | C9: =SUM(C8:C8) -> 5562 | D9: =SUM(D8:D8) -> 7002 | E9: =SUM(E8:E8) -> 8195 | F9: =SUM(F8:F8) -> 8441
A10: Occupancy / Facility
A11: Rent | B11: 30000 | C11: 30900 | D11: 31827 | E11: 32782 | F11: 33765
A12: Utilities | B12: 3600 | C12: 3708 | D12: 3819 | E12: 3934 | F12: 4052
A13: Insurance | B13: 2400 | C13: 2472 | D13: 2546 | E13: 2623 | F13: 2701
A14: Total Occupancy / Facility | B14: =SUM(B11:B13) -> 36000 | C14: =SUM(C11:C13) -> 37080 | D14: =SUM(D11:D13) -> 38192 | E14: =SUM(E11:E13) -> 39338 | F14: =SUM(F11:F13) -> 40518
A15: Administrative / General
A16: Marketing | B16: 3000 | C16: 3090 | D16: 3183 | E16: 3278 | F16: 3377
A17: Total Administrative / General | B17: =SUM(B16:B16) -> 3000 | C17: =SUM(C16:C16) -> 3090 | D17: =SUM(D16:D16) -> 3183 | E17: =SUM(E16:E16) -> 3278 | F17: =SUM(F16:F16) -> 3377
A19: TOTAL OPERATING EXPENSES | B19: =B6+B9+B14+B17 -> 48600 | C19: =C6+C9+C14+C17 -> 55002 | D19: =D6+D9+D14+D17 -> 60047 | E19: =E6+E9+E14+E17 -> 64471 | F19: =F6+F9+F14+F17 -> 66405

Sheet Capital Stack
A1: Capital Stack & Loan Terms
A3: Instrument | B3: Type | C3: Principal | D3: Rate | E3: Term (Yrs) | F3: Annual Payment
A4: Equipment Loan | B4: Loan | C4: 30000 | D4: 0.06 | E4: 5 | F4: 6960
A6: Total Annual Debt Service | F6: 6960
A7: Total Loan Principal | F7: 30000

Sheet Enrollment Tuition Fcst
A1: Enrollment & Tuition Forecast
B3: 2026-27 | C3: 2027-28 | D3: 2028-29 | E3: 2029-30 | F3: 2030-31
A4: Total Students | B4: 12 | C4: 18 | D4: 22 | E4: 25 | F4: 25
A6: REVENUE FORECAST
A7: Tuition | B7: 144000 | C7: 222480 | D7: 280078 | E7: 327818 | F7: 337653
A8: Registration Fee | B8: 3000 | C8: 4635 | D8: 5835 | E8: 6830 | F8: 7034
A9: AZ ESA Funds | B9: 84000 | C9: 129780 | D9: 163379 | E9: 191227 | F9: 196964
A10: Annual Fundraising | B10: 5000 | C10: 5150 | D10: 5305 | E10: 5464 | F10: 5628
A11: Scholarship Discount | B11: -10 | C11: -10 | D11: -11 | E11: -11 | F11: -11
A12: TOTAL REVENUE | B12: =SUM(B7:B11) -> 221600 | C12: =SUM(C7:C11) -> 339130 | D12: =SUM(D7:D11) -> 424882 | E12: =SUM(E7:E11) -> 495517 | F12: =SUM(F7:F11) -> 509276
A14: Revenue per Student | B14: 18467 | C14: 18841 | D14: 19313 | E14: 19821 | F14: 20371

Sheet Staffing Costs Fcst
A1: Staffing Costs Forecast
B3: 2026-27 | C3: 2027-28 | D3: 2028-29 | E3: 2029-30 | F3: 2030-31
A4: Instructional
A5: Lead Teacher [1 FTE] | B5: 47869 | C5: 59166 | D5: 60941 | E5: 62769 | F5: 64652
A6: Teaching Assistant [0.5 FTE] | B6: 12559 | C6: 15523 | D6: 15989 | E6: 16468 | F6: 16963
A7: Total Instructional | B7: =SUM(B5:B6) -> 60428 | C7: =SUM(C5:C6) -> 74689 | D7: =SUM(D5:D6) -> 76930 | E7: =SUM(E5:E6) -> 79237 | F7: =SUM(F5:F6) -> 81615
A8: School Leadership
A9: Founder / Head of School [1 FTE] | B9: 58506 | C9: 72314 | D9: 74483 | E9: 76718 | F9: 79019
A10: Total School Leadership | B10: =SUM(B9:B9) -> 58506 | C10: =SUM(C9:C9) -> 72314 | D10: =SUM(D9:D9) -> 74483 | E10: =SUM(E9:E9) -> 76718 | F10: =SUM(F9:F9) -> 79019
A12: TOTAL PERSONNEL | B12: =B7+B10 -> 118934 | C12: =C7+C10 -> 147003 | D12: =D7+D10 -> 151413 | E12: =E7+E10 -> 155955 | F12: =F7+F10 -> 160634

Sheet Budget Detail
A1: Bright Horizons Microschool - Budget Detail
B3: 2026-27 | C3: 2027-28 | D3: 2028-29 | E3: 2029-30 | F3: 2030-31
A4: REVENUE
A5: Tuition | B5: 120000 | C5: 222480 | D5: 280078 | E5: 327818 | F5: 337653
A6: Registration Fee | B6: 2500 | C6: 4635 | D6: 5835 | E6: 6830 | F6: 7034
A7: AZ ESA Funds | B7: 70000 | C7: 129780 | D7: 163379 | E7: 191227 | F7: 196964
A8: Annual Fundraising | B8: 4167 | C8: 5150 | D8: 5305 | E8: 5464 | F8: 5628
A9: Scholarship Discount | B9: -8 | C9: -10 | D9: -11 | E9: -11 | F9: -11
A10: Total Revenue | B10: =SUM(B5:B9) -> 184667 | C10: =SUM(C5:C9) -> 340512 | D10: =SUM(D5:D9) -> 427946 | E10: =SUM(E5:E9) -> 500518 | F10: =SUM(F5:F9) -> 516085
A12: PERSONNEL
A13: Founder / Head of School | B13: 58506 | C13: 72314 | D13: 74483 | E13: 76718 | F13: 79019
A14: Lead Teacher | B14: 47869 | C14: 59166 | D14: 60941 | E14: 62769 | F14: 64652
A15: Teaching Assistant | B15: 12559 | C15: 15523 | D15: 15989 | E15: 16468 | F15: 16963
A16: Total Personnel | B16: =SUM(B13:B15) -> 118934 | C16: =SUM(C13:C15) -> 147003 | D16: =SUM(D13:D15) -> 151413 | E16: =SUM(E13:E15) -> 155955 | F16: =SUM(F13:F15) -> 160634
A18: OPERATING EXPENSES
A19: Instructional / Program
A20: Curriculum & Materials | B20: 5000 | C20: 9270 | D20: 11670 | E20: 13659 | F20: 14069
A21: Technology
A22: Technology | B22: 3000 | C22: 5562 | D22: 7002 | E22: 8195 | F22: 8441
A23: Occupancy / Facility
A24: Rent | B24: 25000 | C24: 30900 | D24: 31827 | E24: 32782 | F24: 33765
A25: Utilities | B25: 3000 | C25: 3708 | D25: 3819 | E25: 3934 | F25: 4052
A26: Insurance | B26: 2000 | C26: 2472 | D26: 2546 | E26: 2623 | F26: 2701
A27: Total Occupancy / Facility | B27: =SUM(B24:B26) -> 30000 | C27: =SUM(C24:C26) -> 37080 | D27: =SUM(D24:D26) -> 38192 | E27: =SUM(E24:E26) -> 39338 | F27: =SUM(F24:F26) -> 40518
A28: Administrative / General
A29: Marketing | B29: 2500 | C29: 3090 | D29: 3183 | E29: 3278 | F29: 3377
A30: Total Operating Expenses | B30: =B20+B22+B27+B29 -> 40500 | C30: =C20+C22+C27+C29 -> 55002 | D30: =D20+D22+D27+D29 -> 60047 | E30: =E20+E22+E27+E29 -> 64471 | F30: =F20+F22+F27+F29 -> 66405
A32: CAPITAL & DEBT SERVICE
A33: Total Capital & Debt | B33: =SUM(B33:B32) -> 0 | C33: =SUM(C33:C32) -> 0 | D33: =SUM(D33:D32) -> 0 | E33: =SUM(E33:E32) -> 0 | F33: =SUM(F33:F32) -> 0

Sheet Budget Summary
A1: Bright Horizons Microschool - Budget Summary
B3: 2026-27 | C3: 2027-28 | D3: 2028-29 | E3: 2029-30 | F3: 2030-31
A4: Total Revenue | B4: ='Budget Detail'!B10 -> 184667 | C4: ='Budget Detail'!C10 -> 340512 | D4: ='Budget Detail'!D10 -> 427946 | E4: ='Budget Detail'!E10 -> 500518 | F4: ='Budget Detail'!F10 -> 516085
A5: Total Personnel | B5: ='Budget Detail'!B16 -> 118934 | C5: ='Budget Detail'!C16 -> 147003 | D5: ='Budget Detail'!D16 -> 151413 | E5: ='Budget Detail'!E16 -> 155955 | F5: ='Budget Detail'!F16 -> 160634
A6: Total Operating Expenses | B6: ='Budget Detail'!B30 -> 40500 | C6: ='Budget Detail'!C30 -> 55002 | D6: ='Budget Detail'!D30 -> 60047 | E6: ='Budget Detail'!E30 -> 64471 | F6: ='Budget Detail'!F30 -> 66405
A7: Total Capital & Debt Service | B7: ='Budget Detail'!B33 -> 0 | C7: ='Budget Detail'!C33 -> 0 | D7: ='Budget Detail'!D33 -> 0 | E7: ='Budget Detail'!E33 -> 0 | F7: ='Budget Detail'!F33 -> 0
A8: Total Expenses | B8: =SUM(B5:B7) -> 159434 | C8: =SUM(C5:C7) -> 202005 | D8: =SUM(D5:D7) -> 211460 | E8: =SUM(E5:E7) -> 220426 | F8: =SUM(F5:F7) -> 227039
A10: KEY METRICS
A11: Net Income | B11: =B4-B8 -> 25232 | C11: =C4-C8 -> 138507 | D11: =D4-D8 -> 216486 | E11: =E4-E8 -> 280092 | F11: =F4-F8 -> 289046
A12: Net Margin % | B12: =IF(B4=0,0,B11/B4) -> 0.13663809 | C12: =IF(C4=0,0,C11/C4) -> 0.40676208 | D12: =IF(D4=0,0,D11/D4) -> 0.50587283 | E12: =IF(E4=0,0,E11/E4) -> 0.55960384 | F12: =IF(F4=0,0,F11/F4) -> 0.56007487
A13: Cumulative Net Income | B13: 25232 | C13: 163740 | D13: 380226 | E13: 660318 | F13: 949364
A14: Revenue per Student | B14: 15389 | C14: 18917 | D14: 19452 | E14: 20021 | F14: 20643
A15: Cost per Student | B15: 13286 | C15: 11222 | D15: 9612 | E15: 8817 | F15: 9082

Sheet Monthly Cash Flow Y1
A1: Bright Horizons Microschool - Year 1 Monthly Cash Flow
B2: July | C2: August | D2: September | E2: October | F2: November | G2: December | H2: January | I2: February | J2: March | K2: April | L2: May | M2: June | N2: Annual Total
A3: REVENUE
A4: Total Revenue | B4: 26250 | C4: 13210 | D4: 13210 | E4: 34210 | F4: 13210 | G4: 13210 | H4: 34210 | I4: 13210 | J4: 13210 | K4: 34210 | L4: 13210 | M4: 250 | N4: =SUM(B4:M4) -> 221600
A6: EXPENSES
A7: Personnel | B7: 11893 | C7: 11893 | D7: 11893 | E7: 11893 | F7: 11893 | G7: 11893 | H7: 11893 | I7: 11893 | J7: 11893 | K7: 11893 | L7: 0 | M7: 0 | N7: =SUM(B7:M7) -> 118934
A8: Operating Expenses | B8: 4050 | C8: 4050 | D8: 4050 | E8: 4050 | F8: 4050 | G8: 4050 | H8: 4050 | I8: 4050 | J8: 4050 | K8: 4050 | L8: 0 | M8: 0 | N8: =SUM(B8:M8) -> 40500
A9: Debt Service | B9: 0 | C9: 0 | D9: 0 | E9: 0 | F9: 0 | G9: 0 | H9: 0 | I9: 0 | J9: 0 | K9: 0 | L9: 0 | M9: 0 | N9: =SUM(B9:M9) -> 0
A11: CASH FLOW
A12: Total Expenses | B12: =B7+B8+B9 -> 15943 | C12: =C7+C8+C9 -> 15943 | D12: =D7+D8+D9 -> 15943 | E12: =E7+E8+E9 -> 15943 | F12: =F7+F8+F9 -> 15943 | G12: =G7+G8+G9 -> 15943 | H12: =H7+H8+H9 -> 15943 | I12: =I7+I8+I9 -> 15943 | ... M12: =M7+M8+M9 -> 0 | N12: =SUM(B12:M12) -> 159430
A13: Net Cash Flow | B13: =B4-B12 -> 10307 | C13: =C4-C12 -> -2733 | D13: =D4-D12 -> -2733 | E13: =E4-E12 -> 18267 | F13: =F4-F12 -> -2733 | G13: =G4-G12 -> -2733 | H13: =H4-H12 -> 18267 | I13: =I4-I12 -> -2733 | ... M13: =M4-M12 -> 250 | N13: =SUM(B13:M13) -> 62170
A14: Cumulative Cash | B14: =B17+B13 -> 10307 | C14: =B14+C13 -> 7574 | D14: =C14+D13 -> 4841 | E14: =D14+E13 -> 23108 | F14: =E14+F13 -> 20375 | G14: =F14+G13 -> 17642 | H14: =G14+H13 -> 35909 | I14: =H14+I13 -> 33176 | J14: =I14+J13 -> 30443 | ... M14: =L14+M13 -> 62170 | N14: =M14 -> 62170
A16: CASH FLOW METRICS
A17: Starting Cash | B17: 0
A18: Ending Cash (Month 12) | B18: =M14 -> 62170
A19: Minimum Cash Month | B19: =MIN(B14:M14) -> 4841
A20: Cash Trough: September (Month 3)
A21: Your lowest cash point is the month lenders focus on to ensure you won't run out of money before collections start. Plan reserves to cover this trough.

Sheet 5-Year Operating Stmt
A1: Bright Horizons Microschool - 5-Year Operating Statement
A2: Projections prepared on an accrual basis. School currently keeps books on a undetermined basis.
B3: 2026-27 | C3: 2027-28 | D3: 2028-29 | E3: 2029-30 | F3: 2030-31
A4: REVENUE
A5: Total Revenue | B5: 184667 | C5: 340512 | D5: 427946 | E5: 500518 | F5: 516085
A7: EXPENSES
A8: Personnel | B8: 118934 | C8: 147003 | D8: 151413 | E8: 155955 | F8: 160634
A9: Operating Expenses | B9: 40500 | C9: 55002 | D9: 60047 | E9: 64471 | F9: 66405
A10: Interest Expense | B10: 0 | C10: 0 | D10: 0 | E10: 0 | F10: 0
A11: Principal & Capital Outlays | B11: 0 | C11: 0 | D11: 0 | E11: 0 | F11: 0
A12: Depreciation | B12: 714 | C12: 714 | D12: 714 | E12: 714 | F12: 714
A13: Total Expenses | B13: =SUM(B8:B12) -> 160148 | C13: =SUM(C8:C12) -> 202719 | D13: =SUM(D8:D12) -> 212174 | E13: =SUM(E8:E12) -> 221140 | F13: =SUM(F8:F12) -> 227753
A15: BOTTOM LINE
A16: Net Income | B16: =B5-B13 -> 24518 | C16: =C5-C13 -> 137793 | D16: =D5-D13 -> 215772 | E16: =E5-E13 -> 279377 | F16: =F5-F13 -> 288332
A17: Net Margin % | B17: =IF(B5=0,0,B16/B5) -> 0.13277011 | C17: =IF(C5=0,0,C16/C5) -> 0.4046644 | D17: =IF(D5=0,0,D16/D5) -> 0.50420372 | E17: =IF(E5=0,0,E16/E5) -> 0.55817675 | F17: =IF(F5=0,0,F16/F5) -> 0.55869082
A18: Cumulative Net Income | B18: =B16 -> 24518 | C18: =B18+C16 -> 162311 | D18: =C18+D16 -> 378083 | E18: =D18+E16 -> 657460 | F18: =E18+F16 -> 945792
A19: Break-even | B19: ✓ Break-even

Sheet Debt Schedule
A1: Debt Schedule
B3: 2026-27 | C3: 2027-28 | D3: 2028-29 | E3: 2029-30 | F3: 2030-31
A4: LOAN TERMS
A5: Loan Name | B5: Principal | C5: Annual Rate | D5: Term (Years) | E5: Annual Payment

Sheet Balance Sheet
A1: Bright Horizons Microschool - Balance Sheet
B3: 2026-27 | C3: 2027-28 | D3: 2028-29 | E3: 2029-30 | F3: 2030-31
A4: ASSETS
A5: Cash & Equivalents | B5: ='Monthly Cash Flow Y1'!M14 -> 62170 | C5: =B5+'5-Year Operating Stmt'!C16 -> 200677 | D5: =B5+'5-Year Operating Stmt'!C16+'5-Year Operating Stmt'!D16 -> 417164 | E5: =B5+'5-Year Operating Stmt'!C16+'5-Year Operating Stmt'!D16+'5-Year Operating Stmt'!E16 -> 697255 | F5: =B5+'5-Year Operating Stmt'!C16+'5-Year Operating Stmt'!D16+'5-Year Operating Stmt'!E16+'5-Year Operating Stmt'!F16 -> 986301
A6: Accounts Receivable | B6: 1007 | C6: 1036 | D6: 1067 | E6: 1098 | F6: 1131
A7: Fixed Assets (Net of Depreciation) | B7: 4286 | C7: 3571 | D7: 2857 | E7: 2143 | F7: 1429
A8: Other Assets | B8: 0 | C8: 0 | D8: 0 | E8: 0 | F8: 0
A9: Total Assets | B9: =SUM(B5:B8) -> 67463 | C9: =SUM(C5:C8) -> 205285 | D9: =SUM(D5:D8) -> 421088 | E9: =SUM(E5:E8) -> 700496 | F9: =SUM(F5:F8) -> 988860
A11: LIABILITIES
A12: Accounts Payable | B12: 0 | C12: 0 | D12: 0 | E12: 0 | F12: 0
A13: Long-Term Debt | B13: 0 | C13: 0 | D13: 0 | E13: 0 | F13: 0
A14: Total Liabilities | B14: =SUM(B12:B13) -> 0 | C14: =SUM(C12:C13) -> 0 | D14: =SUM(D12:D13) -> 0 | E14: =SUM(E12:E13) -> 0 | F14: =SUM(F12:F13) -> 0
A16: EQUITY
A17: Equity | B17: =B9-B14 -> 67463 | C17: =C9-C14 -> 205285 | D17: =D9-D14 -> 421088 | E17: =E9-E14 -> 700496 | F17: =F9-F14 -> 988860
A19: Balance Check (should = 0) | B19: =B9-B14-B17 -> 0 | C19: =C9-C14-C17 -> 0 | D19: =D9-D14-D17 -> 0 | E19: =E9-E14-E17 -> 0 | F19: =F9-F14-F17 -> 0

Sheet DSCR & Covenants
A1: DSCR & Covenant Checks
B3: 2026-27 | C3: 2027-28 | D3: 2028-29 | E3: 2029-30 | F3: 2030-31
A4: CASH FLOW & DEBT
A5: Revenue | B5: 184667 | C5: 340512 | D5: 427946 | E5: 500518 | F5: 516085
A6: Personnel | B6: 118934 | C6: 147003 | D6: 151413 | E6: 155955 | F6: 160634
A7: Operating Expenses | B7: 40500 | C7: 55002 | D7: 60047 | E7: 64471 | F7: 66405
A8: Net Income | B8: 25232 | C8: 138507 | D8: 216486 | E8: 280092 | F8: 289046
A9: Depreciation Add-Back | B9: 714 | C9: 714 | D9: 714 | E9: 714 | F9: 714
A10: Debt Service (Loan) | B10: 0 | C10: 0 | D10: 0 | E10: 0 | F10: 0
A11: CFADS (NI + Depr + DS) | B11: =B8+B9+B10 -> 25947 | C11: =C8+C9+C10 -> 139222 | D11: =D8+D9+D10 -> 217200 | E11: =E8+E9+E10 -> 280806 | F11: =F8+F9+F10 -> 289761
A12: DSCR | B12: N/A | C12: N/A | D12: N/A | E12: N/A | F12: N/A
A14: LIQUIDITY METRICS
A15: Ending Cash | B15: 40232 | C15: 178740 | D15: 395226 | E15: 675318 | F15: 964364
A16: Working-Capital Cash (basis for runway/days) | B16: 62170 | C16: 200677 | D16: 417164 | E16: 697255 | F16: 986301
A17: Days Cash on Hand | B17: =IF((B5-B8)=0,0,(B16/(B5-B8))*365) -> 142 | C17: =IF((C5-C8)=0,0,(C16/(C5-C8))*365) -> 363 | D17: =IF((D5-D8)=0,0,(D16/(D5-D8))*365) -> 720 | E17: =IF((E5-E8)=0,0,(E16/(E5-E8))*365) -> 1155 | F17: =IF((F5-F8)=0,0,(F16/(F5-F8))*365) -> 1586
A18: Months of Runway | B18: =IF((B5-B8)=0,0,B16/((B5-B8)/12)) -> 4.7 | C18: =IF((C5-C8)=0,0,C16/((C5-C8)/12)) -> 11.9 | D18: =IF((D5-D8)=0,0,D16/((D5-D8)/12)) -> 23.7 | E18: =IF((E5-E8)=0,0,E16/((E5-E8)/12)) -> 38 | F18: =IF((F5-F8)=0,0,F16/((F5-F8)/12)) -> 52.1
A19: Capacity Utilization | B19: 0.48 | C19: 0.72 | D19: 0.88 | E19: 1 | F19: 1
A21: BREAK-EVEN ANALYSIS
A22: Revenue per Student | B22: 15389 | C22: 18917 | D22: 19452 | E22: 20021 | F22: 20643
A23: Fixed Costs (Pers + Debt) | B23: 118934 | C23: 147003 | D23: 151413 | E23: 155955 | F23: 160634
A24: Variable Cost per Student (OpEx) | B24: 3375 | C24: 3056 | D24: 2729 | E24: 2579 | F24: 2656
A25: Break-Even Enrollment | B25: 11 | C25: 11 | D25: 11 | E25: 11 | F25: 11
A27: COVENANT CHECKS
A28: DSCR ≥ 1.2x | B28: N/A | C28: N/A | D28: N/A | E28: N/A | F28: N/A
A29: Positive Net Income | B29: PASS | C29: PASS | D29: PASS | E29: PASS | F29: PASS
A30: Current Ratio ≥ 1.1x | B30: N/A | C30: N/A | D30: N/A | E30: N/A | F30: N/A
A31: Capacity ≥ 70% | B31: FAIL | C31: PASS | D31: PASS | E31: PASS | F31: PASS
A32: Cash Reserve ≥ 3 months | B32: PASS | C32: PASS | D32: PASS | E32: PASS | F32: PASS
A33: Days Cash ≥ 45 | B33: PASS | C33: PASS | D33: PASS | E33: PASS | F33: PASS

Sheet Sources & Uses
A1: Sources & Uses
A3: SOURCES | B3: Amount | D3: USES | E3: Amount
A4: Owner Equity | B4: 20000 | D4: Startup Costs | E4: 15000
D5: Working Capital Reserve | E5: 5000
A7: Total Sources | B7: 20000 | D7: Total Uses | E7: 20000
A8: Sources - Uses (should = 0) | B8: 0

Sheet Scenarios
A1: Scenario Analysis
A3: BASE CASE
A4: Enrollment: +0% | Revenue: +0% | Staffing: +0% | Facility: +0% | Expenses: +0%
B5: 2026-27 | C5: 2027-28 | D5: 2028-29 | E5: 2029-30 | F5: 2030-31
A6: Revenue | B6: 184667 | C6: 340512 | D6: 427946 | E6: 500518 | F6: 516085
A7: Total Expenses | B7: 159434 | C7: 202005 | D7: 211460 | E7: 220426 | F7: 227039
A8: Net Income | B8: 25232 | C8: 138507 | D8: 216486 | E8: 280092 | F8: 289046
A9: Net Margin % | B9: 0.13663809 | C9: 0.40676208 | D9: 0.50587283 | E9: 0.55960384 | F9: 0.56007487
A10: DSCR | B10: N/A | C10: N/A | D10: N/A | E10: N/A | F10: N/A
A11: Break-Even Enrollment | B11: 10 | C11: 10 | D11: 10 | E11: 9 | F11: 9
A13: LOW ENROLLMENT
A14: Enrollment: -20% | Revenue: +0% | Staffing: +0% | Facility: +0% | Expenses: +0%
B15: 2026-27 | C15: 2027-28 | D15: 2028-29 | E15: 2029-30 | F15: 2030-31
A16: Revenue | B16: 147733 | C16: 272410 | D16: 342357 | E16: 400414 | F16: 412868
A17: Total Expenses | B17: 159434 | C17: 202005 | D17: 211460 | E17: 220426 | F17: 227039
A18: Net Income | B18: -11701 | C18: 70405 | D18: 130897 | E18: 179988 | F18: 185829
A19: Net Margin % | B19: -0.079202392 | C19: 0.2584526 | D19: 0.38234103 | E19: 0.4495048 | F19: 0.45009358
A20: DSCR | B20: N/A | C20: N/A | D20: N/A | E20: N/A | F20: N/A
A21: Break-Even Enrollment | B21: 12 | C21: 10 | D21: 10 | E21: 10 | F21: 10

Sheet Lender Snapshot
A1: Lender Conversation Snapshot - Summary
A3: SCHOOL PROFILE
A4: School Name | B4: Bright Horizons Microschool
A5: Type | B5: Microschool
A6: Entity | B6: LLC (Single Member)
A7: Stage | B7: Startup / Pre-Opening
A8: State | B8: AZ
A9: Funding | B9: Tuition-Based
A11: 5-YEAR FINANCIAL TREND
D12: 2026-27 | E12: 2027-28 | F12: 2028-29 | G12: 2029-30 | H12: 2030-31
A13: Revenue | D13: 184667 | E13: 340512 | F13: 427946 | G13: 500518 | H13: 516085
A14: Total Expenses | D14: 159434 | E14: 202005 | F14: 211460 | G14: 220426 | H14: 227039
A15: Net Income | D15: 25232 | E15: 138507 | F15: 216486 | G15: 280092 | H15: 289046
A16: Cash Position | D16: 62170 | E16: 200677 | F16: 417164 | G16: 697255 | H16: 986301
A17: Outstanding Debt | D17: 0 | E17: 0 | F17: 0 | G17: 0 | H17: 0
A19: KEY RATIOS
D20: 2026-27 | E20: 2027-28 | F20: 2028-29 | G20: 2029-30 | H20: 2030-31
A21: Net Margin | D21: 0.13663809 | E21: 0.40676208 | F21: 0.50587283 | G21: 0.55960384 | H21: 0.56007487
A22: DSCR | D22: N/A | E22: N/A | F22: N/A | G22: N/A | H22: N/A
A23: Capacity Utilization | D23: 0.48 | E23: 0.72 | F23: 0.88 | G23: 1 | H23: 1
A24: Enrollment | D24: 12 | E24: 18 | F24: 22 | G24: 25 | H24: 25
A26: BREAK-EVEN & DOWNSIDE
D27: 2026-27 | E27: 2027-28 | F27: 2028-29 | G27: 2029-30 | H27: 2030-31
A28: Break-Even Students | D28: 11 | E28: 11 | F28: 11 | G28: 11 | H28: 11
A29: Break-Even Utilization % | D29: 0.44 | E29: 0.44 | F29: 0.44 | G29: 0.44 | H29: 0.44
A30: -10% Enrollment: DSCR | D30: 1.56 | E30: 14.81 | F30: 25.89 | G30: 34.9 | H30: 36.05
A31: -10% Enrollment: Ending Cash | D31: 18898 | E31: 115034 | F31: 288247 | G31: 524160 | H31: 768075
A32: -20% Enrollment: DSCR | D32: N/A | E32: 9.71 | F32: 20.63 | G32: 26.78 | H32: 27.68
A33: -20% Enrollment: Ending Cash | D33: 4523 | E33: 65131 | F33: 201757 | G33: 381152 | H33: 566866
A35: Prepared by SchoolStack Budget - budget.schoolstack.ai

Sheet Financial Health
B2: Bright Horizons Microschool — Financial Health Dashboard
B3: Generated May 9, 2026
B4: ● Green = healthy | D4: ◐ Yellow = monitor | F4: ○ Red = action needed
B6: Metric | C6: Year 1 | D6: Year 2 | E6: Year 3 | F6: Year 4 | G6: Year 5 | H6: Benchmark
B7: Enrollment | C7: 12 | D7: 18 | E7: 22 | F7: 25 | G7: 25
B8: Revenue | C8: 184666.67 | D8: 340512 | E8: 427945.8 | F8: 500517.5 | G8: 516085
B9: Personnel | C9: 118934.17 | D9: 147002.63 | E9: 151412.71 | F9: 155955.09 | G9: 160633.74
B10: Operating Expenses | C10: 40500 | D10: 55002 | E10: 60046.94 | F10: 64470.893 | G10: 66405.02
B11: Debt Service | C11: 0 | D11: 0 | E11: 0 | F11: 0 | G11: 0
B12: Net Income | C12: 25232.5 | D12: 138507.37 | E12: 216486.15 | F12: 280091.52 | G12: 289046.24
B13: Ending Cash | C13: 62170 | D13: 200677.37 | E13: 417163.52 | F13: 697255.04 | G13: 986301.28
B14: Net Margin | C14: 0.13663809 | D14: 0.40676208 | E14: 0.50587283 | F14: 0.55960384 | G14: 0.56007487
B15: Revenue per Student | C15: 15388.889 | D15: 18917.333 | E15: 19452.082 | F15: 20020.7 | G15: 20643.4 | H15: ≥ $10,000
B16: Cost per Student | C16: 13286.181 | D16: 11222.479 | E16: 9611.8022 | F16: 8817.0393 | G16: 9081.5505
B17: Instructional / Student | C17: 500 | D17: 515 | E17: 530.45 | F17: 546.3635 | G17: 562.75441
B18: Facility / Student | C18: 3000 | D18: 2060 | E18: 1736.0182 | F18: 1573.5269 | G18: 1620.7327 | H18: ≤ $2,000 / $2k–$3.5k / > $3,500
B19: Surplus per Student | C19: 2102.7083 | D19: 7694.8539 | E19: 9840.2796 | F19: 11203.661 | G19: 11561.849
B20: Payroll % | C20: 0.64404783 | D20: 0.43171057 | E20: 0.35381282 | F20: 0.31158769 | G20: 0.31125443 | H20: ≤ 55%
B21: Facility % | C21: 0.19494585 | D21: 0.10889484 | E21: 0.089245881 | F21: 0.078594998 | G21: 0.078510937 | H21: ≤ 15%
B22: Operating Margin | C22: 0.13663809 | D22: 0.40676208 | E22: 0.50587283 | F22: 0.55960384 | G22: 0.56007487 | H22: ≥ 10%
B23: Revenue Sources | C23: 3 | D23: 3 | E23: 3 | F23: 3 | G23: 3 | H23: ≥ 3 sources
B24: DSCR | C24: N/A | D24: N/A | E24: N/A | F24: N/A | G24: N/A | H24: N/A
B25: Break-even Year | C25: =IF('5-Year Operating Stmt'!B18>=0,"✓ Break-even","") -> ✓ Break-even | D25: =IF(AND('5-Year Operating Stmt'!C18>=0,'5-Year Operating Stmt'!B18<0),"✓ Break-even","") -> 0 | E25: =IF(AND('5-Year Operating Stmt'!D18>=0,'5-Year Operating Stmt'!C18<0),"✓ Break-even","") -> 0 | F25: =IF(AND('5-Year Operating Stmt'!E18>=0,'5-Year Operating Stmt'!D18<0),"✓ Break-even","") -> 0 | G25: =IF(AND('5-Year Operating Stmt'!F18>=0,'5-Year Operating Stmt'!E18<0),"✓ Break-even","") -> 0 | H25: Year 1
B26: Cash Runway (Months) | C26: 5 | D26: 12 | E26: 24 | F26: 38 | G26: 52 | H26: ≥ 24 months
B27: Days Cash on Hand | C27: 142 | D27: 363 | E27: 720 | F27: 1155 | G27: 1586 | H27: ≥ 90 days
B29: FINANCIAL HEALTH SIGNALS | C29: Status | D29: Assessment | F29: Watch Item
B30: Viability | C30: ● Healthy | D30: The model reaches profit early and sustains strong margins through Year 5. | F30: Compare your real Year 1 enrollment against this projection as students enroll.
B31: Liquidity | C31: ● Healthy | D31: Cash stays positive throughout the projection and reserves exceed 3 months of expenses. | F31: Maintain reserves as a buffer against seasonal revenue dips.
B32: Staffing Burden | C32: ● Healthy | D32: Staffing at 31% of revenue leaves room for facilities, programs, and reserves. | F32: As you add staff, ensure staffing stays below 60% of revenue.
B33: Facility Burden | C33: ● Healthy | D33: Facility costs at 8% of revenue are well-managed and leave budget for programs. | F33: Watch for rent escalation clauses that could push this higher over time.
B34: Revenue Concentration | C34: ● Healthy | D34: Revenue is anchored to enrollment-driven income — the strongest foundation for a school model. A focused revenue stream is a strength when backed by dependable demand. | F34: Continue to pressure-test enrollment assumptions: recruitment pipeline, waitlist depth, retention rates, and collection reliability.
B35: Reserve Strength | C35: ● Healthy | D35: 52.1 months of reserves by Year 5 — a strong buffer for unexpected costs. | F35: Continue growing reserves toward 6 months for best-in-class financial health.
B37: Summary | C37: 6 Healthy | 0 Watch | 0 Needs Attention
B39: Built by SchoolStack Budget • budget.schoolstack.ai

Sheet Budget Narrative
A1: Budget Narrative
A3: Enrollment Strategy
A4: (Not provided)
A6: Retention Plan
A7: (Not provided)
A9: Risk Mitigation
A10: (Not provided)
A12: Mission & Vision
A13: (Not provided)
A15: Revenue Assumptions
A16: (Not provided)
A18: Staffing Philosophy
... A28: (Not provided)

Sheet Assumptions Confidence
A1: Assumptions Confidence
A3: No assumptions tagged yet — open the wizard and tag each major assumption (Actuals, Signed agreement, Written quote, Research, Estimate) with a one-line evidence note. The tags surface here, in the lender PDF, and on share links.

Sheet Assumptions Memo
A1: Assumptions Memo
A2: Founder-supplied reasoning for each assumption captured during the wizard. Empty when no rationale was entered for that area.
A4: No founder rationale captured.

Sheet Decision History
B1: Decision History
B2: Track record of 5 tracked decisions (2 pursued, 1 on hold, 2 declined). Each entry shows the modeled change, the outcome the team logged, and any retrospective notes captured after the fact.
B4: Decision | C4: Type | D4: Outcome | E4: Applied to base model? | F4: Outcome logged | G4: Modeled change | H4: What happened (retrospective)
B5: Add Middle School program | C5: Add a program | D5: Pursued | E5: [APPLIED] Folded into the base model on Apr 12, 2025 | F5: Apr 10, 2025 | G5: • Program: Middle School (6-8) • Tuition $14,000/yr • Adds 72 cumulative students (5 yrs) • +2 FTE | H5: Launched in fall 2025; enrollment hit plan within 1 student.
B6: Increase retention focus | C6: Change enrollment | D6: Pursued | E6: [PENDING] Pending apply to base model | F6: Mar 5, 2025 | G6: • Enrollment +14 cumulative • Retention 92% | H6: Retention initiatives approved; planner will reflect after Q2 board review.
B7: Evaluate downtown campus | C7: Evaluate a site | D7: On hold | E7: — | F7: Mar 25, 2025 | G7: • Rent $8,500/mo • Rent escalation 4% • Sqft +1500 • Fit-out $75,000 (Y1) | H7: Landlord negotiations paused while waiting on city zoning ruling.
B8: Reduce K cohort | C8: Change enrollment | D8: Declined | E8: — | F8: Mar 15, 2025 | G8: • Enrollment -8 cumulative • Tuition -$500/student | H8: Board declined; enrollment goals retained as originally modeled.
B9: Move to larger building | C9: Evaluate a site | D9: Declined | E9: — | F9: Feb 10, 2025 | G9: • Rent $12,000/mo • Sqft +4000 | H9: Costs out of reach; revisited next year after capital campaign.
B11: Generated by SchoolStack Budget (budget.schoolstack.ai)
